WARNING - [2018-02-21 12:57:32] (base 12822 123145365794816) Not Found: /favicon.ico
ERROR - [2018-02-21 13:03:13] (exception 13026 123145382293504) Internal Server Error: /sky/news/
Traceback (most recent call last):
  File "/Users/YuChih/Project/IMnight2018_Backend/ENV/lib/python3.6/site-packages/django/core/handlers/exception.py", line 35, in inner
    response = get_response(request)
  File "/Users/YuChih/Project/IMnight2018_Backend/ENV/lib/python3.6/site-packages/django/core/handlers/base.py", line 128, in _get_response
    response = self.process_exception_by_middleware(e, request)
  File "/Users/YuChih/Project/IMnight2018_Backend/ENV/lib/python3.6/site-packages/channels/handler.py", line 243, in process_exception_by_middleware
    return super(AsgiHandler, self).process_exception_by_middleware(exception, request)
  File "/Users/YuChih/Project/IMnight2018_Backend/ENV/lib/python3.6/site-packages/django/core/handlers/base.py", line 126, in _get_response
    response = wrapped_callback(request, *callback_args, **callback_kwargs)
  File "/Users/YuChih/Project/IMnight2018_Backend/ENV/lib/python3.6/site-packages/django/views/decorators/csrf.py", line 54, in wrapped_view
    return view_func(*args, **kwargs)
  File "/Users/YuChih/Project/IMnight2018_Backend/ENV/lib/python3.6/site-packages/django/views/generic/base.py", line 69, in view
    return self.dispatch(request, *args, **kwargs)
  File "/Users/YuChih/Project/IMnight2018_Backend/ENV/lib/python3.6/site-packages/rest_framework/views.py", line 489, in dispatch
    response = self.handle_exception(exc)
  File "/Users/YuChih/Project/IMnight2018_Backend/ENV/lib/python3.6/site-packages/rest_framework/views.py", line 449, in handle_exception
    self.raise_uncaught_exception(exc)
  File "/Users/YuChih/Project/IMnight2018_Backend/ENV/lib/python3.6/site-packages/rest_framework/views.py", line 486, in dispatch
    response = handler(request, *args, **kwargs)
  File "/Users/YuChih/Project/IMnight2018_Backend/ENV/lib/python3.6/site-packages/rest_framework/generics.py", line 201, in get
    return self.list(request, *args, **kwargs)
  File "/Users/YuChih/Project/IMnight2018_Backend/ENV/lib/python3.6/site-packages/rest_framework/mixins.py", line 40, in list
    queryset = self.filter_queryset(self.get_queryset())
  File "/Users/YuChih/Project/IMnight2018_Backend/IMnight/sky/views.py", line 19, in get_queryset
    queryset = News.objects.get().order_by('-timestamp')[:5]
  File "/Users/YuChih/Project/IMnight2018_Backend/ENV/lib/python3.6/site-packages/django/db/models/manager.py", line 82, in manager_method
    return getattr(self.get_queryset(), name)(*args, **kwargs)
  File "/Users/YuChih/Project/IMnight2018_Backend/ENV/lib/python3.6/site-packages/django/db/models/query.py", line 407, in get
    (self.model._meta.object_name, num)
sky.models.MultipleObjectsReturned: get() returned more than one News -- it returned 3!
ERROR - [2018-02-21 13:03:41] (exception 13035 123145440563200) Internal Server Error: /sky/news/
Traceback (most recent call last):
  File "/Users/YuChih/Project/IMnight2018_Backend/ENV/lib/python3.6/site-packages/django/core/handlers/exception.py", line 35, in inner
    response = get_response(request)
  File "/Users/YuChih/Project/IMnight2018_Backend/ENV/lib/python3.6/site-packages/django/core/handlers/base.py", line 128, in _get_response
    response = self.process_exception_by_middleware(e, request)
  File "/Users/YuChih/Project/IMnight2018_Backend/ENV/lib/python3.6/site-packages/channels/handler.py", line 243, in process_exception_by_middleware
    return super(AsgiHandler, self).process_exception_by_middleware(exception, request)
  File "/Users/YuChih/Project/IMnight2018_Backend/ENV/lib/python3.6/site-packages/django/core/handlers/base.py", line 126, in _get_response
    response = wrapped_callback(request, *callback_args, **callback_kwargs)
  File "/Users/YuChih/Project/IMnight2018_Backend/ENV/lib/python3.6/site-packages/django/views/decorators/csrf.py", line 54, in wrapped_view
    return view_func(*args, **kwargs)
  File "/Users/YuChih/Project/IMnight2018_Backend/ENV/lib/python3.6/site-packages/django/views/generic/base.py", line 69, in view
    return self.dispatch(request, *args, **kwargs)
  File "/Users/YuChih/Project/IMnight2018_Backend/ENV/lib/python3.6/site-packages/rest_framework/views.py", line 489, in dispatch
    response = self.handle_exception(exc)
  File "/Users/YuChih/Project/IMnight2018_Backend/ENV/lib/python3.6/site-packages/rest_framework/views.py", line 449, in handle_exception
    self.raise_uncaught_exception(exc)
  File "/Users/YuChih/Project/IMnight2018_Backend/ENV/lib/python3.6/site-packages/rest_framework/views.py", line 486, in dispatch
    response = handler(request, *args, **kwargs)
  File "/Users/YuChih/Project/IMnight2018_Backend/ENV/lib/python3.6/site-packages/rest_framework/generics.py", line 201, in get
    return self.list(request, *args, **kwargs)
  File "/Users/YuChih/Project/IMnight2018_Backend/ENV/lib/python3.6/site-packages/rest_framework/mixins.py", line 40, in list
    queryset = self.filter_queryset(self.get_queryset())
  File "/Users/YuChih/Project/IMnight2018_Backend/IMnight/sky/views.py", line 19, in get_queryset
    queryset = News.objects.get()
  File "/Users/YuChih/Project/IMnight2018_Backend/ENV/lib/python3.6/site-packages/django/db/models/manager.py", line 82, in manager_method
    return getattr(self.get_queryset(), name)(*args, **kwargs)
  File "/Users/YuChih/Project/IMnight2018_Backend/ENV/lib/python3.6/site-packages/django/db/models/query.py", line 407, in get
    (self.model._meta.object_name, num)
sky.models.MultipleObjectsReturned: get() returned more than one News -- it returned 3!
ERROR - [2018-02-21 13:04:12] (exception 13057 123145408462848) Internal Server Error: /sky/news/
Traceback (most recent call last):
  File "/Users/YuChih/Project/IMnight2018_Backend/ENV/lib/python3.6/site-packages/django/core/handlers/exception.py", line 35, in inner
    response = get_response(request)
  File "/Users/YuChih/Project/IMnight2018_Backend/ENV/lib/python3.6/site-packages/django/core/handlers/base.py", line 128, in _get_response
    response = self.process_exception_by_middleware(e, request)
  File "/Users/YuChih/Project/IMnight2018_Backend/ENV/lib/python3.6/site-packages/channels/handler.py", line 243, in process_exception_by_middleware
    return super(AsgiHandler, self).process_exception_by_middleware(exception, request)
  File "/Users/YuChih/Project/IMnight2018_Backend/ENV/lib/python3.6/site-packages/django/core/handlers/base.py", line 126, in _get_response
    response = wrapped_callback(request, *callback_args, **callback_kwargs)
  File "/Users/YuChih/Project/IMnight2018_Backend/ENV/lib/python3.6/site-packages/django/views/decorators/csrf.py", line 54, in wrapped_view
    return view_func(*args, **kwargs)
  File "/Users/YuChih/Project/IMnight2018_Backend/ENV/lib/python3.6/site-packages/django/views/generic/base.py", line 69, in view
    return self.dispatch(request, *args, **kwargs)
  File "/Users/YuChih/Project/IMnight2018_Backend/ENV/lib/python3.6/site-packages/rest_framework/views.py", line 489, in dispatch
    response = self.handle_exception(exc)
  File "/Users/YuChih/Project/IMnight2018_Backend/ENV/lib/python3.6/site-packages/rest_framework/views.py", line 449, in handle_exception
    self.raise_uncaught_exception(exc)
  File "/Users/YuChih/Project/IMnight2018_Backend/ENV/lib/python3.6/site-packages/rest_framework/views.py", line 486, in dispatch
    response = handler(request, *args, **kwargs)
  File "/Users/YuChih/Project/IMnight2018_Backend/ENV/lib/python3.6/site-packages/rest_framework/generics.py", line 201, in get
    return self.list(request, *args, **kwargs)
  File "/Users/YuChih/Project/IMnight2018_Backend/ENV/lib/python3.6/site-packages/rest_framework/mixins.py", line 40, in list
    queryset = self.filter_queryset(self.get_queryset())
  File "/Users/YuChih/Project/IMnight2018_Backend/IMnight/sky/views.py", line 20, in get_queryset
    print(queryset)
  File "/Users/YuChih/Project/IMnight2018_Backend/ENV/lib/python3.6/site-packages/django/db/models/query.py", line 248, in __repr__
    data = list(self[:REPR_OUTPUT_SIZE + 1])
  File "/Users/YuChih/Project/IMnight2018_Backend/ENV/lib/python3.6/site-packages/django/db/models/query.py", line 272, in __iter__
    self._fetch_all()
  File "/Users/YuChih/Project/IMnight2018_Backend/ENV/lib/python3.6/site-packages/django/db/models/query.py", line 1179, in _fetch_all
    self._result_cache = list(self._iterable_class(self))
  File "/Users/YuChih/Project/IMnight2018_Backend/ENV/lib/python3.6/site-packages/django/db/models/query.py", line 54, in __iter__
    results = compiler.execute_sql(chunked_fetch=self.chunked_fetch, chunk_size=self.chunk_size)
  File "/Users/YuChih/Project/IMnight2018_Backend/ENV/lib/python3.6/site-packages/django/db/models/sql/compiler.py", line 1050, in execute_sql
    sql, params = self.as_sql()
  File "/Users/YuChih/Project/IMnight2018_Backend/ENV/lib/python3.6/site-packages/django/db/models/sql/compiler.py", line 445, in as_sql
    extra_select, order_by, group_by = self.pre_sql_setup()
  File "/Users/YuChih/Project/IMnight2018_Backend/ENV/lib/python3.6/site-packages/django/db/models/sql/compiler.py", line 51, in pre_sql_setup
    order_by = self.get_order_by()
  File "/Users/YuChih/Project/IMnight2018_Backend/ENV/lib/python3.6/site-packages/django/db/models/sql/compiler.py", line 315, in get_order_by
    field, self.query.get_meta(), default_order=asc))
  File "/Users/YuChih/Project/IMnight2018_Backend/ENV/lib/python3.6/site-packages/django/db/models/sql/compiler.py", line 660, in find_ordering_name
    field, targets, alias, joins, path, opts = self._setup_joins(pieces, opts, alias)
  File "/Users/YuChih/Project/IMnight2018_Backend/ENV/lib/python3.6/site-packages/django/db/models/sql/compiler.py", line 693, in _setup_joins
    pieces, opts, alias)
  File "/Users/YuChih/Project/IMnight2018_Backend/ENV/lib/python3.6/site-packages/django/db/models/sql/query.py", line 1447, in setup_joins
    names, opts, allow_many, fail_on_missing=True)
  File "/Users/YuChih/Project/IMnight2018_Backend/ENV/lib/python3.6/site-packages/django/db/models/sql/query.py", line 1378, in names_to_path
    "Choices are: %s" % (name, ", ".join(available)))
django.core.exceptions.FieldError: Cannot resolve keyword 'timestamp' into field. Choices are: created, id, title, url
WARNING - [2018-02-24 07:40:26] (base 10764 140160341559040) Not Found: /article
ERROR - [2018-02-24 07:40:38] (exception 10764 140160341559040) Internal Server Error: /sky/articles
Traceback (most recent call last):
  File "/usr/local/lib/python3.5/dist-packages/django/core/handlers/exception.py", line 35, in inner
    response = get_response(request)
  File "/usr/local/lib/python3.5/dist-packages/django/core/handlers/base.py", line 128, in _get_response
    response = self.process_exception_by_middleware(e, request)
  File "/usr/local/lib/python3.5/dist-packages/channels/handler.py", line 243, in process_exception_by_middleware
    return super(AsgiHandler, self).process_exception_by_middleware(exception, request)
  File "/usr/local/lib/python3.5/dist-packages/django/core/handlers/base.py", line 126, in _get_response
    response = wrapped_callback(request, *callback_args, **callback_kwargs)
  File "/usr/local/lib/python3.5/dist-packages/django/views/decorators/csrf.py", line 54, in wrapped_view
    return view_func(*args, **kwargs)
  File "/usr/local/lib/python3.5/dist-packages/django/views/generic/base.py", line 69, in view
    return self.dispatch(request, *args, **kwargs)
  File "/usr/local/lib/python3.5/dist-packages/rest_framework/views.py", line 489, in dispatch
    response = self.handle_exception(exc)
  File "/usr/local/lib/python3.5/dist-packages/rest_framework/views.py", line 449, in handle_exception
    self.raise_uncaught_exception(exc)
  File "/usr/local/lib/python3.5/dist-packages/rest_framework/views.py", line 486, in dispatch
    response = handler(request, *args, **kwargs)
  File "/usr/local/lib/python3.5/dist-packages/rest_framework/generics.py", line 201, in get
    return self.list(request, *args, **kwargs)
  File "/usr/local/lib/python3.5/dist-packages/rest_framework/mixins.py", line 40, in list
    queryset = self.filter_queryset(self.get_queryset())
  File "/home/eethan1/Desktop/IMnight2018_Backend/IMnight/sky/views.py", line 20, in get_queryset
    queryset = Article.objects.all().orde_by('-created')[:5]
AttributeError: 'QuerySet' object has no attribute 'orde_by'
ERROR - [2018-02-24 07:42:04] (exception 10764 140160349951744) Internal Server Error: /sky/articles
Traceback (most recent call last):
  File "/usr/local/lib/python3.5/dist-packages/django/core/handlers/exception.py", line 35, in inner
    response = get_response(request)
  File "/usr/local/lib/python3.5/dist-packages/django/core/handlers/base.py", line 128, in _get_response
    response = self.process_exception_by_middleware(e, request)
  File "/usr/local/lib/python3.5/dist-packages/channels/handler.py", line 243, in process_exception_by_middleware
    return super(AsgiHandler, self).process_exception_by_middleware(exception, request)
  File "/usr/local/lib/python3.5/dist-packages/django/core/handlers/base.py", line 126, in _get_response
    response = wrapped_callback(request, *callback_args, **callback_kwargs)
  File "/usr/local/lib/python3.5/dist-packages/django/views/decorators/csrf.py", line 54, in wrapped_view
    return view_func(*args, **kwargs)
  File "/usr/local/lib/python3.5/dist-packages/django/views/generic/base.py", line 69, in view
    return self.dispatch(request, *args, **kwargs)
  File "/usr/local/lib/python3.5/dist-packages/rest_framework/views.py", line 489, in dispatch
    response = self.handle_exception(exc)
  File "/usr/local/lib/python3.5/dist-packages/rest_framework/views.py", line 449, in handle_exception
    self.raise_uncaught_exception(exc)
  File "/usr/local/lib/python3.5/dist-packages/rest_framework/views.py", line 486, in dispatch
    response = handler(request, *args, **kwargs)
  File "/usr/local/lib/python3.5/dist-packages/rest_framework/generics.py", line 201, in get
    return self.list(request, *args, **kwargs)
  File "/usr/local/lib/python3.5/dist-packages/rest_framework/mixins.py", line 40, in list
    queryset = self.filter_queryset(self.get_queryset())
  File "/home/eethan1/Desktop/IMnight2018_Backend/IMnight/sky/views.py", line 20, in get_queryset
    queryset = Article.objects.all().orde_by('-created')[:5]
AttributeError: 'QuerySet' object has no attribute 'orde_by'
ERROR - [2018-02-24 08:12:36] (exception 12787 139793018160896) Internal Server Error: /sky/courses
Traceback (most recent call last):
  File "/usr/local/lib/python3.5/dist-packages/django/db/backends/utils.py", line 85, in _execute
    return self.cursor.execute(sql, params)
psycopg2.ProgrammingError: relation "sky_course" does not exist
LINE 1: ..., "sky_course"."img", "sky_course"."content" FROM "sky_cours...
                                                             ^


The above exception was the direct cause of the following exception:

Traceback (most recent call last):
  File "/usr/local/lib/python3.5/dist-packages/django/core/handlers/exception.py", line 35, in inner
    response = get_response(request)
  File "/usr/local/lib/python3.5/dist-packages/django/core/handlers/base.py", line 128, in _get_response
    response = self.process_exception_by_middleware(e, request)
  File "/usr/local/lib/python3.5/dist-packages/channels/handler.py", line 243, in process_exception_by_middleware
    return super(AsgiHandler, self).process_exception_by_middleware(exception, request)
  File "/usr/local/lib/python3.5/dist-packages/django/core/handlers/base.py", line 126, in _get_response
    response = wrapped_callback(request, *callback_args, **callback_kwargs)
  File "/usr/local/lib/python3.5/dist-packages/django/views/decorators/csrf.py", line 54, in wrapped_view
    return view_func(*args, **kwargs)
  File "/usr/local/lib/python3.5/dist-packages/django/views/generic/base.py", line 69, in view
    return self.dispatch(request, *args, **kwargs)
  File "/usr/local/lib/python3.5/dist-packages/rest_framework/views.py", line 489, in dispatch
    response = self.handle_exception(exc)
  File "/usr/local/lib/python3.5/dist-packages/rest_framework/views.py", line 449, in handle_exception
    self.raise_uncaught_exception(exc)
  File "/usr/local/lib/python3.5/dist-packages/rest_framework/views.py", line 486, in dispatch
    response = handler(request, *args, **kwargs)
  File "/usr/local/lib/python3.5/dist-packages/rest_framework/generics.py", line 201, in get
    return self.list(request, *args, **kwargs)
  File "/usr/local/lib/python3.5/dist-packages/rest_framework/mixins.py", line 48, in list
    return Response(serializer.data)
  File "/usr/local/lib/python3.5/dist-packages/rest_framework/serializers.py", line 738, in data
    ret = super(ListSerializer, self).data
  File "/usr/local/lib/python3.5/dist-packages/rest_framework/serializers.py", line 262, in data
    self._data = self.to_representation(self.instance)
  File "/usr/local/lib/python3.5/dist-packages/rest_framework/serializers.py", line 656, in to_representation
    self.child.to_representation(item) for item in iterable
  File "/usr/local/lib/python3.5/dist-packages/django/db/models/query.py", line 272, in __iter__
    self._fetch_all()
  File "/usr/local/lib/python3.5/dist-packages/django/db/models/query.py", line 1179, in _fetch_all
    self._result_cache = list(self._iterable_class(self))
  File "/usr/local/lib/python3.5/dist-packages/django/db/models/query.py", line 54, in __iter__
    results = compiler.execute_sql(chunked_fetch=self.chunked_fetch, chunk_size=self.chunk_size)
  File "/usr/local/lib/python3.5/dist-packages/django/db/models/sql/compiler.py", line 1063, in execute_sql
    cursor.execute(sql, params)
  File "/usr/local/lib/python3.5/dist-packages/django/db/backends/utils.py", line 100, in execute
    return super().execute(sql, params)
  File "/usr/local/lib/python3.5/dist-packages/django/db/backends/utils.py", line 68, in execute
    return self._execute_with_wrappers(sql, params, many=False, executor=self._execute)
  File "/usr/local/lib/python3.5/dist-packages/django/db/backends/utils.py", line 77, in _execute_with_wrappers
    return executor(sql, params, many, context)
  File "/usr/local/lib/python3.5/dist-packages/django/db/backends/utils.py", line 85, in _execute
    return self.cursor.execute(sql, params)
  File "/usr/local/lib/python3.5/dist-packages/django/db/utils.py", line 89, in __exit__
    raise dj_exc_value.with_traceback(traceback) from exc_value
  File "/usr/local/lib/python3.5/dist-packages/django/db/backends/utils.py", line 85, in _execute
    return self.cursor.execute(sql, params)
django.db.utils.ProgrammingError: relation "sky_course" does not exist
LINE 1: ..., "sky_course"."img", "sky_course"."content" FROM "sky_cours...
                                                             ^

ERROR - [2018-02-24 09:43:45] (exception 17234 140320926848768) Internal Server Error: /admin/sky/course/1/change/
Traceback (most recent call last):
  File "/usr/local/lib/python3.5/dist-packages/django/db/backends/utils.py", line 85, in _execute
    return self.cursor.execute(sql, params)
psycopg2.ProgrammingError: column sky_course.created does not exist
LINE 1: ...ore", "sky_course"."img", "sky_course"."content", "sky_cours...
                                                             ^


The above exception was the direct cause of the following exception:

Traceback (most recent call last):
  File "/usr/local/lib/python3.5/dist-packages/django/core/handlers/exception.py", line 35, in inner
    response = get_response(request)
  File "/usr/local/lib/python3.5/dist-packages/django/core/handlers/base.py", line 128, in _get_response
    response = self.process_exception_by_middleware(e, request)
  File "/usr/local/lib/python3.5/dist-packages/channels/handler.py", line 243, in process_exception_by_middleware
    return super(AsgiHandler, self).process_exception_by_middleware(exception, request)
  File "/usr/local/lib/python3.5/dist-packages/django/core/handlers/base.py", line 126, in _get_response
    response = wrapped_callback(request, *callback_args, **callback_kwargs)
  File "/usr/local/lib/python3.5/dist-packages/django/contrib/admin/options.py", line 574, in wrapper
    return self.admin_site.admin_view(view)(*args, **kwargs)
  File "/usr/local/lib/python3.5/dist-packages/django/utils/decorators.py", line 142, in _wrapped_view
    response = view_func(request, *args, **kwargs)
  File "/usr/local/lib/python3.5/dist-packages/django/views/decorators/cache.py", line 44, in _wrapped_view_func
    response = view_func(request, *args, **kwargs)
  File "/usr/local/lib/python3.5/dist-packages/django/contrib/admin/sites.py", line 223, in inner
    return view(request, *args, **kwargs)
  File "/usr/local/lib/python3.5/dist-packages/django/contrib/admin/options.py", line 1556, in change_view
    return self.changeform_view(request, object_id, form_url, extra_context)
  File "/usr/local/lib/python3.5/dist-packages/django/utils/decorators.py", line 62, in _wrapper
    return bound_func(*args, **kwargs)
  File "/usr/local/lib/python3.5/dist-packages/django/utils/decorators.py", line 142, in _wrapped_view
    response = view_func(request, *args, **kwargs)
  File "/usr/local/lib/python3.5/dist-packages/django/utils/decorators.py", line 58, in bound_func
    return func.__get__(self, type(self))(*args2, **kwargs2)
  File "/usr/local/lib/python3.5/dist-packages/django/contrib/admin/options.py", line 1450, in changeform_view
    return self._changeform_view(request, object_id, form_url, extra_context)
  File "/usr/local/lib/python3.5/dist-packages/django/contrib/admin/options.py", line 1471, in _changeform_view
    obj = self.get_object(request, unquote(object_id), to_field)
  File "/usr/local/lib/python3.5/dist-packages/django/contrib/admin/options.py", line 719, in get_object
    return queryset.get(**{field.name: object_id})
  File "/usr/local/lib/python3.5/dist-packages/django/db/models/query.py", line 397, in get
    num = len(clone)
  File "/usr/local/lib/python3.5/dist-packages/django/db/models/query.py", line 254, in __len__
    self._fetch_all()
  File "/usr/local/lib/python3.5/dist-packages/django/db/models/query.py", line 1179, in _fetch_all
    self._result_cache = list(self._iterable_class(self))
  File "/usr/local/lib/python3.5/dist-packages/django/db/models/query.py", line 54, in __iter__
    results = compiler.execute_sql(chunked_fetch=self.chunked_fetch, chunk_size=self.chunk_size)
  File "/usr/local/lib/python3.5/dist-packages/django/db/models/sql/compiler.py", line 1063, in execute_sql
    cursor.execute(sql, params)
  File "/usr/local/lib/python3.5/dist-packages/django/db/backends/utils.py", line 100, in execute
    return super().execute(sql, params)
  File "/usr/local/lib/python3.5/dist-packages/django/db/backends/utils.py", line 68, in execute
    return self._execute_with_wrappers(sql, params, many=False, executor=self._execute)
  File "/usr/local/lib/python3.5/dist-packages/django/db/backends/utils.py", line 77, in _execute_with_wrappers
    return executor(sql, params, many, context)
  File "/usr/local/lib/python3.5/dist-packages/django/db/backends/utils.py", line 85, in _execute
    return self.cursor.execute(sql, params)
  File "/usr/local/lib/python3.5/dist-packages/django/db/utils.py", line 89, in __exit__
    raise dj_exc_value.with_traceback(traceback) from exc_value
  File "/usr/local/lib/python3.5/dist-packages/django/db/backends/utils.py", line 85, in _execute
    return self.cursor.execute(sql, params)
django.db.utils.ProgrammingError: column sky_course.created does not exist
LINE 1: ...ore", "sky_course"."img", "sky_course"."content", "sky_cours...
                                                             ^

WARNING - [2018-02-24 09:43:48] (base 17234 140320935241472) Not Found: /favicon.ico
ERROR - [2018-02-24 09:45:03] (exception 17296 139700049991424) Internal Server Error: /admin/sky/course/1/change/
Traceback (most recent call last):
  File "/usr/local/lib/python3.5/dist-packages/django/db/backends/utils.py", line 85, in _execute
    return self.cursor.execute(sql, params)
psycopg2.ProgrammingError: column sky_course.created does not exist
LINE 1: ...ore", "sky_course"."img", "sky_course"."content", "sky_cours...
                                                             ^


The above exception was the direct cause of the following exception:

Traceback (most recent call last):
  File "/usr/local/lib/python3.5/dist-packages/django/core/handlers/exception.py", line 35, in inner
    response = get_response(request)
  File "/usr/local/lib/python3.5/dist-packages/django/core/handlers/base.py", line 128, in _get_response
    response = self.process_exception_by_middleware(e, request)
  File "/usr/local/lib/python3.5/dist-packages/channels/handler.py", line 243, in process_exception_by_middleware
    return super(AsgiHandler, self).process_exception_by_middleware(exception, request)
  File "/usr/local/lib/python3.5/dist-packages/django/core/handlers/base.py", line 126, in _get_response
    response = wrapped_callback(request, *callback_args, **callback_kwargs)
  File "/usr/local/lib/python3.5/dist-packages/django/contrib/admin/options.py", line 574, in wrapper
    return self.admin_site.admin_view(view)(*args, **kwargs)
  File "/usr/local/lib/python3.5/dist-packages/django/utils/decorators.py", line 142, in _wrapped_view
    response = view_func(request, *args, **kwargs)
  File "/usr/local/lib/python3.5/dist-packages/django/views/decorators/cache.py", line 44, in _wrapped_view_func
    response = view_func(request, *args, **kwargs)
  File "/usr/local/lib/python3.5/dist-packages/django/contrib/admin/sites.py", line 223, in inner
    return view(request, *args, **kwargs)
  File "/usr/local/lib/python3.5/dist-packages/django/contrib/admin/options.py", line 1556, in change_view
    return self.changeform_view(request, object_id, form_url, extra_context)
  File "/usr/local/lib/python3.5/dist-packages/django/utils/decorators.py", line 62, in _wrapper
    return bound_func(*args, **kwargs)
  File "/usr/local/lib/python3.5/dist-packages/django/utils/decorators.py", line 142, in _wrapped_view
    response = view_func(request, *args, **kwargs)
  File "/usr/local/lib/python3.5/dist-packages/django/utils/decorators.py", line 58, in bound_func
    return func.__get__(self, type(self))(*args2, **kwargs2)
  File "/usr/local/lib/python3.5/dist-packages/django/contrib/admin/options.py", line 1450, in changeform_view
    return self._changeform_view(request, object_id, form_url, extra_context)
  File "/usr/local/lib/python3.5/dist-packages/django/contrib/admin/options.py", line 1471, in _changeform_view
    obj = self.get_object(request, unquote(object_id), to_field)
  File "/usr/local/lib/python3.5/dist-packages/django/contrib/admin/options.py", line 719, in get_object
    return queryset.get(**{field.name: object_id})
  File "/usr/local/lib/python3.5/dist-packages/django/db/models/query.py", line 397, in get
    num = len(clone)
  File "/usr/local/lib/python3.5/dist-packages/django/db/models/query.py", line 254, in __len__
    self._fetch_all()
  File "/usr/local/lib/python3.5/dist-packages/django/db/models/query.py", line 1179, in _fetch_all
    self._result_cache = list(self._iterable_class(self))
  File "/usr/local/lib/python3.5/dist-packages/django/db/models/query.py", line 54, in __iter__
    results = compiler.execute_sql(chunked_fetch=self.chunked_fetch, chunk_size=self.chunk_size)
  File "/usr/local/lib/python3.5/dist-packages/django/db/models/sql/compiler.py", line 1063, in execute_sql
    cursor.execute(sql, params)
  File "/usr/local/lib/python3.5/dist-packages/django/db/backends/utils.py", line 100, in execute
    return super().execute(sql, params)
  File "/usr/local/lib/python3.5/dist-packages/django/db/backends/utils.py", line 68, in execute
    return self._execute_with_wrappers(sql, params, many=False, executor=self._execute)
  File "/usr/local/lib/python3.5/dist-packages/django/db/backends/utils.py", line 77, in _execute_with_wrappers
    return executor(sql, params, many, context)
  File "/usr/local/lib/python3.5/dist-packages/django/db/backends/utils.py", line 85, in _execute
    return self.cursor.execute(sql, params)
  File "/usr/local/lib/python3.5/dist-packages/django/db/utils.py", line 89, in __exit__
    raise dj_exc_value.with_traceback(traceback) from exc_value
  File "/usr/local/lib/python3.5/dist-packages/django/db/backends/utils.py", line 85, in _execute
    return self.cursor.execute(sql, params)
django.db.utils.ProgrammingError: column sky_course.created does not exist
LINE 1: ...ore", "sky_course"."img", "sky_course"."content", "sky_cours...
                                                             ^

ERROR - [2018-02-24 09:45:07] (exception 17296 139700024813312) Internal Server Error: /admin/sky/course/
Traceback (most recent call last):
  File "/usr/local/lib/python3.5/dist-packages/django/db/backends/utils.py", line 85, in _execute
    return self.cursor.execute(sql, params)
psycopg2.ProgrammingError: column sky_course.created does not exist
LINE 1: ...ore", "sky_course"."img", "sky_course"."content", "sky_cours...
                                                             ^


The above exception was the direct cause of the following exception:

Traceback (most recent call last):
  File "/usr/local/lib/python3.5/dist-packages/django/core/handlers/exception.py", line 35, in inner
    response = get_response(request)
  File "/usr/local/lib/python3.5/dist-packages/django/core/handlers/base.py", line 128, in _get_response
    response = self.process_exception_by_middleware(e, request)
  File "/usr/local/lib/python3.5/dist-packages/channels/handler.py", line 243, in process_exception_by_middleware
    return super(AsgiHandler, self).process_exception_by_middleware(exception, request)
  File "/usr/local/lib/python3.5/dist-packages/django/core/handlers/base.py", line 126, in _get_response
    response = wrapped_callback(request, *callback_args, **callback_kwargs)
  File "/usr/local/lib/python3.5/dist-packages/django/contrib/admin/options.py", line 574, in wrapper
    return self.admin_site.admin_view(view)(*args, **kwargs)
  File "/usr/local/lib/python3.5/dist-packages/django/utils/decorators.py", line 142, in _wrapped_view
    response = view_func(request, *args, **kwargs)
  File "/usr/local/lib/python3.5/dist-packages/django/views/decorators/cache.py", line 44, in _wrapped_view_func
    response = view_func(request, *args, **kwargs)
  File "/usr/local/lib/python3.5/dist-packages/django/contrib/admin/sites.py", line 223, in inner
    return view(request, *args, **kwargs)
  File "/usr/local/lib/python3.5/dist-packages/django/utils/decorators.py", line 62, in _wrapper
    return bound_func(*args, **kwargs)
  File "/usr/local/lib/python3.5/dist-packages/django/utils/decorators.py", line 142, in _wrapped_view
    response = view_func(request, *args, **kwargs)
  File "/usr/local/lib/python3.5/dist-packages/django/utils/decorators.py", line 58, in bound_func
    return func.__get__(self, type(self))(*args2, **kwargs2)
  File "/usr/local/lib/python3.5/dist-packages/django/contrib/admin/options.py", line 1685, in changelist_view
    selection_note=_('0 of %(cnt)s selected') % {'cnt': len(cl.result_list)},
  File "/usr/local/lib/python3.5/dist-packages/django/db/models/query.py", line 254, in __len__
    self._fetch_all()
  File "/usr/local/lib/python3.5/dist-packages/django/db/models/query.py", line 1179, in _fetch_all
    self._result_cache = list(self._iterable_class(self))
  File "/usr/local/lib/python3.5/dist-packages/django/db/models/query.py", line 54, in __iter__
    results = compiler.execute_sql(chunked_fetch=self.chunked_fetch, chunk_size=self.chunk_size)
  File "/usr/local/lib/python3.5/dist-packages/django/db/models/sql/compiler.py", line 1063, in execute_sql
    cursor.execute(sql, params)
  File "/usr/local/lib/python3.5/dist-packages/django/db/backends/utils.py", line 100, in execute
    return super().execute(sql, params)
  File "/usr/local/lib/python3.5/dist-packages/django/db/backends/utils.py", line 68, in execute
    return self._execute_with_wrappers(sql, params, many=False, executor=self._execute)
  File "/usr/local/lib/python3.5/dist-packages/django/db/backends/utils.py", line 77, in _execute_with_wrappers
    return executor(sql, params, many, context)
  File "/usr/local/lib/python3.5/dist-packages/django/db/backends/utils.py", line 85, in _execute
    return self.cursor.execute(sql, params)
  File "/usr/local/lib/python3.5/dist-packages/django/db/utils.py", line 89, in __exit__
    raise dj_exc_value.with_traceback(traceback) from exc_value
  File "/usr/local/lib/python3.5/dist-packages/django/db/backends/utils.py", line 85, in _execute
    return self.cursor.execute(sql, params)
django.db.utils.ProgrammingError: column sky_course.created does not exist
LINE 1: ...ore", "sky_course"."img", "sky_course"."content", "sky_cours...
                                                             ^

ERROR - [2018-02-24 09:45:22] (exception 17296 139700049991424) Internal Server Error: /admin/sky/article/
Traceback (most recent call last):
  File "/usr/local/lib/python3.5/dist-packages/django/db/backends/utils.py", line 85, in _execute
    return self.cursor.execute(sql, params)
psycopg2.ProgrammingError: column sky_article.label does not exist
LINE 1: ...g", "sky_article"."url", "sky_article"."created", "sky_artic...
                                                             ^


The above exception was the direct cause of the following exception:

Traceback (most recent call last):
  File "/usr/local/lib/python3.5/dist-packages/django/core/handlers/exception.py", line 35, in inner
    response = get_response(request)
  File "/usr/local/lib/python3.5/dist-packages/django/core/handlers/base.py", line 128, in _get_response
    response = self.process_exception_by_middleware(e, request)
  File "/usr/local/lib/python3.5/dist-packages/channels/handler.py", line 243, in process_exception_by_middleware
    return super(AsgiHandler, self).process_exception_by_middleware(exception, request)
  File "/usr/local/lib/python3.5/dist-packages/django/core/handlers/base.py", line 126, in _get_response
    response = wrapped_callback(request, *callback_args, **callback_kwargs)
  File "/usr/local/lib/python3.5/dist-packages/django/contrib/admin/options.py", line 574, in wrapper
    return self.admin_site.admin_view(view)(*args, **kwargs)
  File "/usr/local/lib/python3.5/dist-packages/django/utils/decorators.py", line 142, in _wrapped_view
    response = view_func(request, *args, **kwargs)
  File "/usr/local/lib/python3.5/dist-packages/django/views/decorators/cache.py", line 44, in _wrapped_view_func
    response = view_func(request, *args, **kwargs)
  File "/usr/local/lib/python3.5/dist-packages/django/contrib/admin/sites.py", line 223, in inner
    return view(request, *args, **kwargs)
  File "/usr/local/lib/python3.5/dist-packages/django/utils/decorators.py", line 62, in _wrapper
    return bound_func(*args, **kwargs)
  File "/usr/local/lib/python3.5/dist-packages/django/utils/decorators.py", line 142, in _wrapped_view
    response = view_func(request, *args, **kwargs)
  File "/usr/local/lib/python3.5/dist-packages/django/utils/decorators.py", line 58, in bound_func
    return func.__get__(self, type(self))(*args2, **kwargs2)
  File "/usr/local/lib/python3.5/dist-packages/django/contrib/admin/options.py", line 1685, in changelist_view
    selection_note=_('0 of %(cnt)s selected') % {'cnt': len(cl.result_list)},
  File "/usr/local/lib/python3.5/dist-packages/django/db/models/query.py", line 254, in __len__
    self._fetch_all()
  File "/usr/local/lib/python3.5/dist-packages/django/db/models/query.py", line 1179, in _fetch_all
    self._result_cache = list(self._iterable_class(self))
  File "/usr/local/lib/python3.5/dist-packages/django/db/models/query.py", line 54, in __iter__
    results = compiler.execute_sql(chunked_fetch=self.chunked_fetch, chunk_size=self.chunk_size)
  File "/usr/local/lib/python3.5/dist-packages/django/db/models/sql/compiler.py", line 1063, in execute_sql
    cursor.execute(sql, params)
  File "/usr/local/lib/python3.5/dist-packages/django/db/backends/utils.py", line 100, in execute
    return super().execute(sql, params)
  File "/usr/local/lib/python3.5/dist-packages/django/db/backends/utils.py", line 68, in execute
    return self._execute_with_wrappers(sql, params, many=False, executor=self._execute)
  File "/usr/local/lib/python3.5/dist-packages/django/db/backends/utils.py", line 77, in _execute_with_wrappers
    return executor(sql, params, many, context)
  File "/usr/local/lib/python3.5/dist-packages/django/db/backends/utils.py", line 85, in _execute
    return self.cursor.execute(sql, params)
  File "/usr/local/lib/python3.5/dist-packages/django/db/utils.py", line 89, in __exit__
    raise dj_exc_value.with_traceback(traceback) from exc_value
  File "/usr/local/lib/python3.5/dist-packages/django/db/backends/utils.py", line 85, in _execute
    return self.cursor.execute(sql, params)
django.db.utils.ProgrammingError: column sky_article.label does not exist
LINE 1: ...g", "sky_article"."url", "sky_article"."created", "sky_artic...
                                                             ^

ERROR - [2018-02-24 09:46:14] (exception 17296 139700041598720) Internal Server Error: /admin/sky/course/
Traceback (most recent call last):
  File "/usr/local/lib/python3.5/dist-packages/django/db/backends/utils.py", line 85, in _execute
    return self.cursor.execute(sql, params)
psycopg2.ProgrammingError: column sky_course.created does not exist
LINE 1: ...ore", "sky_course"."img", "sky_course"."content", "sky_cours...
                                                             ^


The above exception was the direct cause of the following exception:

Traceback (most recent call last):
  File "/usr/local/lib/python3.5/dist-packages/django/core/handlers/exception.py", line 35, in inner
    response = get_response(request)
  File "/usr/local/lib/python3.5/dist-packages/django/core/handlers/base.py", line 128, in _get_response
    response = self.process_exception_by_middleware(e, request)
  File "/usr/local/lib/python3.5/dist-packages/channels/handler.py", line 243, in process_exception_by_middleware
    return super(AsgiHandler, self).process_exception_by_middleware(exception, request)
  File "/usr/local/lib/python3.5/dist-packages/django/core/handlers/base.py", line 126, in _get_response
    response = wrapped_callback(request, *callback_args, **callback_kwargs)
  File "/usr/local/lib/python3.5/dist-packages/django/contrib/admin/options.py", line 574, in wrapper
    return self.admin_site.admin_view(view)(*args, **kwargs)
  File "/usr/local/lib/python3.5/dist-packages/django/utils/decorators.py", line 142, in _wrapped_view
    response = view_func(request, *args, **kwargs)
  File "/usr/local/lib/python3.5/dist-packages/django/views/decorators/cache.py", line 44, in _wrapped_view_func
    response = view_func(request, *args, **kwargs)
  File "/usr/local/lib/python3.5/dist-packages/django/contrib/admin/sites.py", line 223, in inner
    return view(request, *args, **kwargs)
  File "/usr/local/lib/python3.5/dist-packages/django/utils/decorators.py", line 62, in _wrapper
    return bound_func(*args, **kwargs)
  File "/usr/local/lib/python3.5/dist-packages/django/utils/decorators.py", line 142, in _wrapped_view
    response = view_func(request, *args, **kwargs)
  File "/usr/local/lib/python3.5/dist-packages/django/utils/decorators.py", line 58, in bound_func
    return func.__get__(self, type(self))(*args2, **kwargs2)
  File "/usr/local/lib/python3.5/dist-packages/django/contrib/admin/options.py", line 1685, in changelist_view
    selection_note=_('0 of %(cnt)s selected') % {'cnt': len(cl.result_list)},
  File "/usr/local/lib/python3.5/dist-packages/django/db/models/query.py", line 254, in __len__
    self._fetch_all()
  File "/usr/local/lib/python3.5/dist-packages/django/db/models/query.py", line 1179, in _fetch_all
    self._result_cache = list(self._iterable_class(self))
  File "/usr/local/lib/python3.5/dist-packages/django/db/models/query.py", line 54, in __iter__
    results = compiler.execute_sql(chunked_fetch=self.chunked_fetch, chunk_size=self.chunk_size)
  File "/usr/local/lib/python3.5/dist-packages/django/db/models/sql/compiler.py", line 1063, in execute_sql
    cursor.execute(sql, params)
  File "/usr/local/lib/python3.5/dist-packages/django/db/backends/utils.py", line 100, in execute
    return super().execute(sql, params)
  File "/usr/local/lib/python3.5/dist-packages/django/db/backends/utils.py", line 68, in execute
    return self._execute_with_wrappers(sql, params, many=False, executor=self._execute)
  File "/usr/local/lib/python3.5/dist-packages/django/db/backends/utils.py", line 77, in _execute_with_wrappers
    return executor(sql, params, many, context)
  File "/usr/local/lib/python3.5/dist-packages/django/db/backends/utils.py", line 85, in _execute
    return self.cursor.execute(sql, params)
  File "/usr/local/lib/python3.5/dist-packages/django/db/utils.py", line 89, in __exit__
    raise dj_exc_value.with_traceback(traceback) from exc_value
  File "/usr/local/lib/python3.5/dist-packages/django/db/backends/utils.py", line 85, in _execute
    return self.cursor.execute(sql, params)
django.db.utils.ProgrammingError: column sky_course.created does not exist
LINE 1: ...ore", "sky_course"."img", "sky_course"."content", "sky_cours...
                                                             ^

ERROR - [2018-02-24 09:46:29] (exception 17296 139700041598720) Internal Server Error: /admin/sky/article/
Traceback (most recent call last):
  File "/usr/local/lib/python3.5/dist-packages/django/db/backends/utils.py", line 85, in _execute
    return self.cursor.execute(sql, params)
psycopg2.ProgrammingError: column sky_article.label does not exist
LINE 1: ...g", "sky_article"."url", "sky_article"."created", "sky_artic...
                                                             ^


The above exception was the direct cause of the following exception:

Traceback (most recent call last):
  File "/usr/local/lib/python3.5/dist-packages/django/core/handlers/exception.py", line 35, in inner
    response = get_response(request)
  File "/usr/local/lib/python3.5/dist-packages/django/core/handlers/base.py", line 128, in _get_response
    response = self.process_exception_by_middleware(e, request)
  File "/usr/local/lib/python3.5/dist-packages/channels/handler.py", line 243, in process_exception_by_middleware
    return super(AsgiHandler, self).process_exception_by_middleware(exception, request)
  File "/usr/local/lib/python3.5/dist-packages/django/core/handlers/base.py", line 126, in _get_response
    response = wrapped_callback(request, *callback_args, **callback_kwargs)
  File "/usr/local/lib/python3.5/dist-packages/django/contrib/admin/options.py", line 574, in wrapper
    return self.admin_site.admin_view(view)(*args, **kwargs)
  File "/usr/local/lib/python3.5/dist-packages/django/utils/decorators.py", line 142, in _wrapped_view
    response = view_func(request, *args, **kwargs)
  File "/usr/local/lib/python3.5/dist-packages/django/views/decorators/cache.py", line 44, in _wrapped_view_func
    response = view_func(request, *args, **kwargs)
  File "/usr/local/lib/python3.5/dist-packages/django/contrib/admin/sites.py", line 223, in inner
    return view(request, *args, **kwargs)
  File "/usr/local/lib/python3.5/dist-packages/django/utils/decorators.py", line 62, in _wrapper
    return bound_func(*args, **kwargs)
  File "/usr/local/lib/python3.5/dist-packages/django/utils/decorators.py", line 142, in _wrapped_view
    response = view_func(request, *args, **kwargs)
  File "/usr/local/lib/python3.5/dist-packages/django/utils/decorators.py", line 58, in bound_func
    return func.__get__(self, type(self))(*args2, **kwargs2)
  File "/usr/local/lib/python3.5/dist-packages/django/contrib/admin/options.py", line 1685, in changelist_view
    selection_note=_('0 of %(cnt)s selected') % {'cnt': len(cl.result_list)},
  File "/usr/local/lib/python3.5/dist-packages/django/db/models/query.py", line 254, in __len__
    self._fetch_all()
  File "/usr/local/lib/python3.5/dist-packages/django/db/models/query.py", line 1179, in _fetch_all
    self._result_cache = list(self._iterable_class(self))
  File "/usr/local/lib/python3.5/dist-packages/django/db/models/query.py", line 54, in __iter__
    results = compiler.execute_sql(chunked_fetch=self.chunked_fetch, chunk_size=self.chunk_size)
  File "/usr/local/lib/python3.5/dist-packages/django/db/models/sql/compiler.py", line 1063, in execute_sql
    cursor.execute(sql, params)
  File "/usr/local/lib/python3.5/dist-packages/django/db/backends/utils.py", line 100, in execute
    return super().execute(sql, params)
  File "/usr/local/lib/python3.5/dist-packages/django/db/backends/utils.py", line 68, in execute
    return self._execute_with_wrappers(sql, params, many=False, executor=self._execute)
  File "/usr/local/lib/python3.5/dist-packages/django/db/backends/utils.py", line 77, in _execute_with_wrappers
    return executor(sql, params, many, context)
  File "/usr/local/lib/python3.5/dist-packages/django/db/backends/utils.py", line 85, in _execute
    return self.cursor.execute(sql, params)
  File "/usr/local/lib/python3.5/dist-packages/django/db/utils.py", line 89, in __exit__
    raise dj_exc_value.with_traceback(traceback) from exc_value
  File "/usr/local/lib/python3.5/dist-packages/django/db/backends/utils.py", line 85, in _execute
    return self.cursor.execute(sql, params)
django.db.utils.ProgrammingError: column sky_article.label does not exist
LINE 1: ...g", "sky_article"."url", "sky_article"."created", "sky_artic...
                                                             ^

ERROR - [2018-02-24 09:47:21] (exception 17296 139700024813312) Internal Server Error: /admin/sky/course/
Traceback (most recent call last):
  File "/usr/local/lib/python3.5/dist-packages/django/db/backends/utils.py", line 85, in _execute
    return self.cursor.execute(sql, params)
psycopg2.ProgrammingError: column sky_course.created does not exist
LINE 1: ...ore", "sky_course"."img", "sky_course"."content", "sky_cours...
                                                             ^


The above exception was the direct cause of the following exception:

Traceback (most recent call last):
  File "/usr/local/lib/python3.5/dist-packages/django/core/handlers/exception.py", line 35, in inner
    response = get_response(request)
  File "/usr/local/lib/python3.5/dist-packages/django/core/handlers/base.py", line 128, in _get_response
    response = self.process_exception_by_middleware(e, request)
  File "/usr/local/lib/python3.5/dist-packages/channels/handler.py", line 243, in process_exception_by_middleware
    return super(AsgiHandler, self).process_exception_by_middleware(exception, request)
  File "/usr/local/lib/python3.5/dist-packages/django/core/handlers/base.py", line 126, in _get_response
    response = wrapped_callback(request, *callback_args, **callback_kwargs)
  File "/usr/local/lib/python3.5/dist-packages/django/contrib/admin/options.py", line 574, in wrapper
    return self.admin_site.admin_view(view)(*args, **kwargs)
  File "/usr/local/lib/python3.5/dist-packages/django/utils/decorators.py", line 142, in _wrapped_view
    response = view_func(request, *args, **kwargs)
  File "/usr/local/lib/python3.5/dist-packages/django/views/decorators/cache.py", line 44, in _wrapped_view_func
    response = view_func(request, *args, **kwargs)
  File "/usr/local/lib/python3.5/dist-packages/django/contrib/admin/sites.py", line 223, in inner
    return view(request, *args, **kwargs)
  File "/usr/local/lib/python3.5/dist-packages/django/utils/decorators.py", line 62, in _wrapper
    return bound_func(*args, **kwargs)
  File "/usr/local/lib/python3.5/dist-packages/django/utils/decorators.py", line 142, in _wrapped_view
    response = view_func(request, *args, **kwargs)
  File "/usr/local/lib/python3.5/dist-packages/django/utils/decorators.py", line 58, in bound_func
    return func.__get__(self, type(self))(*args2, **kwargs2)
  File "/usr/local/lib/python3.5/dist-packages/django/contrib/admin/options.py", line 1685, in changelist_view
    selection_note=_('0 of %(cnt)s selected') % {'cnt': len(cl.result_list)},
  File "/usr/local/lib/python3.5/dist-packages/django/db/models/query.py", line 254, in __len__
    self._fetch_all()
  File "/usr/local/lib/python3.5/dist-packages/django/db/models/query.py", line 1179, in _fetch_all
    self._result_cache = list(self._iterable_class(self))
  File "/usr/local/lib/python3.5/dist-packages/django/db/models/query.py", line 54, in __iter__
    results = compiler.execute_sql(chunked_fetch=self.chunked_fetch, chunk_size=self.chunk_size)
  File "/usr/local/lib/python3.5/dist-packages/django/db/models/sql/compiler.py", line 1063, in execute_sql
    cursor.execute(sql, params)
  File "/usr/local/lib/python3.5/dist-packages/django/db/backends/utils.py", line 100, in execute
    return super().execute(sql, params)
  File "/usr/local/lib/python3.5/dist-packages/django/db/backends/utils.py", line 68, in execute
    return self._execute_with_wrappers(sql, params, many=False, executor=self._execute)
  File "/usr/local/lib/python3.5/dist-packages/django/db/backends/utils.py", line 77, in _execute_with_wrappers
    return executor(sql, params, many, context)
  File "/usr/local/lib/python3.5/dist-packages/django/db/backends/utils.py", line 85, in _execute
    return self.cursor.execute(sql, params)
  File "/usr/local/lib/python3.5/dist-packages/django/db/utils.py", line 89, in __exit__
    raise dj_exc_value.with_traceback(traceback) from exc_value
  File "/usr/local/lib/python3.5/dist-packages/django/db/backends/utils.py", line 85, in _execute
    return self.cursor.execute(sql, params)
django.db.utils.ProgrammingError: column sky_course.created does not exist
LINE 1: ...ore", "sky_course"."img", "sky_course"."content", "sky_cours...
                                                             ^

ERROR - [2018-02-24 09:47:34] (exception 17296 139700033206016) Internal Server Error: /admin/sky/course/
Traceback (most recent call last):
  File "/usr/local/lib/python3.5/dist-packages/django/db/backends/utils.py", line 85, in _execute
    return self.cursor.execute(sql, params)
psycopg2.ProgrammingError: column sky_course.created does not exist
LINE 1: ...ore", "sky_course"."img", "sky_course"."content", "sky_cours...
                                                             ^


The above exception was the direct cause of the following exception:

Traceback (most recent call last):
  File "/usr/local/lib/python3.5/dist-packages/django/core/handlers/exception.py", line 35, in inner
    response = get_response(request)
  File "/usr/local/lib/python3.5/dist-packages/django/core/handlers/base.py", line 128, in _get_response
    response = self.process_exception_by_middleware(e, request)
  File "/usr/local/lib/python3.5/dist-packages/channels/handler.py", line 243, in process_exception_by_middleware
    return super(AsgiHandler, self).process_exception_by_middleware(exception, request)
  File "/usr/local/lib/python3.5/dist-packages/django/core/handlers/base.py", line 126, in _get_response
    response = wrapped_callback(request, *callback_args, **callback_kwargs)
  File "/usr/local/lib/python3.5/dist-packages/django/contrib/admin/options.py", line 574, in wrapper
    return self.admin_site.admin_view(view)(*args, **kwargs)
  File "/usr/local/lib/python3.5/dist-packages/django/utils/decorators.py", line 142, in _wrapped_view
    response = view_func(request, *args, **kwargs)
  File "/usr/local/lib/python3.5/dist-packages/django/views/decorators/cache.py", line 44, in _wrapped_view_func
    response = view_func(request, *args, **kwargs)
  File "/usr/local/lib/python3.5/dist-packages/django/contrib/admin/sites.py", line 223, in inner
    return view(request, *args, **kwargs)
  File "/usr/local/lib/python3.5/dist-packages/django/utils/decorators.py", line 62, in _wrapper
    return bound_func(*args, **kwargs)
  File "/usr/local/lib/python3.5/dist-packages/django/utils/decorators.py", line 142, in _wrapped_view
    response = view_func(request, *args, **kwargs)
  File "/usr/local/lib/python3.5/dist-packages/django/utils/decorators.py", line 58, in bound_func
    return func.__get__(self, type(self))(*args2, **kwargs2)
  File "/usr/local/lib/python3.5/dist-packages/django/contrib/admin/options.py", line 1685, in changelist_view
    selection_note=_('0 of %(cnt)s selected') % {'cnt': len(cl.result_list)},
  File "/usr/local/lib/python3.5/dist-packages/django/db/models/query.py", line 254, in __len__
    self._fetch_all()
  File "/usr/local/lib/python3.5/dist-packages/django/db/models/query.py", line 1179, in _fetch_all
    self._result_cache = list(self._iterable_class(self))
  File "/usr/local/lib/python3.5/dist-packages/django/db/models/query.py", line 54, in __iter__
    results = compiler.execute_sql(chunked_fetch=self.chunked_fetch, chunk_size=self.chunk_size)
  File "/usr/local/lib/python3.5/dist-packages/django/db/models/sql/compiler.py", line 1063, in execute_sql
    cursor.execute(sql, params)
  File "/usr/local/lib/python3.5/dist-packages/django/db/backends/utils.py", line 100, in execute
    return super().execute(sql, params)
  File "/usr/local/lib/python3.5/dist-packages/django/db/backends/utils.py", line 68, in execute
    return self._execute_with_wrappers(sql, params, many=False, executor=self._execute)
  File "/usr/local/lib/python3.5/dist-packages/django/db/backends/utils.py", line 77, in _execute_with_wrappers
    return executor(sql, params, many, context)
  File "/usr/local/lib/python3.5/dist-packages/django/db/backends/utils.py", line 85, in _execute
    return self.cursor.execute(sql, params)
  File "/usr/local/lib/python3.5/dist-packages/django/db/utils.py", line 89, in __exit__
    raise dj_exc_value.with_traceback(traceback) from exc_value
  File "/usr/local/lib/python3.5/dist-packages/django/db/backends/utils.py", line 85, in _execute
    return self.cursor.execute(sql, params)
django.db.utils.ProgrammingError: column sky_course.created does not exist
LINE 1: ...ore", "sky_course"."img", "sky_course"."content", "sky_cours...
                                                             ^

ERROR - [2018-02-24 09:56:14] (exception 17998 140531344697088) Internal Server Error: /sky/articles
Traceback (most recent call last):
  File "/usr/local/lib/python3.5/dist-packages/django/core/handlers/exception.py", line 35, in inner
    response = get_response(request)
  File "/usr/local/lib/python3.5/dist-packages/django/core/handlers/base.py", line 128, in _get_response
    response = self.process_exception_by_middleware(e, request)
  File "/usr/local/lib/python3.5/dist-packages/channels/handler.py", line 243, in process_exception_by_middleware
    return super(AsgiHandler, self).process_exception_by_middleware(exception, request)
  File "/usr/local/lib/python3.5/dist-packages/django/core/handlers/base.py", line 126, in _get_response
    response = wrapped_callback(request, *callback_args, **callback_kwargs)
  File "/usr/local/lib/python3.5/dist-packages/django/views/decorators/csrf.py", line 54, in wrapped_view
    return view_func(*args, **kwargs)
  File "/usr/local/lib/python3.5/dist-packages/django/views/generic/base.py", line 69, in view
    return self.dispatch(request, *args, **kwargs)
  File "/usr/local/lib/python3.5/dist-packages/rest_framework/views.py", line 489, in dispatch
    response = self.handle_exception(exc)
  File "/usr/local/lib/python3.5/dist-packages/rest_framework/views.py", line 449, in handle_exception
    self.raise_uncaught_exception(exc)
  File "/usr/local/lib/python3.5/dist-packages/rest_framework/views.py", line 486, in dispatch
    response = handler(request, *args, **kwargs)
  File "/usr/local/lib/python3.5/dist-packages/rest_framework/generics.py", line 201, in get
    return self.list(request, *args, **kwargs)
  File "/usr/local/lib/python3.5/dist-packages/rest_framework/mixins.py", line 40, in list
    queryset = self.filter_queryset(self.get_queryset())
  File "/home/eethan1/Desktop/IMnight2018_Backend/IMnight/sky/views.py", line 35, in get_queryset
    queryset = Article.objects.filter(label=int(q['label']))\
TypeError: int() argument must be a string, a bytes-like object or a number, not 'NoneType'
ERROR - [2018-02-24 11:11:26] (exception 21595 140052936681216) Internal Server Error: /sky/news/
Traceback (most recent call last):
  File "/usr/local/lib/python3.5/dist-packages/django/core/handlers/exception.py", line 35, in inner
    response = get_response(request)
  File "/usr/local/lib/python3.5/dist-packages/django/core/handlers/base.py", line 128, in _get_response
    response = self.process_exception_by_middleware(e, request)
  File "/usr/local/lib/python3.5/dist-packages/channels/handler.py", line 243, in process_exception_by_middleware
    return super(AsgiHandler, self).process_exception_by_middleware(exception, request)
  File "/usr/local/lib/python3.5/dist-packages/django/core/handlers/base.py", line 126, in _get_response
    response = wrapped_callback(request, *callback_args, **callback_kwargs)
  File "/usr/local/lib/python3.5/dist-packages/django/views/decorators/csrf.py", line 54, in wrapped_view
    return view_func(*args, **kwargs)
  File "/usr/local/lib/python3.5/dist-packages/django/views/generic/base.py", line 69, in view
    return self.dispatch(request, *args, **kwargs)
  File "/usr/local/lib/python3.5/dist-packages/rest_framework/views.py", line 489, in dispatch
    response = self.handle_exception(exc)
  File "/usr/local/lib/python3.5/dist-packages/rest_framework/views.py", line 449, in handle_exception
    self.raise_uncaught_exception(exc)
  File "/usr/local/lib/python3.5/dist-packages/rest_framework/views.py", line 486, in dispatch
    response = handler(request, *args, **kwargs)
  File "/usr/local/lib/python3.5/dist-packages/rest_framework/generics.py", line 201, in get
    return self.list(request, *args, **kwargs)
  File "/usr/local/lib/python3.5/dist-packages/rest_framework/mixins.py", line 40, in list
    queryset = self.filter_queryset(self.get_queryset())
  File "/home/eethan1/Desktop/IMnight2018_Backend/IMnight/sky/views.py", line 73, in get_queryset
    if q['num'] > QUERY_MAX:
TypeError: unorderable types: str() > int()
ERROR - [2018-02-24 11:17:01] (exception 22098 140515235636992) Internal Server Error: /sky/news/
Traceback (most recent call last):
  File "/usr/local/lib/python3.5/dist-packages/django/core/handlers/exception.py", line 35, in inner
    response = get_response(request)
  File "/usr/local/lib/python3.5/dist-packages/django/core/handlers/base.py", line 128, in _get_response
    response = self.process_exception_by_middleware(e, request)
  File "/usr/local/lib/python3.5/dist-packages/channels/handler.py", line 243, in process_exception_by_middleware
    return super(AsgiHandler, self).process_exception_by_middleware(exception, request)
  File "/usr/local/lib/python3.5/dist-packages/django/core/handlers/base.py", line 126, in _get_response
    response = wrapped_callback(request, *callback_args, **callback_kwargs)
  File "/usr/local/lib/python3.5/dist-packages/django/views/decorators/csrf.py", line 54, in wrapped_view
    return view_func(*args, **kwargs)
  File "/usr/local/lib/python3.5/dist-packages/django/views/generic/base.py", line 69, in view
    return self.dispatch(request, *args, **kwargs)
  File "/usr/local/lib/python3.5/dist-packages/rest_framework/views.py", line 489, in dispatch
    response = self.handle_exception(exc)
  File "/usr/local/lib/python3.5/dist-packages/rest_framework/views.py", line 449, in handle_exception
    self.raise_uncaught_exception(exc)
  File "/usr/local/lib/python3.5/dist-packages/rest_framework/views.py", line 486, in dispatch
    response = handler(request, *args, **kwargs)
  File "/usr/local/lib/python3.5/dist-packages/rest_framework/generics.py", line 201, in get
    return self.list(request, *args, **kwargs)
  File "/usr/local/lib/python3.5/dist-packages/rest_framework/mixins.py", line 40, in list
    queryset = self.filter_queryset(self.get_queryset())
  File "/home/eethan1/Desktop/IMnight2018_Backend/IMnight/sky/views.py", line 73, in get_queryset
    if q['num'] > QUERY_MAX:
TypeError: unorderable types: str() > int()
ERROR - [2018-02-24 11:17:23] (exception 22098 140515156686592) Internal Server Error: /admin/sky/news/
Traceback (most recent call last):
  File "/usr/local/lib/python3.5/dist-packages/django/db/backends/utils.py", line 85, in _execute
    return self.cursor.execute(sql, params)
psycopg2.ProgrammingError: column sky_news.label does not exist
LINE 1: ...."title", "sky_news"."url", "sky_news"."created", "sky_news"...
                                                             ^


The above exception was the direct cause of the following exception:

Traceback (most recent call last):
  File "/usr/local/lib/python3.5/dist-packages/django/core/handlers/exception.py", line 35, in inner
    response = get_response(request)
  File "/usr/local/lib/python3.5/dist-packages/django/core/handlers/base.py", line 128, in _get_response
    response = self.process_exception_by_middleware(e, request)
  File "/usr/local/lib/python3.5/dist-packages/channels/handler.py", line 243, in process_exception_by_middleware
    return super(AsgiHandler, self).process_exception_by_middleware(exception, request)
  File "/usr/local/lib/python3.5/dist-packages/django/core/handlers/base.py", line 126, in _get_response
    response = wrapped_callback(request, *callback_args, **callback_kwargs)
  File "/usr/local/lib/python3.5/dist-packages/django/contrib/admin/options.py", line 574, in wrapper
    return self.admin_site.admin_view(view)(*args, **kwargs)
  File "/usr/local/lib/python3.5/dist-packages/django/utils/decorators.py", line 142, in _wrapped_view
    response = view_func(request, *args, **kwargs)
  File "/usr/local/lib/python3.5/dist-packages/django/views/decorators/cache.py", line 44, in _wrapped_view_func
    response = view_func(request, *args, **kwargs)
  File "/usr/local/lib/python3.5/dist-packages/django/contrib/admin/sites.py", line 223, in inner
    return view(request, *args, **kwargs)
  File "/usr/local/lib/python3.5/dist-packages/django/utils/decorators.py", line 62, in _wrapper
    return bound_func(*args, **kwargs)
  File "/usr/local/lib/python3.5/dist-packages/django/utils/decorators.py", line 142, in _wrapped_view
    response = view_func(request, *args, **kwargs)
  File "/usr/local/lib/python3.5/dist-packages/django/utils/decorators.py", line 58, in bound_func
    return func.__get__(self, type(self))(*args2, **kwargs2)
  File "/usr/local/lib/python3.5/dist-packages/django/contrib/admin/options.py", line 1685, in changelist_view
    selection_note=_('0 of %(cnt)s selected') % {'cnt': len(cl.result_list)},
  File "/usr/local/lib/python3.5/dist-packages/django/db/models/query.py", line 254, in __len__
    self._fetch_all()
  File "/usr/local/lib/python3.5/dist-packages/django/db/models/query.py", line 1179, in _fetch_all
    self._result_cache = list(self._iterable_class(self))
  File "/usr/local/lib/python3.5/dist-packages/django/db/models/query.py", line 54, in __iter__
    results = compiler.execute_sql(chunked_fetch=self.chunked_fetch, chunk_size=self.chunk_size)
  File "/usr/local/lib/python3.5/dist-packages/django/db/models/sql/compiler.py", line 1063, in execute_sql
    cursor.execute(sql, params)
  File "/usr/local/lib/python3.5/dist-packages/django/db/backends/utils.py", line 100, in execute
    return super().execute(sql, params)
  File "/usr/local/lib/python3.5/dist-packages/django/db/backends/utils.py", line 68, in execute
    return self._execute_with_wrappers(sql, params, many=False, executor=self._execute)
  File "/usr/local/lib/python3.5/dist-packages/django/db/backends/utils.py", line 77, in _execute_with_wrappers
    return executor(sql, params, many, context)
  File "/usr/local/lib/python3.5/dist-packages/django/db/backends/utils.py", line 85, in _execute
    return self.cursor.execute(sql, params)
  File "/usr/local/lib/python3.5/dist-packages/django/db/utils.py", line 89, in __exit__
    raise dj_exc_value.with_traceback(traceback) from exc_value
  File "/usr/local/lib/python3.5/dist-packages/django/db/backends/utils.py", line 85, in _execute
    return self.cursor.execute(sql, params)
django.db.utils.ProgrammingError: column sky_news.label does not exist
LINE 1: ...."title", "sky_news"."url", "sky_news"."created", "sky_news"...
                                                             ^

ERROR - [2018-02-24 11:18:19] (exception 22189 140469312681728) Internal Server Error: /sky/news/
Traceback (most recent call last):
  File "/usr/local/lib/python3.5/dist-packages/django/core/handlers/exception.py", line 35, in inner
    response = get_response(request)
  File "/usr/local/lib/python3.5/dist-packages/django/core/handlers/base.py", line 128, in _get_response
    response = self.process_exception_by_middleware(e, request)
  File "/usr/local/lib/python3.5/dist-packages/channels/handler.py", line 243, in process_exception_by_middleware
    return super(AsgiHandler, self).process_exception_by_middleware(exception, request)
  File "/usr/local/lib/python3.5/dist-packages/django/core/handlers/base.py", line 126, in _get_response
    response = wrapped_callback(request, *callback_args, **callback_kwargs)
  File "/usr/local/lib/python3.5/dist-packages/django/views/decorators/csrf.py", line 54, in wrapped_view
    return view_func(*args, **kwargs)
  File "/usr/local/lib/python3.5/dist-packages/django/views/generic/base.py", line 69, in view
    return self.dispatch(request, *args, **kwargs)
  File "/usr/local/lib/python3.5/dist-packages/rest_framework/views.py", line 489, in dispatch
    response = self.handle_exception(exc)
  File "/usr/local/lib/python3.5/dist-packages/rest_framework/views.py", line 449, in handle_exception
    self.raise_uncaught_exception(exc)
  File "/usr/local/lib/python3.5/dist-packages/rest_framework/views.py", line 486, in dispatch
    response = handler(request, *args, **kwargs)
  File "/usr/local/lib/python3.5/dist-packages/rest_framework/generics.py", line 201, in get
    return self.list(request, *args, **kwargs)
  File "/usr/local/lib/python3.5/dist-packages/rest_framework/mixins.py", line 40, in list
    queryset = self.filter_queryset(self.get_queryset())
  File "/home/eethan1/Desktop/IMnight2018_Backend/IMnight/sky/views.py", line 73, in get_queryset
    if q['num'] > QUERY_MAX:
TypeError: unorderable types: str() > int()
WARNING - [2018-02-24 11:38:17] (base 23650 139706008327936) Not Found: /favicon.ico
ERROR - [2018-02-24 11:48:55] (exception 23988 140102688823040) Internal Server Error: /sky/news/
Traceback (most recent call last):
  File "/usr/local/lib/python3.5/dist-packages/django/core/handlers/exception.py", line 35, in inner
    response = get_response(request)
  File "/usr/local/lib/python3.5/dist-packages/django/core/handlers/base.py", line 128, in _get_response
    response = self.process_exception_by_middleware(e, request)
  File "/usr/local/lib/python3.5/dist-packages/channels/handler.py", line 243, in process_exception_by_middleware
    return super(AsgiHandler, self).process_exception_by_middleware(exception, request)
  File "/usr/local/lib/python3.5/dist-packages/django/core/handlers/base.py", line 126, in _get_response
    response = wrapped_callback(request, *callback_args, **callback_kwargs)
  File "/usr/local/lib/python3.5/dist-packages/django/views/decorators/csrf.py", line 54, in wrapped_view
    return view_func(*args, **kwargs)
  File "/usr/local/lib/python3.5/dist-packages/django/views/generic/base.py", line 69, in view
    return self.dispatch(request, *args, **kwargs)
  File "/usr/local/lib/python3.5/dist-packages/rest_framework/views.py", line 489, in dispatch
    response = self.handle_exception(exc)
  File "/usr/local/lib/python3.5/dist-packages/rest_framework/views.py", line 449, in handle_exception
    self.raise_uncaught_exception(exc)
  File "/usr/local/lib/python3.5/dist-packages/rest_framework/views.py", line 486, in dispatch
    response = handler(request, *args, **kwargs)
  File "/usr/local/lib/python3.5/dist-packages/rest_framework/generics.py", line 201, in get
    return self.list(request, *args, **kwargs)
  File "/usr/local/lib/python3.5/dist-packages/rest_framework/mixins.py", line 40, in list
    queryset = self.filter_queryset(self.get_queryset())
  File "/home/eethan1/Desktop/IMnight2018_Backend/IMnight/sky/views.py", line 73, in get_queryset
    if q['num'] > QUERY_MAX:
TypeError: unorderable types: str() > int()
WARNING - [2018-02-24 11:50:05] (base 23988 140102680430336) Not Found: /sky/newss
ERROR - [2018-02-24 11:50:13] (exception 23988 140102705608448) Internal Server Error: /sky/news/
Traceback (most recent call last):
  File "/usr/local/lib/python3.5/dist-packages/django/core/handlers/exception.py", line 35, in inner
    response = get_response(request)
  File "/usr/local/lib/python3.5/dist-packages/django/core/handlers/base.py", line 128, in _get_response
    response = self.process_exception_by_middleware(e, request)
  File "/usr/local/lib/python3.5/dist-packages/channels/handler.py", line 243, in process_exception_by_middleware
    return super(AsgiHandler, self).process_exception_by_middleware(exception, request)
  File "/usr/local/lib/python3.5/dist-packages/django/core/handlers/base.py", line 126, in _get_response
    response = wrapped_callback(request, *callback_args, **callback_kwargs)
  File "/usr/local/lib/python3.5/dist-packages/django/views/decorators/csrf.py", line 54, in wrapped_view
    return view_func(*args, **kwargs)
  File "/usr/local/lib/python3.5/dist-packages/django/views/generic/base.py", line 69, in view
    return self.dispatch(request, *args, **kwargs)
  File "/usr/local/lib/python3.5/dist-packages/rest_framework/views.py", line 489, in dispatch
    response = self.handle_exception(exc)
  File "/usr/local/lib/python3.5/dist-packages/rest_framework/views.py", line 449, in handle_exception
    self.raise_uncaught_exception(exc)
  File "/usr/local/lib/python3.5/dist-packages/rest_framework/views.py", line 486, in dispatch
    response = handler(request, *args, **kwargs)
  File "/usr/local/lib/python3.5/dist-packages/rest_framework/generics.py", line 201, in get
    return self.list(request, *args, **kwargs)
  File "/usr/local/lib/python3.5/dist-packages/rest_framework/mixins.py", line 40, in list
    queryset = self.filter_queryset(self.get_queryset())
  File "/home/eethan1/Desktop/IMnight2018_Backend/IMnight/sky/views.py", line 73, in get_queryset
    if q['num'] > QUERY_MAX:
TypeError: unorderable types: str() > int()
WARNING - [2018-02-24 11:50:18] (base 23988 140102697215744) Not Found: /sky/news/1
ERROR - [2018-02-24 11:50:24] (exception 23988 140102705608448) Internal Server Error: /sky/news/
Traceback (most recent call last):
  File "/usr/local/lib/python3.5/dist-packages/django/core/handlers/exception.py", line 35, in inner
    response = get_response(request)
  File "/usr/local/lib/python3.5/dist-packages/django/core/handlers/base.py", line 128, in _get_response
    response = self.process_exception_by_middleware(e, request)
  File "/usr/local/lib/python3.5/dist-packages/channels/handler.py", line 243, in process_exception_by_middleware
    return super(AsgiHandler, self).process_exception_by_middleware(exception, request)
  File "/usr/local/lib/python3.5/dist-packages/django/core/handlers/base.py", line 126, in _get_response
    response = wrapped_callback(request, *callback_args, **callback_kwargs)
  File "/usr/local/lib/python3.5/dist-packages/django/views/decorators/csrf.py", line 54, in wrapped_view
    return view_func(*args, **kwargs)
  File "/usr/local/lib/python3.5/dist-packages/django/views/generic/base.py", line 69, in view
    return self.dispatch(request, *args, **kwargs)
  File "/usr/local/lib/python3.5/dist-packages/rest_framework/views.py", line 489, in dispatch
    response = self.handle_exception(exc)
  File "/usr/local/lib/python3.5/dist-packages/rest_framework/views.py", line 449, in handle_exception
    self.raise_uncaught_exception(exc)
  File "/usr/local/lib/python3.5/dist-packages/rest_framework/views.py", line 486, in dispatch
    response = handler(request, *args, **kwargs)
  File "/usr/local/lib/python3.5/dist-packages/rest_framework/generics.py", line 201, in get
    return self.list(request, *args, **kwargs)
  File "/usr/local/lib/python3.5/dist-packages/rest_framework/mixins.py", line 40, in list
    queryset = self.filter_queryset(self.get_queryset())
  File "/home/eethan1/Desktop/IMnight2018_Backend/IMnight/sky/views.py", line 73, in get_queryset
    if q['num'] > QUERY_MAX:
TypeError: unorderable types: str() > int()
ERROR - [2018-02-24 11:50:36] (exception 23988 140102705608448) Internal Server Error: /sky/articles
Traceback (most recent call last):
  File "/usr/local/lib/python3.5/dist-packages/django/core/handlers/exception.py", line 35, in inner
    response = get_response(request)
  File "/usr/local/lib/python3.5/dist-packages/django/core/handlers/base.py", line 128, in _get_response
    response = self.process_exception_by_middleware(e, request)
  File "/usr/local/lib/python3.5/dist-packages/channels/handler.py", line 243, in process_exception_by_middleware
    return super(AsgiHandler, self).process_exception_by_middleware(exception, request)
  File "/usr/local/lib/python3.5/dist-packages/django/core/handlers/base.py", line 126, in _get_response
    response = wrapped_callback(request, *callback_args, **callback_kwargs)
  File "/usr/local/lib/python3.5/dist-packages/django/views/decorators/csrf.py", line 54, in wrapped_view
    return view_func(*args, **kwargs)
  File "/usr/local/lib/python3.5/dist-packages/django/views/generic/base.py", line 69, in view
    return self.dispatch(request, *args, **kwargs)
  File "/usr/local/lib/python3.5/dist-packages/rest_framework/views.py", line 489, in dispatch
    response = self.handle_exception(exc)
  File "/usr/local/lib/python3.5/dist-packages/rest_framework/views.py", line 449, in handle_exception
    self.raise_uncaught_exception(exc)
  File "/usr/local/lib/python3.5/dist-packages/rest_framework/views.py", line 486, in dispatch
    response = handler(request, *args, **kwargs)
  File "/usr/local/lib/python3.5/dist-packages/rest_framework/generics.py", line 201, in get
    return self.list(request, *args, **kwargs)
  File "/usr/local/lib/python3.5/dist-packages/rest_framework/mixins.py", line 40, in list
    queryset = self.filter_queryset(self.get_queryset())
  File "/home/eethan1/Desktop/IMnight2018_Backend/IMnight/sky/views.py", line 49, in get_queryset
    if q['num'] > QUERY_MAX:
TypeError: unorderable types: str() > int()
WARNING - [2018-02-24 11:50:51] (base 23988 140102705608448) Not Found: /sky/cources
ERROR - [2018-02-24 11:50:56] (exception 23988 140102705608448) Internal Server Error: /sky/courses
Traceback (most recent call last):
  File "/usr/local/lib/python3.5/dist-packages/django/core/handlers/exception.py", line 35, in inner
    response = get_response(request)
  File "/usr/local/lib/python3.5/dist-packages/django/core/handlers/base.py", line 128, in _get_response
    response = self.process_exception_by_middleware(e, request)
  File "/usr/local/lib/python3.5/dist-packages/channels/handler.py", line 243, in process_exception_by_middleware
    return super(AsgiHandler, self).process_exception_by_middleware(exception, request)
  File "/usr/local/lib/python3.5/dist-packages/django/core/handlers/base.py", line 126, in _get_response
    response = wrapped_callback(request, *callback_args, **callback_kwargs)
  File "/usr/local/lib/python3.5/dist-packages/django/views/decorators/csrf.py", line 54, in wrapped_view
    return view_func(*args, **kwargs)
  File "/usr/local/lib/python3.5/dist-packages/django/views/generic/base.py", line 69, in view
    return self.dispatch(request, *args, **kwargs)
  File "/usr/local/lib/python3.5/dist-packages/rest_framework/views.py", line 489, in dispatch
    response = self.handle_exception(exc)
  File "/usr/local/lib/python3.5/dist-packages/rest_framework/views.py", line 449, in handle_exception
    self.raise_uncaught_exception(exc)
  File "/usr/local/lib/python3.5/dist-packages/rest_framework/views.py", line 486, in dispatch
    response = handler(request, *args, **kwargs)
  File "/usr/local/lib/python3.5/dist-packages/rest_framework/generics.py", line 201, in get
    return self.list(request, *args, **kwargs)
  File "/usr/local/lib/python3.5/dist-packages/rest_framework/mixins.py", line 40, in list
    queryset = self.filter_queryset(self.get_queryset())
  File "/home/eethan1/Desktop/IMnight2018_Backend/IMnight/sky/views.py", line 28, in get_queryset
    if q['num'] > QUERY_MAX:
TypeError: unorderable types: str() > int()
ERROR - [2018-02-24 11:52:48] (exception 24224 140029874624256) Internal Server Error: /sky/news/
Traceback (most recent call last):
  File "/usr/local/lib/python3.5/dist-packages/django/core/handlers/exception.py", line 35, in inner
    response = get_response(request)
  File "/usr/local/lib/python3.5/dist-packages/django/core/handlers/base.py", line 128, in _get_response
    response = self.process_exception_by_middleware(e, request)
  File "/usr/local/lib/python3.5/dist-packages/channels/handler.py", line 243, in process_exception_by_middleware
    return super(AsgiHandler, self).process_exception_by_middleware(exception, request)
  File "/usr/local/lib/python3.5/dist-packages/django/core/handlers/base.py", line 126, in _get_response
    response = wrapped_callback(request, *callback_args, **callback_kwargs)
  File "/usr/local/lib/python3.5/dist-packages/django/views/decorators/csrf.py", line 54, in wrapped_view
    return view_func(*args, **kwargs)
  File "/usr/local/lib/python3.5/dist-packages/django/views/generic/base.py", line 69, in view
    return self.dispatch(request, *args, **kwargs)
  File "/usr/local/lib/python3.5/dist-packages/rest_framework/views.py", line 489, in dispatch
    response = self.handle_exception(exc)
  File "/usr/local/lib/python3.5/dist-packages/rest_framework/views.py", line 449, in handle_exception
    self.raise_uncaught_exception(exc)
  File "/usr/local/lib/python3.5/dist-packages/rest_framework/views.py", line 486, in dispatch
    response = handler(request, *args, **kwargs)
  File "/usr/local/lib/python3.5/dist-packages/rest_framework/generics.py", line 201, in get
    return self.list(request, *args, **kwargs)
  File "/usr/local/lib/python3.5/dist-packages/rest_framework/mixins.py", line 48, in list
    return Response(serializer.data)
  File "/usr/local/lib/python3.5/dist-packages/rest_framework/serializers.py", line 738, in data
    ret = super(ListSerializer, self).data
  File "/usr/local/lib/python3.5/dist-packages/rest_framework/serializers.py", line 262, in data
    self._data = self.to_representation(self.instance)
  File "/usr/local/lib/python3.5/dist-packages/rest_framework/serializers.py", line 656, in to_representation
    self.child.to_representation(item) for item in iterable
  File "/usr/local/lib/python3.5/dist-packages/rest_framework/serializers.py", line 656, in <listcomp>
    self.child.to_representation(item) for item in iterable
  File "/usr/local/lib/python3.5/dist-packages/rest_framework/serializers.py", line 483, in to_representation
    fields = self._readable_fields
  File "/usr/local/lib/python3.5/dist-packages/django/utils/functional.py", line 36, in __get__
    res = instance.__dict__[self.name] = self.func(instance)
  File "/usr/local/lib/python3.5/dist-packages/rest_framework/serializers.py", line 377, in _readable_fields
    field for field in self.fields.values()
  File "/usr/local/lib/python3.5/dist-packages/rest_framework/serializers.py", line 363, in fields
    for key, value in self.get_fields().items():
  File "/usr/local/lib/python3.5/dist-packages/rest_framework/serializers.py", line 993, in get_fields
    field_names = self.get_field_names(declared_fields, info)
  File "/usr/local/lib/python3.5/dist-packages/rest_framework/serializers.py", line 1055, in get_field_names
    type(exclude).__name__
TypeError: The `exclude` option must be a list or tuple. Got str.
ERROR - [2018-02-24 11:52:48] (exception 24224 140029866231552) Internal Server Error: /sky/news/
Traceback (most recent call last):
  File "/usr/local/lib/python3.5/dist-packages/django/core/handlers/exception.py", line 35, in inner
    response = get_response(request)
  File "/usr/local/lib/python3.5/dist-packages/django/core/handlers/base.py", line 128, in _get_response
    response = self.process_exception_by_middleware(e, request)
  File "/usr/local/lib/python3.5/dist-packages/channels/handler.py", line 243, in process_exception_by_middleware
    return super(AsgiHandler, self).process_exception_by_middleware(exception, request)
  File "/usr/local/lib/python3.5/dist-packages/django/core/handlers/base.py", line 126, in _get_response
    response = wrapped_callback(request, *callback_args, **callback_kwargs)
  File "/usr/local/lib/python3.5/dist-packages/django/views/decorators/csrf.py", line 54, in wrapped_view
    return view_func(*args, **kwargs)
  File "/usr/local/lib/python3.5/dist-packages/django/views/generic/base.py", line 69, in view
    return self.dispatch(request, *args, **kwargs)
  File "/usr/local/lib/python3.5/dist-packages/rest_framework/views.py", line 489, in dispatch
    response = self.handle_exception(exc)
  File "/usr/local/lib/python3.5/dist-packages/rest_framework/views.py", line 449, in handle_exception
    self.raise_uncaught_exception(exc)
  File "/usr/local/lib/python3.5/dist-packages/rest_framework/views.py", line 486, in dispatch
    response = handler(request, *args, **kwargs)
  File "/usr/local/lib/python3.5/dist-packages/rest_framework/generics.py", line 201, in get
    return self.list(request, *args, **kwargs)
  File "/usr/local/lib/python3.5/dist-packages/rest_framework/mixins.py", line 48, in list
    return Response(serializer.data)
  File "/usr/local/lib/python3.5/dist-packages/rest_framework/serializers.py", line 738, in data
    ret = super(ListSerializer, self).data
  File "/usr/local/lib/python3.5/dist-packages/rest_framework/serializers.py", line 262, in data
    self._data = self.to_representation(self.instance)
  File "/usr/local/lib/python3.5/dist-packages/rest_framework/serializers.py", line 656, in to_representation
    self.child.to_representation(item) for item in iterable
  File "/usr/local/lib/python3.5/dist-packages/rest_framework/serializers.py", line 656, in <listcomp>
    self.child.to_representation(item) for item in iterable
  File "/usr/local/lib/python3.5/dist-packages/rest_framework/serializers.py", line 483, in to_representation
    fields = self._readable_fields
  File "/usr/local/lib/python3.5/dist-packages/django/utils/functional.py", line 36, in __get__
    res = instance.__dict__[self.name] = self.func(instance)
  File "/usr/local/lib/python3.5/dist-packages/rest_framework/serializers.py", line 377, in _readable_fields
    field for field in self.fields.values()
  File "/usr/local/lib/python3.5/dist-packages/rest_framework/serializers.py", line 363, in fields
    for key, value in self.get_fields().items():
  File "/usr/local/lib/python3.5/dist-packages/rest_framework/serializers.py", line 993, in get_fields
    field_names = self.get_field_names(declared_fields, info)
  File "/usr/local/lib/python3.5/dist-packages/rest_framework/serializers.py", line 1055, in get_field_names
    type(exclude).__name__
TypeError: The `exclude` option must be a list or tuple. Got str.
ERROR - [2018-02-24 11:53:55] (exception 24285 140460948412160) Internal Server Error: /sky/articles
Traceback (most recent call last):
  File "/usr/local/lib/python3.5/dist-packages/django/core/handlers/exception.py", line 35, in inner
    response = get_response(request)
  File "/usr/local/lib/python3.5/dist-packages/django/core/handlers/base.py", line 128, in _get_response
    response = self.process_exception_by_middleware(e, request)
  File "/usr/local/lib/python3.5/dist-packages/channels/handler.py", line 243, in process_exception_by_middleware
    return super(AsgiHandler, self).process_exception_by_middleware(exception, request)
  File "/usr/local/lib/python3.5/dist-packages/django/core/handlers/base.py", line 126, in _get_response
    response = wrapped_callback(request, *callback_args, **callback_kwargs)
  File "/usr/local/lib/python3.5/dist-packages/django/views/decorators/csrf.py", line 54, in wrapped_view
    return view_func(*args, **kwargs)
  File "/usr/local/lib/python3.5/dist-packages/django/views/generic/base.py", line 69, in view
    return self.dispatch(request, *args, **kwargs)
  File "/usr/local/lib/python3.5/dist-packages/rest_framework/views.py", line 489, in dispatch
    response = self.handle_exception(exc)
  File "/usr/local/lib/python3.5/dist-packages/rest_framework/views.py", line 449, in handle_exception
    self.raise_uncaught_exception(exc)
  File "/usr/local/lib/python3.5/dist-packages/rest_framework/views.py", line 486, in dispatch
    response = handler(request, *args, **kwargs)
  File "/usr/local/lib/python3.5/dist-packages/rest_framework/generics.py", line 201, in get
    return self.list(request, *args, **kwargs)
  File "/usr/local/lib/python3.5/dist-packages/rest_framework/mixins.py", line 48, in list
    return Response(serializer.data)
  File "/usr/local/lib/python3.5/dist-packages/rest_framework/serializers.py", line 738, in data
    ret = super(ListSerializer, self).data
  File "/usr/local/lib/python3.5/dist-packages/rest_framework/serializers.py", line 262, in data
    self._data = self.to_representation(self.instance)
  File "/usr/local/lib/python3.5/dist-packages/rest_framework/serializers.py", line 656, in to_representation
    self.child.to_representation(item) for item in iterable
  File "/usr/local/lib/python3.5/dist-packages/rest_framework/serializers.py", line 656, in <listcomp>
    self.child.to_representation(item) for item in iterable
  File "/usr/local/lib/python3.5/dist-packages/rest_framework/serializers.py", line 483, in to_representation
    fields = self._readable_fields
  File "/usr/local/lib/python3.5/dist-packages/django/utils/functional.py", line 36, in __get__
    res = instance.__dict__[self.name] = self.func(instance)
  File "/usr/local/lib/python3.5/dist-packages/rest_framework/serializers.py", line 377, in _readable_fields
    field for field in self.fields.values()
  File "/usr/local/lib/python3.5/dist-packages/rest_framework/serializers.py", line 363, in fields
    for key, value in self.get_fields().items():
  File "/usr/local/lib/python3.5/dist-packages/rest_framework/serializers.py", line 993, in get_fields
    field_names = self.get_field_names(declared_fields, info)
  File "/usr/local/lib/python3.5/dist-packages/rest_framework/serializers.py", line 1061, in get_field_names
    serializer_class=self.__class__.__name__
AssertionError: Cannot set both 'fields' and 'exclude' options on serializer ArticleSerializer.
ERROR - [2018-02-24 11:54:18] (exception 24356 139665719576320) Internal Server Error: /sky/articles
Traceback (most recent call last):
  File "/usr/local/lib/python3.5/dist-packages/django/core/handlers/exception.py", line 35, in inner
    response = get_response(request)
  File "/usr/local/lib/python3.5/dist-packages/django/core/handlers/base.py", line 128, in _get_response
    response = self.process_exception_by_middleware(e, request)
  File "/usr/local/lib/python3.5/dist-packages/channels/handler.py", line 243, in process_exception_by_middleware
    return super(AsgiHandler, self).process_exception_by_middleware(exception, request)
  File "/usr/local/lib/python3.5/dist-packages/django/core/handlers/base.py", line 126, in _get_response
    response = wrapped_callback(request, *callback_args, **callback_kwargs)
  File "/usr/local/lib/python3.5/dist-packages/django/views/decorators/csrf.py", line 54, in wrapped_view
    return view_func(*args, **kwargs)
  File "/usr/local/lib/python3.5/dist-packages/django/views/generic/base.py", line 69, in view
    return self.dispatch(request, *args, **kwargs)
  File "/usr/local/lib/python3.5/dist-packages/rest_framework/views.py", line 489, in dispatch
    response = self.handle_exception(exc)
  File "/usr/local/lib/python3.5/dist-packages/rest_framework/views.py", line 449, in handle_exception
    self.raise_uncaught_exception(exc)
  File "/usr/local/lib/python3.5/dist-packages/rest_framework/views.py", line 486, in dispatch
    response = handler(request, *args, **kwargs)
  File "/usr/local/lib/python3.5/dist-packages/rest_framework/generics.py", line 201, in get
    return self.list(request, *args, **kwargs)
  File "/usr/local/lib/python3.5/dist-packages/rest_framework/mixins.py", line 48, in list
    return Response(serializer.data)
  File "/usr/local/lib/python3.5/dist-packages/rest_framework/serializers.py", line 738, in data
    ret = super(ListSerializer, self).data
  File "/usr/local/lib/python3.5/dist-packages/rest_framework/serializers.py", line 262, in data
    self._data = self.to_representation(self.instance)
  File "/usr/local/lib/python3.5/dist-packages/rest_framework/serializers.py", line 656, in to_representation
    self.child.to_representation(item) for item in iterable
  File "/usr/local/lib/python3.5/dist-packages/rest_framework/serializers.py", line 656, in <listcomp>
    self.child.to_representation(item) for item in iterable
  File "/usr/local/lib/python3.5/dist-packages/rest_framework/serializers.py", line 483, in to_representation
    fields = self._readable_fields
  File "/usr/local/lib/python3.5/dist-packages/django/utils/functional.py", line 36, in __get__
    res = instance.__dict__[self.name] = self.func(instance)
  File "/usr/local/lib/python3.5/dist-packages/rest_framework/serializers.py", line 377, in _readable_fields
    field for field in self.fields.values()
  File "/usr/local/lib/python3.5/dist-packages/rest_framework/serializers.py", line 363, in fields
    for key, value in self.get_fields().items():
  File "/usr/local/lib/python3.5/dist-packages/rest_framework/serializers.py", line 993, in get_fields
    field_names = self.get_field_names(declared_fields, info)
  File "/usr/local/lib/python3.5/dist-packages/rest_framework/serializers.py", line 1061, in get_field_names
    serializer_class=self.__class__.__name__
AssertionError: Cannot set both 'fields' and 'exclude' options on serializer ArticleSerializer.
ERROR - [2018-02-24 11:54:19] (exception 24356 139665711183616) Internal Server Error: /sky/articles
Traceback (most recent call last):
  File "/usr/local/lib/python3.5/dist-packages/django/core/handlers/exception.py", line 35, in inner
    response = get_response(request)
  File "/usr/local/lib/python3.5/dist-packages/django/core/handlers/base.py", line 128, in _get_response
    response = self.process_exception_by_middleware(e, request)
  File "/usr/local/lib/python3.5/dist-packages/channels/handler.py", line 243, in process_exception_by_middleware
    return super(AsgiHandler, self).process_exception_by_middleware(exception, request)
  File "/usr/local/lib/python3.5/dist-packages/django/core/handlers/base.py", line 126, in _get_response
    response = wrapped_callback(request, *callback_args, **callback_kwargs)
  File "/usr/local/lib/python3.5/dist-packages/django/views/decorators/csrf.py", line 54, in wrapped_view
    return view_func(*args, **kwargs)
  File "/usr/local/lib/python3.5/dist-packages/django/views/generic/base.py", line 69, in view
    return self.dispatch(request, *args, **kwargs)
  File "/usr/local/lib/python3.5/dist-packages/rest_framework/views.py", line 489, in dispatch
    response = self.handle_exception(exc)
  File "/usr/local/lib/python3.5/dist-packages/rest_framework/views.py", line 449, in handle_exception
    self.raise_uncaught_exception(exc)
  File "/usr/local/lib/python3.5/dist-packages/rest_framework/views.py", line 486, in dispatch
    response = handler(request, *args, **kwargs)
  File "/usr/local/lib/python3.5/dist-packages/rest_framework/generics.py", line 201, in get
    return self.list(request, *args, **kwargs)
  File "/usr/local/lib/python3.5/dist-packages/rest_framework/mixins.py", line 48, in list
    return Response(serializer.data)
  File "/usr/local/lib/python3.5/dist-packages/rest_framework/serializers.py", line 738, in data
    ret = super(ListSerializer, self).data
  File "/usr/local/lib/python3.5/dist-packages/rest_framework/serializers.py", line 262, in data
    self._data = self.to_representation(self.instance)
  File "/usr/local/lib/python3.5/dist-packages/rest_framework/serializers.py", line 656, in to_representation
    self.child.to_representation(item) for item in iterable
  File "/usr/local/lib/python3.5/dist-packages/rest_framework/serializers.py", line 656, in <listcomp>
    self.child.to_representation(item) for item in iterable
  File "/usr/local/lib/python3.5/dist-packages/rest_framework/serializers.py", line 483, in to_representation
    fields = self._readable_fields
  File "/usr/local/lib/python3.5/dist-packages/django/utils/functional.py", line 36, in __get__
    res = instance.__dict__[self.name] = self.func(instance)
  File "/usr/local/lib/python3.5/dist-packages/rest_framework/serializers.py", line 377, in _readable_fields
    field for field in self.fields.values()
  File "/usr/local/lib/python3.5/dist-packages/rest_framework/serializers.py", line 363, in fields
    for key, value in self.get_fields().items():
  File "/usr/local/lib/python3.5/dist-packages/rest_framework/serializers.py", line 993, in get_fields
    field_names = self.get_field_names(declared_fields, info)
  File "/usr/local/lib/python3.5/dist-packages/rest_framework/serializers.py", line 1061, in get_field_names
    serializer_class=self.__class__.__name__
AssertionError: Cannot set both 'fields' and 'exclude' options on serializer ArticleSerializer.
ERROR - [2018-02-24 11:54:23] (exception 24356 139665702790912) Internal Server Error: /sky/articles
Traceback (most recent call last):
  File "/usr/local/lib/python3.5/dist-packages/django/core/handlers/exception.py", line 35, in inner
    response = get_response(request)
  File "/usr/local/lib/python3.5/dist-packages/django/core/handlers/base.py", line 128, in _get_response
    response = self.process_exception_by_middleware(e, request)
  File "/usr/local/lib/python3.5/dist-packages/channels/handler.py", line 243, in process_exception_by_middleware
    return super(AsgiHandler, self).process_exception_by_middleware(exception, request)
  File "/usr/local/lib/python3.5/dist-packages/django/core/handlers/base.py", line 126, in _get_response
    response = wrapped_callback(request, *callback_args, **callback_kwargs)
  File "/usr/local/lib/python3.5/dist-packages/django/views/decorators/csrf.py", line 54, in wrapped_view
    return view_func(*args, **kwargs)
  File "/usr/local/lib/python3.5/dist-packages/django/views/generic/base.py", line 69, in view
    return self.dispatch(request, *args, **kwargs)
  File "/usr/local/lib/python3.5/dist-packages/rest_framework/views.py", line 489, in dispatch
    response = self.handle_exception(exc)
  File "/usr/local/lib/python3.5/dist-packages/rest_framework/views.py", line 449, in handle_exception
    self.raise_uncaught_exception(exc)
  File "/usr/local/lib/python3.5/dist-packages/rest_framework/views.py", line 486, in dispatch
    response = handler(request, *args, **kwargs)
  File "/usr/local/lib/python3.5/dist-packages/rest_framework/generics.py", line 201, in get
    return self.list(request, *args, **kwargs)
  File "/usr/local/lib/python3.5/dist-packages/rest_framework/mixins.py", line 48, in list
    return Response(serializer.data)
  File "/usr/local/lib/python3.5/dist-packages/rest_framework/serializers.py", line 738, in data
    ret = super(ListSerializer, self).data
  File "/usr/local/lib/python3.5/dist-packages/rest_framework/serializers.py", line 262, in data
    self._data = self.to_representation(self.instance)
  File "/usr/local/lib/python3.5/dist-packages/rest_framework/serializers.py", line 656, in to_representation
    self.child.to_representation(item) for item in iterable
  File "/usr/local/lib/python3.5/dist-packages/rest_framework/serializers.py", line 656, in <listcomp>
    self.child.to_representation(item) for item in iterable
  File "/usr/local/lib/python3.5/dist-packages/rest_framework/serializers.py", line 483, in to_representation
    fields = self._readable_fields
  File "/usr/local/lib/python3.5/dist-packages/django/utils/functional.py", line 36, in __get__
    res = instance.__dict__[self.name] = self.func(instance)
  File "/usr/local/lib/python3.5/dist-packages/rest_framework/serializers.py", line 377, in _readable_fields
    field for field in self.fields.values()
  File "/usr/local/lib/python3.5/dist-packages/rest_framework/serializers.py", line 363, in fields
    for key, value in self.get_fields().items():
  File "/usr/local/lib/python3.5/dist-packages/rest_framework/serializers.py", line 993, in get_fields
    field_names = self.get_field_names(declared_fields, info)
  File "/usr/local/lib/python3.5/dist-packages/rest_framework/serializers.py", line 1061, in get_field_names
    serializer_class=self.__class__.__name__
AssertionError: Cannot set both 'fields' and 'exclude' options on serializer ArticleSerializer.
WARNING - [2018-03-02 15:27:17] (base 7352 140681519560448) Not Found: /favicon.ico
ERROR - [2018-03-02 16:09:20] (exception 9704 140437086320384) Internal Server Error: /admin/lottery/task/
Traceback (most recent call last):
  File "/usr/local/lib/python3.5/dist-packages/django/db/models/options.py", line 566, in get_field
    return self.fields_map[field_name]
KeyError: '__str__'

During handling of the above exception, another exception occurred:

Traceback (most recent call last):
  File "/usr/local/lib/python3.5/dist-packages/django/contrib/admin/utils.py", line 276, in lookup_field
    f = _get_non_gfk_field(opts, name)
  File "/usr/local/lib/python3.5/dist-packages/django/contrib/admin/utils.py", line 307, in _get_non_gfk_field
    field = opts.get_field(name)
  File "/usr/local/lib/python3.5/dist-packages/django/db/models/options.py", line 568, in get_field
    raise FieldDoesNotExist("%s has no field named '%s'" % (self.object_name, field_name))
django.core.exceptions.FieldDoesNotExist: Task has no field named '__str__'

During handling of the above exception, another exception occurred:

Traceback (most recent call last):
  File "/usr/local/lib/python3.5/dist-packages/django/core/handlers/exception.py", line 35, in inner
    response = get_response(request)
  File "/usr/local/lib/python3.5/dist-packages/django/core/handlers/base.py", line 158, in _get_response
    response = self.process_exception_by_middleware(e, request)
  File "/usr/local/lib/python3.5/dist-packages/channels/handler.py", line 243, in process_exception_by_middleware
    return super(AsgiHandler, self).process_exception_by_middleware(exception, request)
  File "/usr/local/lib/python3.5/dist-packages/django/core/handlers/base.py", line 156, in _get_response
    response = response.render()
  File "/usr/local/lib/python3.5/dist-packages/django/template/response.py", line 106, in render
    self.content = self.rendered_content
  File "/usr/local/lib/python3.5/dist-packages/django/template/response.py", line 83, in rendered_content
    content = template.render(context, self._request)
  File "/usr/local/lib/python3.5/dist-packages/django/template/backends/django.py", line 61, in render
    return self.template.render(context)
  File "/usr/local/lib/python3.5/dist-packages/django/template/base.py", line 175, in render
    return self._render(context)
  File "/usr/local/lib/python3.5/dist-packages/django/template/base.py", line 167, in _render
    return self.nodelist.render(context)
  File "/usr/local/lib/python3.5/dist-packages/django/template/base.py", line 943, in render
    bit = node.render_annotated(context)
  File "/usr/local/lib/python3.5/dist-packages/django/template/base.py", line 910, in render_annotated
    return self.render(context)
  File "/usr/local/lib/python3.5/dist-packages/django/template/loader_tags.py", line 155, in render
    return compiled_parent._render(context)
  File "/usr/local/lib/python3.5/dist-packages/django/template/base.py", line 167, in _render
    return self.nodelist.render(context)
  File "/usr/local/lib/python3.5/dist-packages/django/template/base.py", line 943, in render
    bit = node.render_annotated(context)
  File "/usr/local/lib/python3.5/dist-packages/django/template/base.py", line 910, in render_annotated
    return self.render(context)
  File "/usr/local/lib/python3.5/dist-packages/django/template/loader_tags.py", line 155, in render
    return compiled_parent._render(context)
  File "/usr/local/lib/python3.5/dist-packages/django/template/base.py", line 167, in _render
    return self.nodelist.render(context)
  File "/usr/local/lib/python3.5/dist-packages/django/template/base.py", line 943, in render
    bit = node.render_annotated(context)
  File "/usr/local/lib/python3.5/dist-packages/django/template/base.py", line 910, in render_annotated
    return self.render(context)
  File "/usr/local/lib/python3.5/dist-packages/django/template/loader_tags.py", line 67, in render
    result = block.nodelist.render(context)
  File "/usr/local/lib/python3.5/dist-packages/django/template/base.py", line 943, in render
    bit = node.render_annotated(context)
  File "/usr/local/lib/python3.5/dist-packages/django/template/base.py", line 910, in render_annotated
    return self.render(context)
  File "/usr/local/lib/python3.5/dist-packages/django/template/loader_tags.py", line 67, in render
    result = block.nodelist.render(context)
  File "/usr/local/lib/python3.5/dist-packages/django/template/base.py", line 943, in render
    bit = node.render_annotated(context)
  File "/usr/local/lib/python3.5/dist-packages/django/template/base.py", line 910, in render_annotated
    return self.render(context)
  File "/usr/local/lib/python3.5/dist-packages/django/template/loader_tags.py", line 67, in render
    result = block.nodelist.render(context)
  File "/usr/local/lib/python3.5/dist-packages/django/template/base.py", line 943, in render
    bit = node.render_annotated(context)
  File "/usr/local/lib/python3.5/dist-packages/django/template/base.py", line 910, in render_annotated
    return self.render(context)
  File "/usr/local/lib/python3.5/dist-packages/django/template/library.py", line 214, in render
    _dict = self.func(*resolved_args, **resolved_kwargs)
  File "/usr/local/lib/python3.5/dist-packages/django/contrib/admin/templatetags/admin_list.py", line 326, in result_list
    'results': list(results(cl))}
  File "/usr/local/lib/python3.5/dist-packages/django/contrib/admin/templatetags/admin_list.py", line 302, in results
    yield ResultList(None, items_for_result(cl, res, None))
  File "/usr/local/lib/python3.5/dist-packages/django/contrib/admin/templatetags/admin_list.py", line 293, in __init__
    super().__init__(*items)
  File "/usr/local/lib/python3.5/dist-packages/django/contrib/admin/templatetags/admin_list.py", line 212, in items_for_result
    f, attr, value = lookup_field(field_name, result, cl.model_admin)
  File "/usr/local/lib/python3.5/dist-packages/django/contrib/admin/utils.py", line 289, in lookup_field
    value = attr()
  File "/home/eethan1/Desktop/IMnight2018_Backend/IMnight/lottery/models.py", line 44, in __str__
    return "%s %s have %d credit, due in %s, label:%s" % (self.name, TASK_CATEGORY_CHOICE[self.category][2]\
IndexError: tuple index out of range
ERROR - [2018-03-02 16:10:04] (exception 9782 140629776455424) Internal Server Error: /admin/lottery/task/
Traceback (most recent call last):
  File "/usr/local/lib/python3.5/dist-packages/django/db/models/options.py", line 566, in get_field
    return self.fields_map[field_name]
KeyError: '__str__'

During handling of the above exception, another exception occurred:

Traceback (most recent call last):
  File "/usr/local/lib/python3.5/dist-packages/django/contrib/admin/utils.py", line 276, in lookup_field
    f = _get_non_gfk_field(opts, name)
  File "/usr/local/lib/python3.5/dist-packages/django/contrib/admin/utils.py", line 307, in _get_non_gfk_field
    field = opts.get_field(name)
  File "/usr/local/lib/python3.5/dist-packages/django/db/models/options.py", line 568, in get_field
    raise FieldDoesNotExist("%s has no field named '%s'" % (self.object_name, field_name))
django.core.exceptions.FieldDoesNotExist: Task has no field named '__str__'

During handling of the above exception, another exception occurred:

Traceback (most recent call last):
  File "/usr/local/lib/python3.5/dist-packages/django/core/handlers/exception.py", line 35, in inner
    response = get_response(request)
  File "/usr/local/lib/python3.5/dist-packages/django/core/handlers/base.py", line 158, in _get_response
    response = self.process_exception_by_middleware(e, request)
  File "/usr/local/lib/python3.5/dist-packages/channels/handler.py", line 243, in process_exception_by_middleware
    return super(AsgiHandler, self).process_exception_by_middleware(exception, request)
  File "/usr/local/lib/python3.5/dist-packages/django/core/handlers/base.py", line 156, in _get_response
    response = response.render()
  File "/usr/local/lib/python3.5/dist-packages/django/template/response.py", line 106, in render
    self.content = self.rendered_content
  File "/usr/local/lib/python3.5/dist-packages/django/template/response.py", line 83, in rendered_content
    content = template.render(context, self._request)
  File "/usr/local/lib/python3.5/dist-packages/django/template/backends/django.py", line 61, in render
    return self.template.render(context)
  File "/usr/local/lib/python3.5/dist-packages/django/template/base.py", line 175, in render
    return self._render(context)
  File "/usr/local/lib/python3.5/dist-packages/django/template/base.py", line 167, in _render
    return self.nodelist.render(context)
  File "/usr/local/lib/python3.5/dist-packages/django/template/base.py", line 943, in render
    bit = node.render_annotated(context)
  File "/usr/local/lib/python3.5/dist-packages/django/template/base.py", line 910, in render_annotated
    return self.render(context)
  File "/usr/local/lib/python3.5/dist-packages/django/template/loader_tags.py", line 155, in render
    return compiled_parent._render(context)
  File "/usr/local/lib/python3.5/dist-packages/django/template/base.py", line 167, in _render
    return self.nodelist.render(context)
  File "/usr/local/lib/python3.5/dist-packages/django/template/base.py", line 943, in render
    bit = node.render_annotated(context)
  File "/usr/local/lib/python3.5/dist-packages/django/template/base.py", line 910, in render_annotated
    return self.render(context)
  File "/usr/local/lib/python3.5/dist-packages/django/template/loader_tags.py", line 155, in render
    return compiled_parent._render(context)
  File "/usr/local/lib/python3.5/dist-packages/django/template/base.py", line 167, in _render
    return self.nodelist.render(context)
  File "/usr/local/lib/python3.5/dist-packages/django/template/base.py", line 943, in render
    bit = node.render_annotated(context)
  File "/usr/local/lib/python3.5/dist-packages/django/template/base.py", line 910, in render_annotated
    return self.render(context)
  File "/usr/local/lib/python3.5/dist-packages/django/template/loader_tags.py", line 67, in render
    result = block.nodelist.render(context)
  File "/usr/local/lib/python3.5/dist-packages/django/template/base.py", line 943, in render
    bit = node.render_annotated(context)
  File "/usr/local/lib/python3.5/dist-packages/django/template/base.py", line 910, in render_annotated
    return self.render(context)
  File "/usr/local/lib/python3.5/dist-packages/django/template/loader_tags.py", line 67, in render
    result = block.nodelist.render(context)
  File "/usr/local/lib/python3.5/dist-packages/django/template/base.py", line 943, in render
    bit = node.render_annotated(context)
  File "/usr/local/lib/python3.5/dist-packages/django/template/base.py", line 910, in render_annotated
    return self.render(context)
  File "/usr/local/lib/python3.5/dist-packages/django/template/loader_tags.py", line 67, in render
    result = block.nodelist.render(context)
  File "/usr/local/lib/python3.5/dist-packages/django/template/base.py", line 943, in render
    bit = node.render_annotated(context)
  File "/usr/local/lib/python3.5/dist-packages/django/template/base.py", line 910, in render_annotated
    return self.render(context)
  File "/usr/local/lib/python3.5/dist-packages/django/template/library.py", line 214, in render
    _dict = self.func(*resolved_args, **resolved_kwargs)
  File "/usr/local/lib/python3.5/dist-packages/django/contrib/admin/templatetags/admin_list.py", line 326, in result_list
    'results': list(results(cl))}
  File "/usr/local/lib/python3.5/dist-packages/django/contrib/admin/templatetags/admin_list.py", line 302, in results
    yield ResultList(None, items_for_result(cl, res, None))
  File "/usr/local/lib/python3.5/dist-packages/django/contrib/admin/templatetags/admin_list.py", line 293, in __init__
    super().__init__(*items)
  File "/usr/local/lib/python3.5/dist-packages/django/contrib/admin/templatetags/admin_list.py", line 212, in items_for_result
    f, attr, value = lookup_field(field_name, result, cl.model_admin)
  File "/usr/local/lib/python3.5/dist-packages/django/contrib/admin/utils.py", line 289, in lookup_field
    value = attr()
  File "/home/eethan1/Desktop/IMnight2018_Backend/IMnight/lottery/models.py", line 44, in __str__
    return "%s %s have %d credit, due in %s, label:%s" % (self.name, TASK_CATEGORY_CHOICE[self.category][1]\
IndexError: tuple index out of range
ERROR - [2018-03-02 16:10:12] (exception 9782 140629768062720) Internal Server Error: /admin/lottery/task/
Traceback (most recent call last):
  File "/usr/local/lib/python3.5/dist-packages/django/db/models/options.py", line 566, in get_field
    return self.fields_map[field_name]
KeyError: '__str__'

During handling of the above exception, another exception occurred:

Traceback (most recent call last):
  File "/usr/local/lib/python3.5/dist-packages/django/contrib/admin/utils.py", line 276, in lookup_field
    f = _get_non_gfk_field(opts, name)
  File "/usr/local/lib/python3.5/dist-packages/django/contrib/admin/utils.py", line 307, in _get_non_gfk_field
    field = opts.get_field(name)
  File "/usr/local/lib/python3.5/dist-packages/django/db/models/options.py", line 568, in get_field
    raise FieldDoesNotExist("%s has no field named '%s'" % (self.object_name, field_name))
django.core.exceptions.FieldDoesNotExist: Task has no field named '__str__'

During handling of the above exception, another exception occurred:

Traceback (most recent call last):
  File "/usr/local/lib/python3.5/dist-packages/django/core/handlers/exception.py", line 35, in inner
    response = get_response(request)
  File "/usr/local/lib/python3.5/dist-packages/django/core/handlers/base.py", line 158, in _get_response
    response = self.process_exception_by_middleware(e, request)
  File "/usr/local/lib/python3.5/dist-packages/channels/handler.py", line 243, in process_exception_by_middleware
    return super(AsgiHandler, self).process_exception_by_middleware(exception, request)
  File "/usr/local/lib/python3.5/dist-packages/django/core/handlers/base.py", line 156, in _get_response
    response = response.render()
  File "/usr/local/lib/python3.5/dist-packages/django/template/response.py", line 106, in render
    self.content = self.rendered_content
  File "/usr/local/lib/python3.5/dist-packages/django/template/response.py", line 83, in rendered_content
    content = template.render(context, self._request)
  File "/usr/local/lib/python3.5/dist-packages/django/template/backends/django.py", line 61, in render
    return self.template.render(context)
  File "/usr/local/lib/python3.5/dist-packages/django/template/base.py", line 175, in render
    return self._render(context)
  File "/usr/local/lib/python3.5/dist-packages/django/template/base.py", line 167, in _render
    return self.nodelist.render(context)
  File "/usr/local/lib/python3.5/dist-packages/django/template/base.py", line 943, in render
    bit = node.render_annotated(context)
  File "/usr/local/lib/python3.5/dist-packages/django/template/base.py", line 910, in render_annotated
    return self.render(context)
  File "/usr/local/lib/python3.5/dist-packages/django/template/loader_tags.py", line 155, in render
    return compiled_parent._render(context)
  File "/usr/local/lib/python3.5/dist-packages/django/template/base.py", line 167, in _render
    return self.nodelist.render(context)
  File "/usr/local/lib/python3.5/dist-packages/django/template/base.py", line 943, in render
    bit = node.render_annotated(context)
  File "/usr/local/lib/python3.5/dist-packages/django/template/base.py", line 910, in render_annotated
    return self.render(context)
  File "/usr/local/lib/python3.5/dist-packages/django/template/loader_tags.py", line 155, in render
    return compiled_parent._render(context)
  File "/usr/local/lib/python3.5/dist-packages/django/template/base.py", line 167, in _render
    return self.nodelist.render(context)
  File "/usr/local/lib/python3.5/dist-packages/django/template/base.py", line 943, in render
    bit = node.render_annotated(context)
  File "/usr/local/lib/python3.5/dist-packages/django/template/base.py", line 910, in render_annotated
    return self.render(context)
  File "/usr/local/lib/python3.5/dist-packages/django/template/loader_tags.py", line 67, in render
    result = block.nodelist.render(context)
  File "/usr/local/lib/python3.5/dist-packages/django/template/base.py", line 943, in render
    bit = node.render_annotated(context)
  File "/usr/local/lib/python3.5/dist-packages/django/template/base.py", line 910, in render_annotated
    return self.render(context)
  File "/usr/local/lib/python3.5/dist-packages/django/template/loader_tags.py", line 67, in render
    result = block.nodelist.render(context)
  File "/usr/local/lib/python3.5/dist-packages/django/template/base.py", line 943, in render
    bit = node.render_annotated(context)
  File "/usr/local/lib/python3.5/dist-packages/django/template/base.py", line 910, in render_annotated
    return self.render(context)
  File "/usr/local/lib/python3.5/dist-packages/django/template/loader_tags.py", line 67, in render
    result = block.nodelist.render(context)
  File "/usr/local/lib/python3.5/dist-packages/django/template/base.py", line 943, in render
    bit = node.render_annotated(context)
  File "/usr/local/lib/python3.5/dist-packages/django/template/base.py", line 910, in render_annotated
    return self.render(context)
  File "/usr/local/lib/python3.5/dist-packages/django/template/library.py", line 214, in render
    _dict = self.func(*resolved_args, **resolved_kwargs)
  File "/usr/local/lib/python3.5/dist-packages/django/contrib/admin/templatetags/admin_list.py", line 326, in result_list
    'results': list(results(cl))}
  File "/usr/local/lib/python3.5/dist-packages/django/contrib/admin/templatetags/admin_list.py", line 302, in results
    yield ResultList(None, items_for_result(cl, res, None))
  File "/usr/local/lib/python3.5/dist-packages/django/contrib/admin/templatetags/admin_list.py", line 293, in __init__
    super().__init__(*items)
  File "/usr/local/lib/python3.5/dist-packages/django/contrib/admin/templatetags/admin_list.py", line 212, in items_for_result
    f, attr, value = lookup_field(field_name, result, cl.model_admin)
  File "/usr/local/lib/python3.5/dist-packages/django/contrib/admin/utils.py", line 289, in lookup_field
    value = attr()
  File "/home/eethan1/Desktop/IMnight2018_Backend/IMnight/lottery/models.py", line 44, in __str__
    return "%s %s have %d credit, due in %s, label:%s" % (self.name, TASK_CATEGORY_CHOICE[self.category][1]\
IndexError: tuple index out of range
WARNING - [2018-03-03 00:20:49] (base 2354 140302421587712) Not Found: /favicon.ico
