WARNING - [2018-02-21 12:57:32] (base 12822 123145365794816) Not Found: /favicon.ico
ERROR - [2018-02-21 13:03:13] (exception 13026 123145382293504) Internal Server Error: /sky/news/
Traceback (most recent call last):
  File "/Users/YuChih/Project/IMnight2018_Backend/ENV/lib/python3.6/site-packages/django/core/handlers/exception.py", line 35, in inner
    response = get_response(request)
  File "/Users/YuChih/Project/IMnight2018_Backend/ENV/lib/python3.6/site-packages/django/core/handlers/base.py", line 128, in _get_response
    response = self.process_exception_by_middleware(e, request)
  File "/Users/YuChih/Project/IMnight2018_Backend/ENV/lib/python3.6/site-packages/channels/handler.py", line 243, in process_exception_by_middleware
    return super(AsgiHandler, self).process_exception_by_middleware(exception, request)
  File "/Users/YuChih/Project/IMnight2018_Backend/ENV/lib/python3.6/site-packages/django/core/handlers/base.py", line 126, in _get_response
    response = wrapped_callback(request, *callback_args, **callback_kwargs)
  File "/Users/YuChih/Project/IMnight2018_Backend/ENV/lib/python3.6/site-packages/django/views/decorators/csrf.py", line 54, in wrapped_view
    return view_func(*args, **kwargs)
  File "/Users/YuChih/Project/IMnight2018_Backend/ENV/lib/python3.6/site-packages/django/views/generic/base.py", line 69, in view
    return self.dispatch(request, *args, **kwargs)
  File "/Users/YuChih/Project/IMnight2018_Backend/ENV/lib/python3.6/site-packages/rest_framework/views.py", line 489, in dispatch
    response = self.handle_exception(exc)
  File "/Users/YuChih/Project/IMnight2018_Backend/ENV/lib/python3.6/site-packages/rest_framework/views.py", line 449, in handle_exception
    self.raise_uncaught_exception(exc)
  File "/Users/YuChih/Project/IMnight2018_Backend/ENV/lib/python3.6/site-packages/rest_framework/views.py", line 486, in dispatch
    response = handler(request, *args, **kwargs)
  File "/Users/YuChih/Project/IMnight2018_Backend/ENV/lib/python3.6/site-packages/rest_framework/generics.py", line 201, in get
    return self.list(request, *args, **kwargs)
  File "/Users/YuChih/Project/IMnight2018_Backend/ENV/lib/python3.6/site-packages/rest_framework/mixins.py", line 40, in list
    queryset = self.filter_queryset(self.get_queryset())
  File "/Users/YuChih/Project/IMnight2018_Backend/IMnight/sky/views.py", line 19, in get_queryset
    queryset = News.objects.get().order_by('-timestamp')[:5]
  File "/Users/YuChih/Project/IMnight2018_Backend/ENV/lib/python3.6/site-packages/django/db/models/manager.py", line 82, in manager_method
    return getattr(self.get_queryset(), name)(*args, **kwargs)
  File "/Users/YuChih/Project/IMnight2018_Backend/ENV/lib/python3.6/site-packages/django/db/models/query.py", line 407, in get
    (self.model._meta.object_name, num)
sky.models.MultipleObjectsReturned: get() returned more than one News -- it returned 3!
ERROR - [2018-02-21 13:03:41] (exception 13035 123145440563200) Internal Server Error: /sky/news/
Traceback (most recent call last):
  File "/Users/YuChih/Project/IMnight2018_Backend/ENV/lib/python3.6/site-packages/django/core/handlers/exception.py", line 35, in inner
    response = get_response(request)
  File "/Users/YuChih/Project/IMnight2018_Backend/ENV/lib/python3.6/site-packages/django/core/handlers/base.py", line 128, in _get_response
    response = self.process_exception_by_middleware(e, request)
  File "/Users/YuChih/Project/IMnight2018_Backend/ENV/lib/python3.6/site-packages/channels/handler.py", line 243, in process_exception_by_middleware
    return super(AsgiHandler, self).process_exception_by_middleware(exception, request)
  File "/Users/YuChih/Project/IMnight2018_Backend/ENV/lib/python3.6/site-packages/django/core/handlers/base.py", line 126, in _get_response
    response = wrapped_callback(request, *callback_args, **callback_kwargs)
  File "/Users/YuChih/Project/IMnight2018_Backend/ENV/lib/python3.6/site-packages/django/views/decorators/csrf.py", line 54, in wrapped_view
    return view_func(*args, **kwargs)
  File "/Users/YuChih/Project/IMnight2018_Backend/ENV/lib/python3.6/site-packages/django/views/generic/base.py", line 69, in view
    return self.dispatch(request, *args, **kwargs)
  File "/Users/YuChih/Project/IMnight2018_Backend/ENV/lib/python3.6/site-packages/rest_framework/views.py", line 489, in dispatch
    response = self.handle_exception(exc)
  File "/Users/YuChih/Project/IMnight2018_Backend/ENV/lib/python3.6/site-packages/rest_framework/views.py", line 449, in handle_exception
    self.raise_uncaught_exception(exc)
  File "/Users/YuChih/Project/IMnight2018_Backend/ENV/lib/python3.6/site-packages/rest_framework/views.py", line 486, in dispatch
    response = handler(request, *args, **kwargs)
  File "/Users/YuChih/Project/IMnight2018_Backend/ENV/lib/python3.6/site-packages/rest_framework/generics.py", line 201, in get
    return self.list(request, *args, **kwargs)
  File "/Users/YuChih/Project/IMnight2018_Backend/ENV/lib/python3.6/site-packages/rest_framework/mixins.py", line 40, in list
    queryset = self.filter_queryset(self.get_queryset())
  File "/Users/YuChih/Project/IMnight2018_Backend/IMnight/sky/views.py", line 19, in get_queryset
    queryset = News.objects.get()
  File "/Users/YuChih/Project/IMnight2018_Backend/ENV/lib/python3.6/site-packages/django/db/models/manager.py", line 82, in manager_method
    return getattr(self.get_queryset(), name)(*args, **kwargs)
  File "/Users/YuChih/Project/IMnight2018_Backend/ENV/lib/python3.6/site-packages/django/db/models/query.py", line 407, in get
    (self.model._meta.object_name, num)
sky.models.MultipleObjectsReturned: get() returned more than one News -- it returned 3!
ERROR - [2018-02-21 13:04:12] (exception 13057 123145408462848) Internal Server Error: /sky/news/
Traceback (most recent call last):
  File "/Users/YuChih/Project/IMnight2018_Backend/ENV/lib/python3.6/site-packages/django/core/handlers/exception.py", line 35, in inner
    response = get_response(request)
  File "/Users/YuChih/Project/IMnight2018_Backend/ENV/lib/python3.6/site-packages/django/core/handlers/base.py", line 128, in _get_response
    response = self.process_exception_by_middleware(e, request)
  File "/Users/YuChih/Project/IMnight2018_Backend/ENV/lib/python3.6/site-packages/channels/handler.py", line 243, in process_exception_by_middleware
    return super(AsgiHandler, self).process_exception_by_middleware(exception, request)
  File "/Users/YuChih/Project/IMnight2018_Backend/ENV/lib/python3.6/site-packages/django/core/handlers/base.py", line 126, in _get_response
    response = wrapped_callback(request, *callback_args, **callback_kwargs)
  File "/Users/YuChih/Project/IMnight2018_Backend/ENV/lib/python3.6/site-packages/django/views/decorators/csrf.py", line 54, in wrapped_view
    return view_func(*args, **kwargs)
  File "/Users/YuChih/Project/IMnight2018_Backend/ENV/lib/python3.6/site-packages/django/views/generic/base.py", line 69, in view
    return self.dispatch(request, *args, **kwargs)
  File "/Users/YuChih/Project/IMnight2018_Backend/ENV/lib/python3.6/site-packages/rest_framework/views.py", line 489, in dispatch
    response = self.handle_exception(exc)
  File "/Users/YuChih/Project/IMnight2018_Backend/ENV/lib/python3.6/site-packages/rest_framework/views.py", line 449, in handle_exception
    self.raise_uncaught_exception(exc)
  File "/Users/YuChih/Project/IMnight2018_Backend/ENV/lib/python3.6/site-packages/rest_framework/views.py", line 486, in dispatch
    response = handler(request, *args, **kwargs)
  File "/Users/YuChih/Project/IMnight2018_Backend/ENV/lib/python3.6/site-packages/rest_framework/generics.py", line 201, in get
    return self.list(request, *args, **kwargs)
  File "/Users/YuChih/Project/IMnight2018_Backend/ENV/lib/python3.6/site-packages/rest_framework/mixins.py", line 40, in list
    queryset = self.filter_queryset(self.get_queryset())
  File "/Users/YuChih/Project/IMnight2018_Backend/IMnight/sky/views.py", line 20, in get_queryset
    print(queryset)
  File "/Users/YuChih/Project/IMnight2018_Backend/ENV/lib/python3.6/site-packages/django/db/models/query.py", line 248, in __repr__
    data = list(self[:REPR_OUTPUT_SIZE + 1])
  File "/Users/YuChih/Project/IMnight2018_Backend/ENV/lib/python3.6/site-packages/django/db/models/query.py", line 272, in __iter__
    self._fetch_all()
  File "/Users/YuChih/Project/IMnight2018_Backend/ENV/lib/python3.6/site-packages/django/db/models/query.py", line 1179, in _fetch_all
    self._result_cache = list(self._iterable_class(self))
  File "/Users/YuChih/Project/IMnight2018_Backend/ENV/lib/python3.6/site-packages/django/db/models/query.py", line 54, in __iter__
    results = compiler.execute_sql(chunked_fetch=self.chunked_fetch, chunk_size=self.chunk_size)
  File "/Users/YuChih/Project/IMnight2018_Backend/ENV/lib/python3.6/site-packages/django/db/models/sql/compiler.py", line 1050, in execute_sql
    sql, params = self.as_sql()
  File "/Users/YuChih/Project/IMnight2018_Backend/ENV/lib/python3.6/site-packages/django/db/models/sql/compiler.py", line 445, in as_sql
    extra_select, order_by, group_by = self.pre_sql_setup()
  File "/Users/YuChih/Project/IMnight2018_Backend/ENV/lib/python3.6/site-packages/django/db/models/sql/compiler.py", line 51, in pre_sql_setup
    order_by = self.get_order_by()
  File "/Users/YuChih/Project/IMnight2018_Backend/ENV/lib/python3.6/site-packages/django/db/models/sql/compiler.py", line 315, in get_order_by
    field, self.query.get_meta(), default_order=asc))
  File "/Users/YuChih/Project/IMnight2018_Backend/ENV/lib/python3.6/site-packages/django/db/models/sql/compiler.py", line 660, in find_ordering_name
    field, targets, alias, joins, path, opts = self._setup_joins(pieces, opts, alias)
  File "/Users/YuChih/Project/IMnight2018_Backend/ENV/lib/python3.6/site-packages/django/db/models/sql/compiler.py", line 693, in _setup_joins
    pieces, opts, alias)
  File "/Users/YuChih/Project/IMnight2018_Backend/ENV/lib/python3.6/site-packages/django/db/models/sql/query.py", line 1447, in setup_joins
    names, opts, allow_many, fail_on_missing=True)
  File "/Users/YuChih/Project/IMnight2018_Backend/ENV/lib/python3.6/site-packages/django/db/models/sql/query.py", line 1378, in names_to_path
    "Choices are: %s" % (name, ", ".join(available)))
django.core.exceptions.FieldError: Cannot resolve keyword 'timestamp' into field. Choices are: created, id, title, url
