ERROR - [2018-01-19 16:09:18] (exception 65594 123145322815488) Internal Server Error: /human/performer/list/
Traceback (most recent call last):
  File "/Users/YuChih/Project/IMnight2018_Backend/ENV/lib/python3.6/site-packages/django/core/handlers/exception.py", line 35, in inner
    response = get_response(request)
  File "/Users/YuChih/Project/IMnight2018_Backend/ENV/lib/python3.6/site-packages/django/core/handlers/base.py", line 128, in _get_response
    response = self.process_exception_by_middleware(e, request)
  File "/Users/YuChih/Project/IMnight2018_Backend/ENV/lib/python3.6/site-packages/channels/handler.py", line 243, in process_exception_by_middleware
    return super(AsgiHandler, self).process_exception_by_middleware(exception, request)
  File "/Users/YuChih/Project/IMnight2018_Backend/ENV/lib/python3.6/site-packages/django/core/handlers/base.py", line 126, in _get_response
    response = wrapped_callback(request, *callback_args, **callback_kwargs)
  File "/Users/YuChih/Project/IMnight2018_Backend/ENV/lib/python3.6/site-packages/django/views/decorators/csrf.py", line 54, in wrapped_view
    return view_func(*args, **kwargs)
  File "/Users/YuChih/Project/IMnight2018_Backend/ENV/lib/python3.6/site-packages/django/views/generic/base.py", line 69, in view
    return self.dispatch(request, *args, **kwargs)
  File "/Users/YuChih/Project/IMnight2018_Backend/ENV/lib/python3.6/site-packages/rest_framework/views.py", line 489, in dispatch
    response = self.handle_exception(exc)
  File "/Users/YuChih/Project/IMnight2018_Backend/ENV/lib/python3.6/site-packages/rest_framework/views.py", line 449, in handle_exception
    self.raise_uncaught_exception(exc)
  File "/Users/YuChih/Project/IMnight2018_Backend/ENV/lib/python3.6/site-packages/rest_framework/views.py", line 486, in dispatch
    response = handler(request, *args, **kwargs)
  File "/Users/YuChih/Project/IMnight2018_Backend/ENV/lib/python3.6/site-packages/rest_framework/generics.py", line 201, in get
    return self.list(request, *args, **kwargs)
  File "/Users/YuChih/Project/IMnight2018_Backend/ENV/lib/python3.6/site-packages/rest_framework/mixins.py", line 40, in list
    queryset = self.filter_queryset(self.get_queryset())
  File "/Users/YuChih/Project/IMnight2018_Backend/IMnight/human/views.py", line 77, in get_queryset
    return queryset
UnboundLocalError: local variable 'queryset' referenced before assignment
ERROR - [2018-01-19 16:09:21] (exception 65594 123145328070656) Internal Server Error: /human/performer/list/
Traceback (most recent call last):
  File "/Users/YuChih/Project/IMnight2018_Backend/ENV/lib/python3.6/site-packages/django/core/handlers/exception.py", line 35, in inner
    response = get_response(request)
  File "/Users/YuChih/Project/IMnight2018_Backend/ENV/lib/python3.6/site-packages/django/core/handlers/base.py", line 128, in _get_response
    response = self.process_exception_by_middleware(e, request)
  File "/Users/YuChih/Project/IMnight2018_Backend/ENV/lib/python3.6/site-packages/channels/handler.py", line 243, in process_exception_by_middleware
    return super(AsgiHandler, self).process_exception_by_middleware(exception, request)
  File "/Users/YuChih/Project/IMnight2018_Backend/ENV/lib/python3.6/site-packages/django/core/handlers/base.py", line 126, in _get_response
    response = wrapped_callback(request, *callback_args, **callback_kwargs)
  File "/Users/YuChih/Project/IMnight2018_Backend/ENV/lib/python3.6/site-packages/django/views/decorators/csrf.py", line 54, in wrapped_view
    return view_func(*args, **kwargs)
  File "/Users/YuChih/Project/IMnight2018_Backend/ENV/lib/python3.6/site-packages/django/views/generic/base.py", line 69, in view
    return self.dispatch(request, *args, **kwargs)
  File "/Users/YuChih/Project/IMnight2018_Backend/ENV/lib/python3.6/site-packages/rest_framework/views.py", line 489, in dispatch
    response = self.handle_exception(exc)
  File "/Users/YuChih/Project/IMnight2018_Backend/ENV/lib/python3.6/site-packages/rest_framework/views.py", line 449, in handle_exception
    self.raise_uncaught_exception(exc)
  File "/Users/YuChih/Project/IMnight2018_Backend/ENV/lib/python3.6/site-packages/rest_framework/views.py", line 486, in dispatch
    response = handler(request, *args, **kwargs)
  File "/Users/YuChih/Project/IMnight2018_Backend/ENV/lib/python3.6/site-packages/rest_framework/generics.py", line 201, in get
    return self.list(request, *args, **kwargs)
  File "/Users/YuChih/Project/IMnight2018_Backend/ENV/lib/python3.6/site-packages/rest_framework/mixins.py", line 40, in list
    queryset = self.filter_queryset(self.get_queryset())
  File "/Users/YuChih/Project/IMnight2018_Backend/IMnight/human/views.py", line 77, in get_queryset
    return queryset
UnboundLocalError: local variable 'queryset' referenced before assignment
ERROR - [2018-01-23 15:47:29] (exception 79154 123145568088064) Internal Server Error: /earth/vocher/
Traceback (most recent call last):
  File "/Users/YuChih/Project/IMnight2018_Backend/ENV/lib/python3.6/site-packages/django/core/handlers/exception.py", line 35, in inner
    response = get_response(request)
  File "/Users/YuChih/Project/IMnight2018_Backend/ENV/lib/python3.6/site-packages/django/core/handlers/base.py", line 128, in _get_response
    response = self.process_exception_by_middleware(e, request)
  File "/Users/YuChih/Project/IMnight2018_Backend/ENV/lib/python3.6/site-packages/channels/handler.py", line 243, in process_exception_by_middleware
    return super(AsgiHandler, self).process_exception_by_middleware(exception, request)
  File "/Users/YuChih/Project/IMnight2018_Backend/ENV/lib/python3.6/site-packages/django/core/handlers/base.py", line 126, in _get_response
    response = wrapped_callback(request, *callback_args, **callback_kwargs)
  File "/Users/YuChih/Project/IMnight2018_Backend/ENV/lib/python3.6/site-packages/django/views/decorators/csrf.py", line 54, in wrapped_view
    return view_func(*args, **kwargs)
  File "/Users/YuChih/Project/IMnight2018_Backend/ENV/lib/python3.6/site-packages/django/views/generic/base.py", line 69, in view
    return self.dispatch(request, *args, **kwargs)
  File "/Users/YuChih/Project/IMnight2018_Backend/ENV/lib/python3.6/site-packages/rest_framework/views.py", line 489, in dispatch
    response = self.handle_exception(exc)
  File "/Users/YuChih/Project/IMnight2018_Backend/ENV/lib/python3.6/site-packages/rest_framework/views.py", line 449, in handle_exception
    self.raise_uncaught_exception(exc)
  File "/Users/YuChih/Project/IMnight2018_Backend/ENV/lib/python3.6/site-packages/rest_framework/views.py", line 486, in dispatch
    response = handler(request, *args, **kwargs)
  File "/Users/YuChih/Project/IMnight2018_Backend/ENV/lib/python3.6/site-packages/rest_framework/generics.py", line 201, in get
    return self.list(request, *args, **kwargs)
  File "/Users/YuChih/Project/IMnight2018_Backend/ENV/lib/python3.6/site-packages/rest_framework/mixins.py", line 40, in list
    queryset = self.filter_queryset(self.get_queryset())
  File "/Users/YuChih/Project/IMnight2018_Backend/IMnight/earth/views.py", line 42, in get_queryset
    queryset = HoldingVocher.objects.get_vochers(user)
TypeError: get_vochers() missing 1 required positional argument: 'storename'
ERROR - [2018-01-23 15:51:42] (exception 79211 123145524617216) Internal Server Error: /earth/vocher/
Traceback (most recent call last):
  File "/Users/YuChih/Project/IMnight2018_Backend/ENV/lib/python3.6/site-packages/rest_framework/fields.py", line 441, in get_attribute
    return get_attribute(instance, self.source_attrs)
  File "/Users/YuChih/Project/IMnight2018_Backend/ENV/lib/python3.6/site-packages/rest_framework/fields.py", line 98, in get_attribute
    instance = instance[attr]
KeyError: 'store'

During handling of the above exception, another exception occurred:

Traceback (most recent call last):
  File "/Users/YuChih/Project/IMnight2018_Backend/ENV/lib/python3.6/site-packages/django/core/handlers/exception.py", line 35, in inner
    response = get_response(request)
  File "/Users/YuChih/Project/IMnight2018_Backend/ENV/lib/python3.6/site-packages/django/core/handlers/base.py", line 128, in _get_response
    response = self.process_exception_by_middleware(e, request)
  File "/Users/YuChih/Project/IMnight2018_Backend/ENV/lib/python3.6/site-packages/channels/handler.py", line 243, in process_exception_by_middleware
    return super(AsgiHandler, self).process_exception_by_middleware(exception, request)
  File "/Users/YuChih/Project/IMnight2018_Backend/ENV/lib/python3.6/site-packages/django/core/handlers/base.py", line 126, in _get_response
    response = wrapped_callback(request, *callback_args, **callback_kwargs)
  File "/Users/YuChih/Project/IMnight2018_Backend/ENV/lib/python3.6/site-packages/django/views/decorators/csrf.py", line 54, in wrapped_view
    return view_func(*args, **kwargs)
  File "/Users/YuChih/Project/IMnight2018_Backend/ENV/lib/python3.6/site-packages/django/views/generic/base.py", line 69, in view
    return self.dispatch(request, *args, **kwargs)
  File "/Users/YuChih/Project/IMnight2018_Backend/ENV/lib/python3.6/site-packages/rest_framework/views.py", line 489, in dispatch
    response = self.handle_exception(exc)
  File "/Users/YuChih/Project/IMnight2018_Backend/ENV/lib/python3.6/site-packages/rest_framework/views.py", line 449, in handle_exception
    self.raise_uncaught_exception(exc)
  File "/Users/YuChih/Project/IMnight2018_Backend/ENV/lib/python3.6/site-packages/rest_framework/views.py", line 486, in dispatch
    response = handler(request, *args, **kwargs)
  File "/Users/YuChih/Project/IMnight2018_Backend/ENV/lib/python3.6/site-packages/rest_framework/generics.py", line 201, in get
    return self.list(request, *args, **kwargs)
  File "/Users/YuChih/Project/IMnight2018_Backend/ENV/lib/python3.6/site-packages/rest_framework/mixins.py", line 48, in list
    return Response(serializer.data)
  File "/Users/YuChih/Project/IMnight2018_Backend/ENV/lib/python3.6/site-packages/rest_framework/serializers.py", line 738, in data
    ret = super(ListSerializer, self).data
  File "/Users/YuChih/Project/IMnight2018_Backend/ENV/lib/python3.6/site-packages/rest_framework/serializers.py", line 262, in data
    self._data = self.to_representation(self.instance)
  File "/Users/YuChih/Project/IMnight2018_Backend/ENV/lib/python3.6/site-packages/rest_framework/serializers.py", line 656, in to_representation
    self.child.to_representation(item) for item in iterable
  File "/Users/YuChih/Project/IMnight2018_Backend/ENV/lib/python3.6/site-packages/rest_framework/serializers.py", line 656, in <listcomp>
    self.child.to_representation(item) for item in iterable
  File "/Users/YuChih/Project/IMnight2018_Backend/ENV/lib/python3.6/site-packages/rest_framework/serializers.py", line 487, in to_representation
    attribute = field.get_attribute(instance)
  File "/Users/YuChih/Project/IMnight2018_Backend/ENV/lib/python3.6/site-packages/rest_framework/fields.py", line 462, in get_attribute
    raise type(exc)(msg)
KeyError: "Got KeyError when attempting to get a value for field `store` on serializer `VocherSerializer`.\nThe serializer field might be named incorrectly and not match any attribute or key on the `dict` instance.\nOriginal exception text was: 'store'."
ERROR - [2018-01-23 15:52:29] (exception 79219 123145397198848) Internal Server Error: /earth/vocher/
Traceback (most recent call last):
  File "/Users/YuChih/Project/IMnight2018_Backend/ENV/lib/python3.6/site-packages/rest_framework/fields.py", line 441, in get_attribute
    return get_attribute(instance, self.source_attrs)
  File "/Users/YuChih/Project/IMnight2018_Backend/ENV/lib/python3.6/site-packages/rest_framework/fields.py", line 98, in get_attribute
    instance = instance[attr]
KeyError: 'store'

During handling of the above exception, another exception occurred:

Traceback (most recent call last):
  File "/Users/YuChih/Project/IMnight2018_Backend/ENV/lib/python3.6/site-packages/django/core/handlers/exception.py", line 35, in inner
    response = get_response(request)
  File "/Users/YuChih/Project/IMnight2018_Backend/ENV/lib/python3.6/site-packages/django/core/handlers/base.py", line 128, in _get_response
    response = self.process_exception_by_middleware(e, request)
  File "/Users/YuChih/Project/IMnight2018_Backend/ENV/lib/python3.6/site-packages/channels/handler.py", line 243, in process_exception_by_middleware
    return super(AsgiHandler, self).process_exception_by_middleware(exception, request)
  File "/Users/YuChih/Project/IMnight2018_Backend/ENV/lib/python3.6/site-packages/django/core/handlers/base.py", line 126, in _get_response
    response = wrapped_callback(request, *callback_args, **callback_kwargs)
  File "/Users/YuChih/Project/IMnight2018_Backend/ENV/lib/python3.6/site-packages/django/views/decorators/csrf.py", line 54, in wrapped_view
    return view_func(*args, **kwargs)
  File "/Users/YuChih/Project/IMnight2018_Backend/ENV/lib/python3.6/site-packages/django/views/generic/base.py", line 69, in view
    return self.dispatch(request, *args, **kwargs)
  File "/Users/YuChih/Project/IMnight2018_Backend/ENV/lib/python3.6/site-packages/rest_framework/views.py", line 489, in dispatch
    response = self.handle_exception(exc)
  File "/Users/YuChih/Project/IMnight2018_Backend/ENV/lib/python3.6/site-packages/rest_framework/views.py", line 449, in handle_exception
    self.raise_uncaught_exception(exc)
  File "/Users/YuChih/Project/IMnight2018_Backend/ENV/lib/python3.6/site-packages/rest_framework/views.py", line 486, in dispatch
    response = handler(request, *args, **kwargs)
  File "/Users/YuChih/Project/IMnight2018_Backend/ENV/lib/python3.6/site-packages/rest_framework/generics.py", line 201, in get
    return self.list(request, *args, **kwargs)
  File "/Users/YuChih/Project/IMnight2018_Backend/ENV/lib/python3.6/site-packages/rest_framework/mixins.py", line 48, in list
    return Response(serializer.data)
  File "/Users/YuChih/Project/IMnight2018_Backend/ENV/lib/python3.6/site-packages/rest_framework/serializers.py", line 738, in data
    ret = super(ListSerializer, self).data
  File "/Users/YuChih/Project/IMnight2018_Backend/ENV/lib/python3.6/site-packages/rest_framework/serializers.py", line 262, in data
    self._data = self.to_representation(self.instance)
  File "/Users/YuChih/Project/IMnight2018_Backend/ENV/lib/python3.6/site-packages/rest_framework/serializers.py", line 656, in to_representation
    self.child.to_representation(item) for item in iterable
  File "/Users/YuChih/Project/IMnight2018_Backend/ENV/lib/python3.6/site-packages/rest_framework/serializers.py", line 656, in <listcomp>
    self.child.to_representation(item) for item in iterable
  File "/Users/YuChih/Project/IMnight2018_Backend/ENV/lib/python3.6/site-packages/rest_framework/serializers.py", line 487, in to_representation
    attribute = field.get_attribute(instance)
  File "/Users/YuChih/Project/IMnight2018_Backend/ENV/lib/python3.6/site-packages/rest_framework/fields.py", line 462, in get_attribute
    raise type(exc)(msg)
KeyError: "Got KeyError when attempting to get a value for field `store` on serializer `VocherSerializer`.\nThe serializer field might be named incorrectly and not match any attribute or key on the `dict` instance.\nOriginal exception text was: 'store'."
ERROR - [2018-01-23 15:54:15] (exception 79234 123145497116672) Internal Server Error: /earth/vocher/
Traceback (most recent call last):
  File "/Users/YuChih/Project/IMnight2018_Backend/ENV/lib/python3.6/site-packages/rest_framework/fields.py", line 441, in get_attribute
    return get_attribute(instance, self.source_attrs)
  File "/Users/YuChih/Project/IMnight2018_Backend/ENV/lib/python3.6/site-packages/rest_framework/fields.py", line 98, in get_attribute
    instance = instance[attr]
KeyError: 'store'

During handling of the above exception, another exception occurred:

Traceback (most recent call last):
  File "/Users/YuChih/Project/IMnight2018_Backend/ENV/lib/python3.6/site-packages/django/core/handlers/exception.py", line 35, in inner
    response = get_response(request)
  File "/Users/YuChih/Project/IMnight2018_Backend/ENV/lib/python3.6/site-packages/django/core/handlers/base.py", line 128, in _get_response
    response = self.process_exception_by_middleware(e, request)
  File "/Users/YuChih/Project/IMnight2018_Backend/ENV/lib/python3.6/site-packages/channels/handler.py", line 243, in process_exception_by_middleware
    return super(AsgiHandler, self).process_exception_by_middleware(exception, request)
  File "/Users/YuChih/Project/IMnight2018_Backend/ENV/lib/python3.6/site-packages/django/core/handlers/base.py", line 126, in _get_response
    response = wrapped_callback(request, *callback_args, **callback_kwargs)
  File "/Users/YuChih/Project/IMnight2018_Backend/ENV/lib/python3.6/site-packages/django/views/decorators/csrf.py", line 54, in wrapped_view
    return view_func(*args, **kwargs)
  File "/Users/YuChih/Project/IMnight2018_Backend/ENV/lib/python3.6/site-packages/django/views/generic/base.py", line 69, in view
    return self.dispatch(request, *args, **kwargs)
  File "/Users/YuChih/Project/IMnight2018_Backend/ENV/lib/python3.6/site-packages/rest_framework/views.py", line 489, in dispatch
    response = self.handle_exception(exc)
  File "/Users/YuChih/Project/IMnight2018_Backend/ENV/lib/python3.6/site-packages/rest_framework/views.py", line 449, in handle_exception
    self.raise_uncaught_exception(exc)
  File "/Users/YuChih/Project/IMnight2018_Backend/ENV/lib/python3.6/site-packages/rest_framework/views.py", line 486, in dispatch
    response = handler(request, *args, **kwargs)
  File "/Users/YuChih/Project/IMnight2018_Backend/ENV/lib/python3.6/site-packages/rest_framework/generics.py", line 201, in get
    return self.list(request, *args, **kwargs)
  File "/Users/YuChih/Project/IMnight2018_Backend/ENV/lib/python3.6/site-packages/rest_framework/mixins.py", line 48, in list
    return Response(serializer.data)
  File "/Users/YuChih/Project/IMnight2018_Backend/ENV/lib/python3.6/site-packages/rest_framework/serializers.py", line 738, in data
    ret = super(ListSerializer, self).data
  File "/Users/YuChih/Project/IMnight2018_Backend/ENV/lib/python3.6/site-packages/rest_framework/serializers.py", line 262, in data
    self._data = self.to_representation(self.instance)
  File "/Users/YuChih/Project/IMnight2018_Backend/ENV/lib/python3.6/site-packages/rest_framework/serializers.py", line 656, in to_representation
    self.child.to_representation(item) for item in iterable
  File "/Users/YuChih/Project/IMnight2018_Backend/ENV/lib/python3.6/site-packages/rest_framework/serializers.py", line 656, in <listcomp>
    self.child.to_representation(item) for item in iterable
  File "/Users/YuChih/Project/IMnight2018_Backend/ENV/lib/python3.6/site-packages/rest_framework/serializers.py", line 487, in to_representation
    attribute = field.get_attribute(instance)
  File "/Users/YuChih/Project/IMnight2018_Backend/ENV/lib/python3.6/site-packages/rest_framework/fields.py", line 462, in get_attribute
    raise type(exc)(msg)
KeyError: "Got KeyError when attempting to get a value for field `store` on serializer `VocherSerializer`.\nThe serializer field might be named incorrectly and not match any attribute or key on the `dict` instance.\nOriginal exception text was: 'store'."
ERROR - [2018-01-23 15:54:30] (exception 79242 123145451245568) Internal Server Error: /earth/vocher/
Traceback (most recent call last):
  File "/Users/YuChih/Project/IMnight2018_Backend/ENV/lib/python3.6/site-packages/rest_framework/fields.py", line 441, in get_attribute
    return get_attribute(instance, self.source_attrs)
  File "/Users/YuChih/Project/IMnight2018_Backend/ENV/lib/python3.6/site-packages/rest_framework/fields.py", line 98, in get_attribute
    instance = instance[attr]
KeyError: 'sub_title'

During handling of the above exception, another exception occurred:

Traceback (most recent call last):
  File "/Users/YuChih/Project/IMnight2018_Backend/ENV/lib/python3.6/site-packages/django/core/handlers/exception.py", line 35, in inner
    response = get_response(request)
  File "/Users/YuChih/Project/IMnight2018_Backend/ENV/lib/python3.6/site-packages/django/core/handlers/base.py", line 128, in _get_response
    response = self.process_exception_by_middleware(e, request)
  File "/Users/YuChih/Project/IMnight2018_Backend/ENV/lib/python3.6/site-packages/channels/handler.py", line 243, in process_exception_by_middleware
    return super(AsgiHandler, self).process_exception_by_middleware(exception, request)
  File "/Users/YuChih/Project/IMnight2018_Backend/ENV/lib/python3.6/site-packages/django/core/handlers/base.py", line 126, in _get_response
    response = wrapped_callback(request, *callback_args, **callback_kwargs)
  File "/Users/YuChih/Project/IMnight2018_Backend/ENV/lib/python3.6/site-packages/django/views/decorators/csrf.py", line 54, in wrapped_view
    return view_func(*args, **kwargs)
  File "/Users/YuChih/Project/IMnight2018_Backend/ENV/lib/python3.6/site-packages/django/views/generic/base.py", line 69, in view
    return self.dispatch(request, *args, **kwargs)
  File "/Users/YuChih/Project/IMnight2018_Backend/ENV/lib/python3.6/site-packages/rest_framework/views.py", line 489, in dispatch
    response = self.handle_exception(exc)
  File "/Users/YuChih/Project/IMnight2018_Backend/ENV/lib/python3.6/site-packages/rest_framework/views.py", line 449, in handle_exception
    self.raise_uncaught_exception(exc)
  File "/Users/YuChih/Project/IMnight2018_Backend/ENV/lib/python3.6/site-packages/rest_framework/views.py", line 486, in dispatch
    response = handler(request, *args, **kwargs)
  File "/Users/YuChih/Project/IMnight2018_Backend/ENV/lib/python3.6/site-packages/rest_framework/generics.py", line 201, in get
    return self.list(request, *args, **kwargs)
  File "/Users/YuChih/Project/IMnight2018_Backend/ENV/lib/python3.6/site-packages/rest_framework/mixins.py", line 48, in list
    return Response(serializer.data)
  File "/Users/YuChih/Project/IMnight2018_Backend/ENV/lib/python3.6/site-packages/rest_framework/serializers.py", line 738, in data
    ret = super(ListSerializer, self).data
  File "/Users/YuChih/Project/IMnight2018_Backend/ENV/lib/python3.6/site-packages/rest_framework/serializers.py", line 262, in data
    self._data = self.to_representation(self.instance)
  File "/Users/YuChih/Project/IMnight2018_Backend/ENV/lib/python3.6/site-packages/rest_framework/serializers.py", line 656, in to_representation
    self.child.to_representation(item) for item in iterable
  File "/Users/YuChih/Project/IMnight2018_Backend/ENV/lib/python3.6/site-packages/rest_framework/serializers.py", line 656, in <listcomp>
    self.child.to_representation(item) for item in iterable
  File "/Users/YuChih/Project/IMnight2018_Backend/ENV/lib/python3.6/site-packages/rest_framework/serializers.py", line 487, in to_representation
    attribute = field.get_attribute(instance)
  File "/Users/YuChih/Project/IMnight2018_Backend/ENV/lib/python3.6/site-packages/rest_framework/fields.py", line 462, in get_attribute
    raise type(exc)(msg)
KeyError: "Got KeyError when attempting to get a value for field `sub_title` on serializer `VocherSerializer`.\nThe serializer field might be named incorrectly and not match any attribute or key on the `dict` instance.\nOriginal exception text was: 'sub_title'."
ERROR - [2018-01-23 15:55:16] (exception 79399 123145405562880) Internal Server Error: /earth/vocher/
Traceback (most recent call last):
  File "/Users/YuChih/Project/IMnight2018_Backend/ENV/lib/python3.6/site-packages/rest_framework/fields.py", line 441, in get_attribute
    return get_attribute(instance, self.source_attrs)
  File "/Users/YuChih/Project/IMnight2018_Backend/ENV/lib/python3.6/site-packages/rest_framework/fields.py", line 98, in get_attribute
    instance = instance[attr]
KeyError: 'store'

During handling of the above exception, another exception occurred:

Traceback (most recent call last):
  File "/Users/YuChih/Project/IMnight2018_Backend/ENV/lib/python3.6/site-packages/django/core/handlers/exception.py", line 35, in inner
    response = get_response(request)
  File "/Users/YuChih/Project/IMnight2018_Backend/ENV/lib/python3.6/site-packages/django/core/handlers/base.py", line 128, in _get_response
    response = self.process_exception_by_middleware(e, request)
  File "/Users/YuChih/Project/IMnight2018_Backend/ENV/lib/python3.6/site-packages/channels/handler.py", line 243, in process_exception_by_middleware
    return super(AsgiHandler, self).process_exception_by_middleware(exception, request)
  File "/Users/YuChih/Project/IMnight2018_Backend/ENV/lib/python3.6/site-packages/django/core/handlers/base.py", line 126, in _get_response
    response = wrapped_callback(request, *callback_args, **callback_kwargs)
  File "/Users/YuChih/Project/IMnight2018_Backend/ENV/lib/python3.6/site-packages/django/views/decorators/csrf.py", line 54, in wrapped_view
    return view_func(*args, **kwargs)
  File "/Users/YuChih/Project/IMnight2018_Backend/ENV/lib/python3.6/site-packages/django/views/generic/base.py", line 69, in view
    return self.dispatch(request, *args, **kwargs)
  File "/Users/YuChih/Project/IMnight2018_Backend/ENV/lib/python3.6/site-packages/rest_framework/views.py", line 489, in dispatch
    response = self.handle_exception(exc)
  File "/Users/YuChih/Project/IMnight2018_Backend/ENV/lib/python3.6/site-packages/rest_framework/views.py", line 449, in handle_exception
    self.raise_uncaught_exception(exc)
  File "/Users/YuChih/Project/IMnight2018_Backend/ENV/lib/python3.6/site-packages/rest_framework/views.py", line 486, in dispatch
    response = handler(request, *args, **kwargs)
  File "/Users/YuChih/Project/IMnight2018_Backend/ENV/lib/python3.6/site-packages/rest_framework/generics.py", line 201, in get
    return self.list(request, *args, **kwargs)
  File "/Users/YuChih/Project/IMnight2018_Backend/ENV/lib/python3.6/site-packages/rest_framework/mixins.py", line 48, in list
    return Response(serializer.data)
  File "/Users/YuChih/Project/IMnight2018_Backend/ENV/lib/python3.6/site-packages/rest_framework/serializers.py", line 738, in data
    ret = super(ListSerializer, self).data
  File "/Users/YuChih/Project/IMnight2018_Backend/ENV/lib/python3.6/site-packages/rest_framework/serializers.py", line 262, in data
    self._data = self.to_representation(self.instance)
  File "/Users/YuChih/Project/IMnight2018_Backend/ENV/lib/python3.6/site-packages/rest_framework/serializers.py", line 656, in to_representation
    self.child.to_representation(item) for item in iterable
  File "/Users/YuChih/Project/IMnight2018_Backend/ENV/lib/python3.6/site-packages/rest_framework/serializers.py", line 656, in <listcomp>
    self.child.to_representation(item) for item in iterable
  File "/Users/YuChih/Project/IMnight2018_Backend/ENV/lib/python3.6/site-packages/rest_framework/serializers.py", line 487, in to_representation
    attribute = field.get_attribute(instance)
  File "/Users/YuChih/Project/IMnight2018_Backend/ENV/lib/python3.6/site-packages/rest_framework/fields.py", line 462, in get_attribute
    raise type(exc)(msg)
KeyError: "Got KeyError when attempting to get a value for field `store` on serializer `VocherSerializer`.\nThe serializer field might be named incorrectly and not match any attribute or key on the `dict` instance.\nOriginal exception text was: 'store'."
ERROR - [2018-01-23 15:55:17] (exception 79399 123145410818048) Internal Server Error: /earth/vocher/
Traceback (most recent call last):
  File "/Users/YuChih/Project/IMnight2018_Backend/ENV/lib/python3.6/site-packages/rest_framework/fields.py", line 441, in get_attribute
    return get_attribute(instance, self.source_attrs)
  File "/Users/YuChih/Project/IMnight2018_Backend/ENV/lib/python3.6/site-packages/rest_framework/fields.py", line 98, in get_attribute
    instance = instance[attr]
KeyError: 'store'

During handling of the above exception, another exception occurred:

Traceback (most recent call last):
  File "/Users/YuChih/Project/IMnight2018_Backend/ENV/lib/python3.6/site-packages/django/core/handlers/exception.py", line 35, in inner
    response = get_response(request)
  File "/Users/YuChih/Project/IMnight2018_Backend/ENV/lib/python3.6/site-packages/django/core/handlers/base.py", line 128, in _get_response
    response = self.process_exception_by_middleware(e, request)
  File "/Users/YuChih/Project/IMnight2018_Backend/ENV/lib/python3.6/site-packages/channels/handler.py", line 243, in process_exception_by_middleware
    return super(AsgiHandler, self).process_exception_by_middleware(exception, request)
  File "/Users/YuChih/Project/IMnight2018_Backend/ENV/lib/python3.6/site-packages/django/core/handlers/base.py", line 126, in _get_response
    response = wrapped_callback(request, *callback_args, **callback_kwargs)
  File "/Users/YuChih/Project/IMnight2018_Backend/ENV/lib/python3.6/site-packages/django/views/decorators/csrf.py", line 54, in wrapped_view
    return view_func(*args, **kwargs)
  File "/Users/YuChih/Project/IMnight2018_Backend/ENV/lib/python3.6/site-packages/django/views/generic/base.py", line 69, in view
    return self.dispatch(request, *args, **kwargs)
  File "/Users/YuChih/Project/IMnight2018_Backend/ENV/lib/python3.6/site-packages/rest_framework/views.py", line 489, in dispatch
    response = self.handle_exception(exc)
  File "/Users/YuChih/Project/IMnight2018_Backend/ENV/lib/python3.6/site-packages/rest_framework/views.py", line 449, in handle_exception
    self.raise_uncaught_exception(exc)
  File "/Users/YuChih/Project/IMnight2018_Backend/ENV/lib/python3.6/site-packages/rest_framework/views.py", line 486, in dispatch
    response = handler(request, *args, **kwargs)
  File "/Users/YuChih/Project/IMnight2018_Backend/ENV/lib/python3.6/site-packages/rest_framework/generics.py", line 201, in get
    return self.list(request, *args, **kwargs)
  File "/Users/YuChih/Project/IMnight2018_Backend/ENV/lib/python3.6/site-packages/rest_framework/mixins.py", line 48, in list
    return Response(serializer.data)
  File "/Users/YuChih/Project/IMnight2018_Backend/ENV/lib/python3.6/site-packages/rest_framework/serializers.py", line 738, in data
    ret = super(ListSerializer, self).data
  File "/Users/YuChih/Project/IMnight2018_Backend/ENV/lib/python3.6/site-packages/rest_framework/serializers.py", line 262, in data
    self._data = self.to_representation(self.instance)
  File "/Users/YuChih/Project/IMnight2018_Backend/ENV/lib/python3.6/site-packages/rest_framework/serializers.py", line 656, in to_representation
    self.child.to_representation(item) for item in iterable
  File "/Users/YuChih/Project/IMnight2018_Backend/ENV/lib/python3.6/site-packages/rest_framework/serializers.py", line 656, in <listcomp>
    self.child.to_representation(item) for item in iterable
  File "/Users/YuChih/Project/IMnight2018_Backend/ENV/lib/python3.6/site-packages/rest_framework/serializers.py", line 487, in to_representation
    attribute = field.get_attribute(instance)
  File "/Users/YuChih/Project/IMnight2018_Backend/ENV/lib/python3.6/site-packages/rest_framework/fields.py", line 462, in get_attribute
    raise type(exc)(msg)
KeyError: "Got KeyError when attempting to get a value for field `store` on serializer `VocherSerializer`.\nThe serializer field might be named incorrectly and not match any attribute or key on the `dict` instance.\nOriginal exception text was: 'store'."
ERROR - [2018-01-23 15:55:24] (exception 79399 123145400307712) Internal Server Error: /earth/vocher/
Traceback (most recent call last):
  File "/Users/YuChih/Project/IMnight2018_Backend/ENV/lib/python3.6/site-packages/rest_framework/fields.py", line 441, in get_attribute
    return get_attribute(instance, self.source_attrs)
  File "/Users/YuChih/Project/IMnight2018_Backend/ENV/lib/python3.6/site-packages/rest_framework/fields.py", line 98, in get_attribute
    instance = instance[attr]
KeyError: 'store'

During handling of the above exception, another exception occurred:

Traceback (most recent call last):
  File "/Users/YuChih/Project/IMnight2018_Backend/ENV/lib/python3.6/site-packages/django/core/handlers/exception.py", line 35, in inner
    response = get_response(request)
  File "/Users/YuChih/Project/IMnight2018_Backend/ENV/lib/python3.6/site-packages/django/core/handlers/base.py", line 128, in _get_response
    response = self.process_exception_by_middleware(e, request)
  File "/Users/YuChih/Project/IMnight2018_Backend/ENV/lib/python3.6/site-packages/channels/handler.py", line 243, in process_exception_by_middleware
    return super(AsgiHandler, self).process_exception_by_middleware(exception, request)
  File "/Users/YuChih/Project/IMnight2018_Backend/ENV/lib/python3.6/site-packages/django/core/handlers/base.py", line 126, in _get_response
    response = wrapped_callback(request, *callback_args, **callback_kwargs)
  File "/Users/YuChih/Project/IMnight2018_Backend/ENV/lib/python3.6/site-packages/django/views/decorators/csrf.py", line 54, in wrapped_view
    return view_func(*args, **kwargs)
  File "/Users/YuChih/Project/IMnight2018_Backend/ENV/lib/python3.6/site-packages/django/views/generic/base.py", line 69, in view
    return self.dispatch(request, *args, **kwargs)
  File "/Users/YuChih/Project/IMnight2018_Backend/ENV/lib/python3.6/site-packages/rest_framework/views.py", line 489, in dispatch
    response = self.handle_exception(exc)
  File "/Users/YuChih/Project/IMnight2018_Backend/ENV/lib/python3.6/site-packages/rest_framework/views.py", line 449, in handle_exception
    self.raise_uncaught_exception(exc)
  File "/Users/YuChih/Project/IMnight2018_Backend/ENV/lib/python3.6/site-packages/rest_framework/views.py", line 486, in dispatch
    response = handler(request, *args, **kwargs)
  File "/Users/YuChih/Project/IMnight2018_Backend/ENV/lib/python3.6/site-packages/rest_framework/generics.py", line 201, in get
    return self.list(request, *args, **kwargs)
  File "/Users/YuChih/Project/IMnight2018_Backend/ENV/lib/python3.6/site-packages/rest_framework/mixins.py", line 48, in list
    return Response(serializer.data)
  File "/Users/YuChih/Project/IMnight2018_Backend/ENV/lib/python3.6/site-packages/rest_framework/serializers.py", line 738, in data
    ret = super(ListSerializer, self).data
  File "/Users/YuChih/Project/IMnight2018_Backend/ENV/lib/python3.6/site-packages/rest_framework/serializers.py", line 262, in data
    self._data = self.to_representation(self.instance)
  File "/Users/YuChih/Project/IMnight2018_Backend/ENV/lib/python3.6/site-packages/rest_framework/serializers.py", line 656, in to_representation
    self.child.to_representation(item) for item in iterable
  File "/Users/YuChih/Project/IMnight2018_Backend/ENV/lib/python3.6/site-packages/rest_framework/serializers.py", line 656, in <listcomp>
    self.child.to_representation(item) for item in iterable
  File "/Users/YuChih/Project/IMnight2018_Backend/ENV/lib/python3.6/site-packages/rest_framework/serializers.py", line 487, in to_representation
    attribute = field.get_attribute(instance)
  File "/Users/YuChih/Project/IMnight2018_Backend/ENV/lib/python3.6/site-packages/rest_framework/fields.py", line 462, in get_attribute
    raise type(exc)(msg)
KeyError: "Got KeyError when attempting to get a value for field `store` on serializer `VocherSerializer`.\nThe serializer field might be named incorrectly and not match any attribute or key on the `dict` instance.\nOriginal exception text was: 'store'."
ERROR - [2018-01-23 15:56:03] (exception 79415 123145436327936) Internal Server Error: /earth/vocher/
Traceback (most recent call last):
  File "/Users/YuChih/Project/IMnight2018_Backend/ENV/lib/python3.6/site-packages/rest_framework/fields.py", line 441, in get_attribute
    return get_attribute(instance, self.source_attrs)
  File "/Users/YuChih/Project/IMnight2018_Backend/ENV/lib/python3.6/site-packages/rest_framework/fields.py", line 98, in get_attribute
    instance = instance[attr]
KeyError: 'sub_title'

During handling of the above exception, another exception occurred:

Traceback (most recent call last):
  File "/Users/YuChih/Project/IMnight2018_Backend/ENV/lib/python3.6/site-packages/django/core/handlers/exception.py", line 35, in inner
    response = get_response(request)
  File "/Users/YuChih/Project/IMnight2018_Backend/ENV/lib/python3.6/site-packages/django/core/handlers/base.py", line 128, in _get_response
    response = self.process_exception_by_middleware(e, request)
  File "/Users/YuChih/Project/IMnight2018_Backend/ENV/lib/python3.6/site-packages/channels/handler.py", line 243, in process_exception_by_middleware
    return super(AsgiHandler, self).process_exception_by_middleware(exception, request)
  File "/Users/YuChih/Project/IMnight2018_Backend/ENV/lib/python3.6/site-packages/django/core/handlers/base.py", line 126, in _get_response
    response = wrapped_callback(request, *callback_args, **callback_kwargs)
  File "/Users/YuChih/Project/IMnight2018_Backend/ENV/lib/python3.6/site-packages/django/views/decorators/csrf.py", line 54, in wrapped_view
    return view_func(*args, **kwargs)
  File "/Users/YuChih/Project/IMnight2018_Backend/ENV/lib/python3.6/site-packages/django/views/generic/base.py", line 69, in view
    return self.dispatch(request, *args, **kwargs)
  File "/Users/YuChih/Project/IMnight2018_Backend/ENV/lib/python3.6/site-packages/rest_framework/views.py", line 489, in dispatch
    response = self.handle_exception(exc)
  File "/Users/YuChih/Project/IMnight2018_Backend/ENV/lib/python3.6/site-packages/rest_framework/views.py", line 449, in handle_exception
    self.raise_uncaught_exception(exc)
  File "/Users/YuChih/Project/IMnight2018_Backend/ENV/lib/python3.6/site-packages/rest_framework/views.py", line 486, in dispatch
    response = handler(request, *args, **kwargs)
  File "/Users/YuChih/Project/IMnight2018_Backend/ENV/lib/python3.6/site-packages/rest_framework/generics.py", line 201, in get
    return self.list(request, *args, **kwargs)
  File "/Users/YuChih/Project/IMnight2018_Backend/ENV/lib/python3.6/site-packages/rest_framework/mixins.py", line 48, in list
    return Response(serializer.data)
  File "/Users/YuChih/Project/IMnight2018_Backend/ENV/lib/python3.6/site-packages/rest_framework/serializers.py", line 738, in data
    ret = super(ListSerializer, self).data
  File "/Users/YuChih/Project/IMnight2018_Backend/ENV/lib/python3.6/site-packages/rest_framework/serializers.py", line 262, in data
    self._data = self.to_representation(self.instance)
  File "/Users/YuChih/Project/IMnight2018_Backend/ENV/lib/python3.6/site-packages/rest_framework/serializers.py", line 656, in to_representation
    self.child.to_representation(item) for item in iterable
  File "/Users/YuChih/Project/IMnight2018_Backend/ENV/lib/python3.6/site-packages/rest_framework/serializers.py", line 656, in <listcomp>
    self.child.to_representation(item) for item in iterable
  File "/Users/YuChih/Project/IMnight2018_Backend/ENV/lib/python3.6/site-packages/rest_framework/serializers.py", line 487, in to_representation
    attribute = field.get_attribute(instance)
  File "/Users/YuChih/Project/IMnight2018_Backend/ENV/lib/python3.6/site-packages/rest_framework/fields.py", line 462, in get_attribute
    raise type(exc)(msg)
KeyError: "Got KeyError when attempting to get a value for field `sub_title` on serializer `VocherSerializer`.\nThe serializer field might be named incorrectly and not match any attribute or key on the `dict` instance.\nOriginal exception text was: 'sub_title'."
ERROR - [2018-01-23 15:57:07] (exception 79425 123145566474240) Internal Server Error: /earth/vocher/
Traceback (most recent call last):
  File "/Users/YuChih/Project/IMnight2018_Backend/ENV/lib/python3.6/site-packages/rest_framework/fields.py", line 441, in get_attribute
    return get_attribute(instance, self.source_attrs)
  File "/Users/YuChih/Project/IMnight2018_Backend/ENV/lib/python3.6/site-packages/rest_framework/fields.py", line 98, in get_attribute
    instance = instance[attr]
KeyError: 'sub_title'

During handling of the above exception, another exception occurred:

Traceback (most recent call last):
  File "/Users/YuChih/Project/IMnight2018_Backend/ENV/lib/python3.6/site-packages/django/core/handlers/exception.py", line 35, in inner
    response = get_response(request)
  File "/Users/YuChih/Project/IMnight2018_Backend/ENV/lib/python3.6/site-packages/django/core/handlers/base.py", line 128, in _get_response
    response = self.process_exception_by_middleware(e, request)
  File "/Users/YuChih/Project/IMnight2018_Backend/ENV/lib/python3.6/site-packages/channels/handler.py", line 243, in process_exception_by_middleware
    return super(AsgiHandler, self).process_exception_by_middleware(exception, request)
  File "/Users/YuChih/Project/IMnight2018_Backend/ENV/lib/python3.6/site-packages/django/core/handlers/base.py", line 126, in _get_response
    response = wrapped_callback(request, *callback_args, **callback_kwargs)
  File "/Users/YuChih/Project/IMnight2018_Backend/ENV/lib/python3.6/site-packages/django/views/decorators/csrf.py", line 54, in wrapped_view
    return view_func(*args, **kwargs)
  File "/Users/YuChih/Project/IMnight2018_Backend/ENV/lib/python3.6/site-packages/django/views/generic/base.py", line 69, in view
    return self.dispatch(request, *args, **kwargs)
  File "/Users/YuChih/Project/IMnight2018_Backend/ENV/lib/python3.6/site-packages/rest_framework/views.py", line 489, in dispatch
    response = self.handle_exception(exc)
  File "/Users/YuChih/Project/IMnight2018_Backend/ENV/lib/python3.6/site-packages/rest_framework/views.py", line 449, in handle_exception
    self.raise_uncaught_exception(exc)
  File "/Users/YuChih/Project/IMnight2018_Backend/ENV/lib/python3.6/site-packages/rest_framework/views.py", line 486, in dispatch
    response = handler(request, *args, **kwargs)
  File "/Users/YuChih/Project/IMnight2018_Backend/ENV/lib/python3.6/site-packages/rest_framework/generics.py", line 201, in get
    return self.list(request, *args, **kwargs)
  File "/Users/YuChih/Project/IMnight2018_Backend/ENV/lib/python3.6/site-packages/rest_framework/mixins.py", line 48, in list
    return Response(serializer.data)
  File "/Users/YuChih/Project/IMnight2018_Backend/ENV/lib/python3.6/site-packages/rest_framework/serializers.py", line 738, in data
    ret = super(ListSerializer, self).data
  File "/Users/YuChih/Project/IMnight2018_Backend/ENV/lib/python3.6/site-packages/rest_framework/serializers.py", line 262, in data
    self._data = self.to_representation(self.instance)
  File "/Users/YuChih/Project/IMnight2018_Backend/ENV/lib/python3.6/site-packages/rest_framework/serializers.py", line 656, in to_representation
    self.child.to_representation(item) for item in iterable
  File "/Users/YuChih/Project/IMnight2018_Backend/ENV/lib/python3.6/site-packages/rest_framework/serializers.py", line 656, in <listcomp>
    self.child.to_representation(item) for item in iterable
  File "/Users/YuChih/Project/IMnight2018_Backend/ENV/lib/python3.6/site-packages/rest_framework/serializers.py", line 487, in to_representation
    attribute = field.get_attribute(instance)
  File "/Users/YuChih/Project/IMnight2018_Backend/ENV/lib/python3.6/site-packages/rest_framework/fields.py", line 462, in get_attribute
    raise type(exc)(msg)
KeyError: "Got KeyError when attempting to get a value for field `sub_title` on serializer `VocherSerializer`.\nThe serializer field might be named incorrectly and not match any attribute or key on the `dict` instance.\nOriginal exception text was: 'sub_title'."
ERROR - [2018-01-23 15:57:21] (exception 79440 123145538469888) Internal Server Error: /earth/vocher/
Traceback (most recent call last):
  File "/Users/YuChih/Project/IMnight2018_Backend/ENV/lib/python3.6/site-packages/rest_framework/fields.py", line 441, in get_attribute
    return get_attribute(instance, self.source_attrs)
  File "/Users/YuChih/Project/IMnight2018_Backend/ENV/lib/python3.6/site-packages/rest_framework/fields.py", line 100, in get_attribute
    instance = getattr(instance, attr)
AttributeError: 'tuple' object has no attribute 'sub_title'

During handling of the above exception, another exception occurred:

Traceback (most recent call last):
  File "/Users/YuChih/Project/IMnight2018_Backend/ENV/lib/python3.6/site-packages/django/core/handlers/exception.py", line 35, in inner
    response = get_response(request)
  File "/Users/YuChih/Project/IMnight2018_Backend/ENV/lib/python3.6/site-packages/django/core/handlers/base.py", line 128, in _get_response
    response = self.process_exception_by_middleware(e, request)
  File "/Users/YuChih/Project/IMnight2018_Backend/ENV/lib/python3.6/site-packages/channels/handler.py", line 243, in process_exception_by_middleware
    return super(AsgiHandler, self).process_exception_by_middleware(exception, request)
  File "/Users/YuChih/Project/IMnight2018_Backend/ENV/lib/python3.6/site-packages/django/core/handlers/base.py", line 126, in _get_response
    response = wrapped_callback(request, *callback_args, **callback_kwargs)
  File "/Users/YuChih/Project/IMnight2018_Backend/ENV/lib/python3.6/site-packages/django/views/decorators/csrf.py", line 54, in wrapped_view
    return view_func(*args, **kwargs)
  File "/Users/YuChih/Project/IMnight2018_Backend/ENV/lib/python3.6/site-packages/django/views/generic/base.py", line 69, in view
    return self.dispatch(request, *args, **kwargs)
  File "/Users/YuChih/Project/IMnight2018_Backend/ENV/lib/python3.6/site-packages/rest_framework/views.py", line 489, in dispatch
    response = self.handle_exception(exc)
  File "/Users/YuChih/Project/IMnight2018_Backend/ENV/lib/python3.6/site-packages/rest_framework/views.py", line 449, in handle_exception
    self.raise_uncaught_exception(exc)
  File "/Users/YuChih/Project/IMnight2018_Backend/ENV/lib/python3.6/site-packages/rest_framework/views.py", line 486, in dispatch
    response = handler(request, *args, **kwargs)
  File "/Users/YuChih/Project/IMnight2018_Backend/ENV/lib/python3.6/site-packages/rest_framework/generics.py", line 201, in get
    return self.list(request, *args, **kwargs)
  File "/Users/YuChih/Project/IMnight2018_Backend/ENV/lib/python3.6/site-packages/rest_framework/mixins.py", line 48, in list
    return Response(serializer.data)
  File "/Users/YuChih/Project/IMnight2018_Backend/ENV/lib/python3.6/site-packages/rest_framework/serializers.py", line 738, in data
    ret = super(ListSerializer, self).data
  File "/Users/YuChih/Project/IMnight2018_Backend/ENV/lib/python3.6/site-packages/rest_framework/serializers.py", line 262, in data
    self._data = self.to_representation(self.instance)
  File "/Users/YuChih/Project/IMnight2018_Backend/ENV/lib/python3.6/site-packages/rest_framework/serializers.py", line 656, in to_representation
    self.child.to_representation(item) for item in iterable
  File "/Users/YuChih/Project/IMnight2018_Backend/ENV/lib/python3.6/site-packages/rest_framework/serializers.py", line 656, in <listcomp>
    self.child.to_representation(item) for item in iterable
  File "/Users/YuChih/Project/IMnight2018_Backend/ENV/lib/python3.6/site-packages/rest_framework/serializers.py", line 487, in to_representation
    attribute = field.get_attribute(instance)
  File "/Users/YuChih/Project/IMnight2018_Backend/ENV/lib/python3.6/site-packages/rest_framework/fields.py", line 462, in get_attribute
    raise type(exc)(msg)
AttributeError: Got AttributeError when attempting to get a value for field `sub_title` on serializer `VocherSerializer`.
The serializer field might be named incorrectly and not match any attribute or key on the `tuple` instance.
Original exception text was: 'tuple' object has no attribute 'sub_title'.
ERROR - [2018-01-23 15:57:34] (exception 79449 123145390387200) Internal Server Error: /earth/vocher/
Traceback (most recent call last):
  File "/Users/YuChih/Project/IMnight2018_Backend/ENV/lib/python3.6/site-packages/rest_framework/fields.py", line 441, in get_attribute
    return get_attribute(instance, self.source_attrs)
  File "/Users/YuChih/Project/IMnight2018_Backend/ENV/lib/python3.6/site-packages/rest_framework/fields.py", line 98, in get_attribute
    instance = instance[attr]
KeyError: 'sub_title'

During handling of the above exception, another exception occurred:

Traceback (most recent call last):
  File "/Users/YuChih/Project/IMnight2018_Backend/ENV/lib/python3.6/site-packages/django/core/handlers/exception.py", line 35, in inner
    response = get_response(request)
  File "/Users/YuChih/Project/IMnight2018_Backend/ENV/lib/python3.6/site-packages/django/core/handlers/base.py", line 128, in _get_response
    response = self.process_exception_by_middleware(e, request)
  File "/Users/YuChih/Project/IMnight2018_Backend/ENV/lib/python3.6/site-packages/channels/handler.py", line 243, in process_exception_by_middleware
    return super(AsgiHandler, self).process_exception_by_middleware(exception, request)
  File "/Users/YuChih/Project/IMnight2018_Backend/ENV/lib/python3.6/site-packages/django/core/handlers/base.py", line 126, in _get_response
    response = wrapped_callback(request, *callback_args, **callback_kwargs)
  File "/Users/YuChih/Project/IMnight2018_Backend/ENV/lib/python3.6/site-packages/django/views/decorators/csrf.py", line 54, in wrapped_view
    return view_func(*args, **kwargs)
  File "/Users/YuChih/Project/IMnight2018_Backend/ENV/lib/python3.6/site-packages/django/views/generic/base.py", line 69, in view
    return self.dispatch(request, *args, **kwargs)
  File "/Users/YuChih/Project/IMnight2018_Backend/ENV/lib/python3.6/site-packages/rest_framework/views.py", line 489, in dispatch
    response = self.handle_exception(exc)
  File "/Users/YuChih/Project/IMnight2018_Backend/ENV/lib/python3.6/site-packages/rest_framework/views.py", line 449, in handle_exception
    self.raise_uncaught_exception(exc)
  File "/Users/YuChih/Project/IMnight2018_Backend/ENV/lib/python3.6/site-packages/rest_framework/views.py", line 486, in dispatch
    response = handler(request, *args, **kwargs)
  File "/Users/YuChih/Project/IMnight2018_Backend/ENV/lib/python3.6/site-packages/rest_framework/generics.py", line 201, in get
    return self.list(request, *args, **kwargs)
  File "/Users/YuChih/Project/IMnight2018_Backend/ENV/lib/python3.6/site-packages/rest_framework/mixins.py", line 48, in list
    return Response(serializer.data)
  File "/Users/YuChih/Project/IMnight2018_Backend/ENV/lib/python3.6/site-packages/rest_framework/serializers.py", line 738, in data
    ret = super(ListSerializer, self).data
  File "/Users/YuChih/Project/IMnight2018_Backend/ENV/lib/python3.6/site-packages/rest_framework/serializers.py", line 262, in data
    self._data = self.to_representation(self.instance)
  File "/Users/YuChih/Project/IMnight2018_Backend/ENV/lib/python3.6/site-packages/rest_framework/serializers.py", line 656, in to_representation
    self.child.to_representation(item) for item in iterable
  File "/Users/YuChih/Project/IMnight2018_Backend/ENV/lib/python3.6/site-packages/rest_framework/serializers.py", line 656, in <listcomp>
    self.child.to_representation(item) for item in iterable
  File "/Users/YuChih/Project/IMnight2018_Backend/ENV/lib/python3.6/site-packages/rest_framework/serializers.py", line 487, in to_representation
    attribute = field.get_attribute(instance)
  File "/Users/YuChih/Project/IMnight2018_Backend/ENV/lib/python3.6/site-packages/rest_framework/fields.py", line 462, in get_attribute
    raise type(exc)(msg)
KeyError: "Got KeyError when attempting to get a value for field `sub_title` on serializer `VocherSerializer`.\nThe serializer field might be named incorrectly and not match any attribute or key on the `dict` instance.\nOriginal exception text was: 'sub_title'."
ERROR - [2018-01-23 15:58:42] (exception 79475 123145393770496) Internal Server Error: /earth/vocher/
Traceback (most recent call last):
  File "/Users/YuChih/Project/IMnight2018_Backend/ENV/lib/python3.6/site-packages/django/core/handlers/exception.py", line 35, in inner
    response = get_response(request)
  File "/Users/YuChih/Project/IMnight2018_Backend/ENV/lib/python3.6/site-packages/django/core/handlers/base.py", line 128, in _get_response
    response = self.process_exception_by_middleware(e, request)
  File "/Users/YuChih/Project/IMnight2018_Backend/ENV/lib/python3.6/site-packages/channels/handler.py", line 243, in process_exception_by_middleware
    return super(AsgiHandler, self).process_exception_by_middleware(exception, request)
  File "/Users/YuChih/Project/IMnight2018_Backend/ENV/lib/python3.6/site-packages/django/core/handlers/base.py", line 126, in _get_response
    response = wrapped_callback(request, *callback_args, **callback_kwargs)
  File "/Users/YuChih/Project/IMnight2018_Backend/ENV/lib/python3.6/site-packages/django/views/decorators/csrf.py", line 54, in wrapped_view
    return view_func(*args, **kwargs)
  File "/Users/YuChih/Project/IMnight2018_Backend/ENV/lib/python3.6/site-packages/django/views/generic/base.py", line 69, in view
    return self.dispatch(request, *args, **kwargs)
  File "/Users/YuChih/Project/IMnight2018_Backend/ENV/lib/python3.6/site-packages/rest_framework/views.py", line 489, in dispatch
    response = self.handle_exception(exc)
  File "/Users/YuChih/Project/IMnight2018_Backend/ENV/lib/python3.6/site-packages/rest_framework/views.py", line 449, in handle_exception
    self.raise_uncaught_exception(exc)
  File "/Users/YuChih/Project/IMnight2018_Backend/ENV/lib/python3.6/site-packages/rest_framework/views.py", line 486, in dispatch
    response = handler(request, *args, **kwargs)
  File "/Users/YuChih/Project/IMnight2018_Backend/ENV/lib/python3.6/site-packages/rest_framework/generics.py", line 201, in get
    return self.list(request, *args, **kwargs)
  File "/Users/YuChih/Project/IMnight2018_Backend/ENV/lib/python3.6/site-packages/rest_framework/mixins.py", line 48, in list
    return Response(serializer.data)
  File "/Users/YuChih/Project/IMnight2018_Backend/ENV/lib/python3.6/site-packages/rest_framework/serializers.py", line 738, in data
    ret = super(ListSerializer, self).data
  File "/Users/YuChih/Project/IMnight2018_Backend/ENV/lib/python3.6/site-packages/rest_framework/serializers.py", line 262, in data
    self._data = self.to_representation(self.instance)
  File "/Users/YuChih/Project/IMnight2018_Backend/ENV/lib/python3.6/site-packages/rest_framework/serializers.py", line 656, in to_representation
    self.child.to_representation(item) for item in iterable
TypeError: 'Vocher' object is not iterable
ERROR - [2018-01-23 16:00:03] (exception 79506 123145581121536) Internal Server Error: /earth/vocher/八方雲集/
Traceback (most recent call last):
  File "/Users/YuChih/Project/IMnight2018_Backend/ENV/lib/python3.6/site-packages/django/core/handlers/exception.py", line 35, in inner
    response = get_response(request)
  File "/Users/YuChih/Project/IMnight2018_Backend/ENV/lib/python3.6/site-packages/django/core/handlers/base.py", line 128, in _get_response
    response = self.process_exception_by_middleware(e, request)
  File "/Users/YuChih/Project/IMnight2018_Backend/ENV/lib/python3.6/site-packages/channels/handler.py", line 243, in process_exception_by_middleware
    return super(AsgiHandler, self).process_exception_by_middleware(exception, request)
  File "/Users/YuChih/Project/IMnight2018_Backend/ENV/lib/python3.6/site-packages/django/core/handlers/base.py", line 126, in _get_response
    response = wrapped_callback(request, *callback_args, **callback_kwargs)
  File "/Users/YuChih/Project/IMnight2018_Backend/ENV/lib/python3.6/site-packages/django/views/decorators/csrf.py", line 54, in wrapped_view
    return view_func(*args, **kwargs)
  File "/Users/YuChih/Project/IMnight2018_Backend/ENV/lib/python3.6/site-packages/django/views/generic/base.py", line 69, in view
    return self.dispatch(request, *args, **kwargs)
  File "/Users/YuChih/Project/IMnight2018_Backend/ENV/lib/python3.6/site-packages/rest_framework/views.py", line 489, in dispatch
    response = self.handle_exception(exc)
  File "/Users/YuChih/Project/IMnight2018_Backend/ENV/lib/python3.6/site-packages/rest_framework/views.py", line 449, in handle_exception
    self.raise_uncaught_exception(exc)
  File "/Users/YuChih/Project/IMnight2018_Backend/ENV/lib/python3.6/site-packages/rest_framework/views.py", line 486, in dispatch
    response = handler(request, *args, **kwargs)
  File "/Users/YuChih/Project/IMnight2018_Backend/ENV/lib/python3.6/site-packages/rest_framework/generics.py", line 201, in get
    return self.list(request, *args, **kwargs)
  File "/Users/YuChih/Project/IMnight2018_Backend/ENV/lib/python3.6/site-packages/rest_framework/mixins.py", line 40, in list
    queryset = self.filter_queryset(self.get_queryset())
  File "/Users/YuChih/Project/IMnight2018_Backend/IMnight/earth/views.py", line 40, in get_queryset
    queryset = HoldingVocher.objects.get_vochers(user, storename)
  File "/Users/YuChih/Project/IMnight2018_Backend/IMnight/earth/models.py", line 21, in get_vochers
    vochers = vochers.filter(store__in=store)
AttributeError: 'Vocher' object has no attribute 'filter'
ERROR - [2018-01-23 16:00:55] (exception 79516 123145581301760) Internal Server Error: /earth/vocher/八方雲集/
Traceback (most recent call last):
  File "/Users/YuChih/Project/IMnight2018_Backend/ENV/lib/python3.6/site-packages/django/core/handlers/exception.py", line 35, in inner
    response = get_response(request)
  File "/Users/YuChih/Project/IMnight2018_Backend/ENV/lib/python3.6/site-packages/django/core/handlers/base.py", line 128, in _get_response
    response = self.process_exception_by_middleware(e, request)
  File "/Users/YuChih/Project/IMnight2018_Backend/ENV/lib/python3.6/site-packages/channels/handler.py", line 243, in process_exception_by_middleware
    return super(AsgiHandler, self).process_exception_by_middleware(exception, request)
  File "/Users/YuChih/Project/IMnight2018_Backend/ENV/lib/python3.6/site-packages/django/core/handlers/base.py", line 126, in _get_response
    response = wrapped_callback(request, *callback_args, **callback_kwargs)
  File "/Users/YuChih/Project/IMnight2018_Backend/ENV/lib/python3.6/site-packages/django/views/decorators/csrf.py", line 54, in wrapped_view
    return view_func(*args, **kwargs)
  File "/Users/YuChih/Project/IMnight2018_Backend/ENV/lib/python3.6/site-packages/django/views/generic/base.py", line 69, in view
    return self.dispatch(request, *args, **kwargs)
  File "/Users/YuChih/Project/IMnight2018_Backend/ENV/lib/python3.6/site-packages/rest_framework/views.py", line 489, in dispatch
    response = self.handle_exception(exc)
  File "/Users/YuChih/Project/IMnight2018_Backend/ENV/lib/python3.6/site-packages/rest_framework/views.py", line 449, in handle_exception
    self.raise_uncaught_exception(exc)
  File "/Users/YuChih/Project/IMnight2018_Backend/ENV/lib/python3.6/site-packages/rest_framework/views.py", line 486, in dispatch
    response = handler(request, *args, **kwargs)
  File "/Users/YuChih/Project/IMnight2018_Backend/ENV/lib/python3.6/site-packages/rest_framework/generics.py", line 201, in get
    return self.list(request, *args, **kwargs)
  File "/Users/YuChih/Project/IMnight2018_Backend/ENV/lib/python3.6/site-packages/rest_framework/mixins.py", line 40, in list
    queryset = self.filter_queryset(self.get_queryset())
  File "/Users/YuChih/Project/IMnight2018_Backend/IMnight/earth/views.py", line 40, in get_queryset
    queryset = HoldingVocher.objects.get_vochers(user, storename)
  File "/Users/YuChih/Project/IMnight2018_Backend/IMnight/earth/models.py", line 21, in get_vochers
    vochers = vochers.objects.filter(store__in=store)
  File "/Users/YuChih/Project/IMnight2018_Backend/ENV/lib/python3.6/site-packages/django/db/models/manager.py", line 178, in __get__
    raise AttributeError("Manager isn't accessible via %s instances" % cls.__name__)
AttributeError: Manager isn't accessible via Vocher instances
ERROR - [2018-01-23 16:01:34] (exception 79541 123145460989952) Internal Server Error: /earth/vocher/八方雲集/
Traceback (most recent call last):
  File "/Users/YuChih/Project/IMnight2018_Backend/ENV/lib/python3.6/site-packages/django/core/handlers/exception.py", line 35, in inner
    response = get_response(request)
  File "/Users/YuChih/Project/IMnight2018_Backend/ENV/lib/python3.6/site-packages/django/core/handlers/base.py", line 128, in _get_response
    response = self.process_exception_by_middleware(e, request)
  File "/Users/YuChih/Project/IMnight2018_Backend/ENV/lib/python3.6/site-packages/channels/handler.py", line 243, in process_exception_by_middleware
    return super(AsgiHandler, self).process_exception_by_middleware(exception, request)
  File "/Users/YuChih/Project/IMnight2018_Backend/ENV/lib/python3.6/site-packages/django/core/handlers/base.py", line 126, in _get_response
    response = wrapped_callback(request, *callback_args, **callback_kwargs)
  File "/Users/YuChih/Project/IMnight2018_Backend/ENV/lib/python3.6/site-packages/django/views/decorators/csrf.py", line 54, in wrapped_view
    return view_func(*args, **kwargs)
  File "/Users/YuChih/Project/IMnight2018_Backend/ENV/lib/python3.6/site-packages/django/views/generic/base.py", line 69, in view
    return self.dispatch(request, *args, **kwargs)
  File "/Users/YuChih/Project/IMnight2018_Backend/ENV/lib/python3.6/site-packages/rest_framework/views.py", line 489, in dispatch
    response = self.handle_exception(exc)
  File "/Users/YuChih/Project/IMnight2018_Backend/ENV/lib/python3.6/site-packages/rest_framework/views.py", line 449, in handle_exception
    self.raise_uncaught_exception(exc)
  File "/Users/YuChih/Project/IMnight2018_Backend/ENV/lib/python3.6/site-packages/rest_framework/views.py", line 486, in dispatch
    response = handler(request, *args, **kwargs)
  File "/Users/YuChih/Project/IMnight2018_Backend/ENV/lib/python3.6/site-packages/rest_framework/generics.py", line 201, in get
    return self.list(request, *args, **kwargs)
  File "/Users/YuChih/Project/IMnight2018_Backend/ENV/lib/python3.6/site-packages/rest_framework/mixins.py", line 40, in list
    queryset = self.filter_queryset(self.get_queryset())
  File "/Users/YuChih/Project/IMnight2018_Backend/IMnight/earth/views.py", line 40, in get_queryset
    queryset = HoldingVocher.objects.get_vochers(user, storename)
  File "/Users/YuChih/Project/IMnight2018_Backend/IMnight/earth/models.py", line 18, in get_vochers
    vochers = Vocher.objects.get(pk__in=vochers_pk).all()
AttributeError: 'Vocher' object has no attribute 'all'
ERROR - [2018-01-23 16:02:01] (exception 79541 123145471500288) Internal Server Error: /earth/vocher/八方雲集/
Traceback (most recent call last):
  File "/Users/YuChih/Project/IMnight2018_Backend/ENV/lib/python3.6/site-packages/django/core/handlers/exception.py", line 35, in inner
    response = get_response(request)
  File "/Users/YuChih/Project/IMnight2018_Backend/ENV/lib/python3.6/site-packages/django/core/handlers/base.py", line 128, in _get_response
    response = self.process_exception_by_middleware(e, request)
  File "/Users/YuChih/Project/IMnight2018_Backend/ENV/lib/python3.6/site-packages/channels/handler.py", line 243, in process_exception_by_middleware
    return super(AsgiHandler, self).process_exception_by_middleware(exception, request)
  File "/Users/YuChih/Project/IMnight2018_Backend/ENV/lib/python3.6/site-packages/django/core/handlers/base.py", line 126, in _get_response
    response = wrapped_callback(request, *callback_args, **callback_kwargs)
  File "/Users/YuChih/Project/IMnight2018_Backend/ENV/lib/python3.6/site-packages/django/views/decorators/csrf.py", line 54, in wrapped_view
    return view_func(*args, **kwargs)
  File "/Users/YuChih/Project/IMnight2018_Backend/ENV/lib/python3.6/site-packages/django/views/generic/base.py", line 69, in view
    return self.dispatch(request, *args, **kwargs)
  File "/Users/YuChih/Project/IMnight2018_Backend/ENV/lib/python3.6/site-packages/rest_framework/views.py", line 489, in dispatch
    response = self.handle_exception(exc)
  File "/Users/YuChih/Project/IMnight2018_Backend/ENV/lib/python3.6/site-packages/rest_framework/views.py", line 449, in handle_exception
    self.raise_uncaught_exception(exc)
  File "/Users/YuChih/Project/IMnight2018_Backend/ENV/lib/python3.6/site-packages/rest_framework/views.py", line 486, in dispatch
    response = handler(request, *args, **kwargs)
  File "/Users/YuChih/Project/IMnight2018_Backend/ENV/lib/python3.6/site-packages/rest_framework/generics.py", line 201, in get
    return self.list(request, *args, **kwargs)
  File "/Users/YuChih/Project/IMnight2018_Backend/ENV/lib/python3.6/site-packages/rest_framework/mixins.py", line 40, in list
    queryset = self.filter_queryset(self.get_queryset())
  File "/Users/YuChih/Project/IMnight2018_Backend/IMnight/earth/views.py", line 40, in get_queryset
    queryset = HoldingVocher.objects.get_vochers(user, storename)
  File "/Users/YuChih/Project/IMnight2018_Backend/IMnight/earth/models.py", line 18, in get_vochers
    vochers = Vocher.objects.get(pk__in=vochers_pk).all()
AttributeError: 'Vocher' object has no attribute 'all'
ERROR - [2018-01-23 16:03:05] (exception 79550 123145553547264) Internal Server Error: /earth/vocher/八方雲集/
Traceback (most recent call last):
  File "/Users/YuChih/Project/IMnight2018_Backend/ENV/lib/python3.6/site-packages/django/core/handlers/exception.py", line 35, in inner
    response = get_response(request)
  File "/Users/YuChih/Project/IMnight2018_Backend/ENV/lib/python3.6/site-packages/django/core/handlers/base.py", line 128, in _get_response
    response = self.process_exception_by_middleware(e, request)
  File "/Users/YuChih/Project/IMnight2018_Backend/ENV/lib/python3.6/site-packages/channels/handler.py", line 243, in process_exception_by_middleware
    return super(AsgiHandler, self).process_exception_by_middleware(exception, request)
  File "/Users/YuChih/Project/IMnight2018_Backend/ENV/lib/python3.6/site-packages/django/core/handlers/base.py", line 126, in _get_response
    response = wrapped_callback(request, *callback_args, **callback_kwargs)
  File "/Users/YuChih/Project/IMnight2018_Backend/ENV/lib/python3.6/site-packages/django/views/decorators/csrf.py", line 54, in wrapped_view
    return view_func(*args, **kwargs)
  File "/Users/YuChih/Project/IMnight2018_Backend/ENV/lib/python3.6/site-packages/django/views/generic/base.py", line 69, in view
    return self.dispatch(request, *args, **kwargs)
  File "/Users/YuChih/Project/IMnight2018_Backend/ENV/lib/python3.6/site-packages/rest_framework/views.py", line 489, in dispatch
    response = self.handle_exception(exc)
  File "/Users/YuChih/Project/IMnight2018_Backend/ENV/lib/python3.6/site-packages/rest_framework/views.py", line 449, in handle_exception
    self.raise_uncaught_exception(exc)
  File "/Users/YuChih/Project/IMnight2018_Backend/ENV/lib/python3.6/site-packages/rest_framework/views.py", line 486, in dispatch
    response = handler(request, *args, **kwargs)
  File "/Users/YuChih/Project/IMnight2018_Backend/ENV/lib/python3.6/site-packages/rest_framework/generics.py", line 201, in get
    return self.list(request, *args, **kwargs)
  File "/Users/YuChih/Project/IMnight2018_Backend/ENV/lib/python3.6/site-packages/rest_framework/mixins.py", line 40, in list
    queryset = self.filter_queryset(self.get_queryset())
  File "/Users/YuChih/Project/IMnight2018_Backend/IMnight/earth/views.py", line 40, in get_queryset
    queryset = HoldingVocher.objects.get_vochers(user, storename)
  File "/Users/YuChih/Project/IMnight2018_Backend/IMnight/earth/models.py", line 21, in get_vochers
    vochers = vochers.filter(store__in=store).all()
AttributeError: 'Vocher' object has no attribute 'filter'
ERROR - [2018-01-23 16:05:46] (exception 79566 123145468178432) Internal Server Error: /earth/vocher/八方雲集/
Traceback (most recent call last):
  File "/Users/YuChih/Project/IMnight2018_Backend/ENV/lib/python3.6/site-packages/rest_framework/fields.py", line 441, in get_attribute
    return get_attribute(instance, self.source_attrs)
  File "/Users/YuChih/Project/IMnight2018_Backend/ENV/lib/python3.6/site-packages/rest_framework/fields.py", line 100, in get_attribute
    instance = getattr(instance, attr)
AttributeError: 'QuerySet' object has no attribute 'store'

During handling of the above exception, another exception occurred:

Traceback (most recent call last):
  File "/Users/YuChih/Project/IMnight2018_Backend/ENV/lib/python3.6/site-packages/django/core/handlers/exception.py", line 35, in inner
    response = get_response(request)
  File "/Users/YuChih/Project/IMnight2018_Backend/ENV/lib/python3.6/site-packages/django/core/handlers/base.py", line 128, in _get_response
    response = self.process_exception_by_middleware(e, request)
  File "/Users/YuChih/Project/IMnight2018_Backend/ENV/lib/python3.6/site-packages/channels/handler.py", line 243, in process_exception_by_middleware
    return super(AsgiHandler, self).process_exception_by_middleware(exception, request)
  File "/Users/YuChih/Project/IMnight2018_Backend/ENV/lib/python3.6/site-packages/django/core/handlers/base.py", line 126, in _get_response
    response = wrapped_callback(request, *callback_args, **callback_kwargs)
  File "/Users/YuChih/Project/IMnight2018_Backend/ENV/lib/python3.6/site-packages/django/views/decorators/csrf.py", line 54, in wrapped_view
    return view_func(*args, **kwargs)
  File "/Users/YuChih/Project/IMnight2018_Backend/ENV/lib/python3.6/site-packages/django/views/generic/base.py", line 69, in view
    return self.dispatch(request, *args, **kwargs)
  File "/Users/YuChih/Project/IMnight2018_Backend/ENV/lib/python3.6/site-packages/rest_framework/views.py", line 489, in dispatch
    response = self.handle_exception(exc)
  File "/Users/YuChih/Project/IMnight2018_Backend/ENV/lib/python3.6/site-packages/rest_framework/views.py", line 449, in handle_exception
    self.raise_uncaught_exception(exc)
  File "/Users/YuChih/Project/IMnight2018_Backend/ENV/lib/python3.6/site-packages/rest_framework/views.py", line 486, in dispatch
    response = handler(request, *args, **kwargs)
  File "/Users/YuChih/Project/IMnight2018_Backend/ENV/lib/python3.6/site-packages/rest_framework/generics.py", line 201, in get
    return self.list(request, *args, **kwargs)
  File "/Users/YuChih/Project/IMnight2018_Backend/ENV/lib/python3.6/site-packages/rest_framework/mixins.py", line 48, in list
    return Response(serializer.data)
  File "/Users/YuChih/Project/IMnight2018_Backend/ENV/lib/python3.6/site-packages/rest_framework/serializers.py", line 738, in data
    ret = super(ListSerializer, self).data
  File "/Users/YuChih/Project/IMnight2018_Backend/ENV/lib/python3.6/site-packages/rest_framework/serializers.py", line 262, in data
    self._data = self.to_representation(self.instance)
  File "/Users/YuChih/Project/IMnight2018_Backend/ENV/lib/python3.6/site-packages/rest_framework/serializers.py", line 656, in to_representation
    self.child.to_representation(item) for item in iterable
  File "/Users/YuChih/Project/IMnight2018_Backend/ENV/lib/python3.6/site-packages/rest_framework/serializers.py", line 656, in <listcomp>
    self.child.to_representation(item) for item in iterable
  File "/Users/YuChih/Project/IMnight2018_Backend/ENV/lib/python3.6/site-packages/rest_framework/serializers.py", line 487, in to_representation
    attribute = field.get_attribute(instance)
  File "/Users/YuChih/Project/IMnight2018_Backend/ENV/lib/python3.6/site-packages/rest_framework/fields.py", line 462, in get_attribute
    raise type(exc)(msg)
AttributeError: Got AttributeError when attempting to get a value for field `store` on serializer `VocherSerializer`.
The serializer field might be named incorrectly and not match any attribute or key on the `QuerySet` instance.
Original exception text was: 'QuerySet' object has no attribute 'store'.
ERROR - [2018-01-23 16:05:46] (exception 79566 123145473433600) Internal Server Error: /earth/vocher/八方雲集/
Traceback (most recent call last):
  File "/Users/YuChih/Project/IMnight2018_Backend/ENV/lib/python3.6/site-packages/rest_framework/fields.py", line 441, in get_attribute
    return get_attribute(instance, self.source_attrs)
  File "/Users/YuChih/Project/IMnight2018_Backend/ENV/lib/python3.6/site-packages/rest_framework/fields.py", line 100, in get_attribute
    instance = getattr(instance, attr)
AttributeError: 'QuerySet' object has no attribute 'store'

During handling of the above exception, another exception occurred:

Traceback (most recent call last):
  File "/Users/YuChih/Project/IMnight2018_Backend/ENV/lib/python3.6/site-packages/django/core/handlers/exception.py", line 35, in inner
    response = get_response(request)
  File "/Users/YuChih/Project/IMnight2018_Backend/ENV/lib/python3.6/site-packages/django/core/handlers/base.py", line 128, in _get_response
    response = self.process_exception_by_middleware(e, request)
  File "/Users/YuChih/Project/IMnight2018_Backend/ENV/lib/python3.6/site-packages/channels/handler.py", line 243, in process_exception_by_middleware
    return super(AsgiHandler, self).process_exception_by_middleware(exception, request)
  File "/Users/YuChih/Project/IMnight2018_Backend/ENV/lib/python3.6/site-packages/django/core/handlers/base.py", line 126, in _get_response
    response = wrapped_callback(request, *callback_args, **callback_kwargs)
  File "/Users/YuChih/Project/IMnight2018_Backend/ENV/lib/python3.6/site-packages/django/views/decorators/csrf.py", line 54, in wrapped_view
    return view_func(*args, **kwargs)
  File "/Users/YuChih/Project/IMnight2018_Backend/ENV/lib/python3.6/site-packages/django/views/generic/base.py", line 69, in view
    return self.dispatch(request, *args, **kwargs)
  File "/Users/YuChih/Project/IMnight2018_Backend/ENV/lib/python3.6/site-packages/rest_framework/views.py", line 489, in dispatch
    response = self.handle_exception(exc)
  File "/Users/YuChih/Project/IMnight2018_Backend/ENV/lib/python3.6/site-packages/rest_framework/views.py", line 449, in handle_exception
    self.raise_uncaught_exception(exc)
  File "/Users/YuChih/Project/IMnight2018_Backend/ENV/lib/python3.6/site-packages/rest_framework/views.py", line 486, in dispatch
    response = handler(request, *args, **kwargs)
  File "/Users/YuChih/Project/IMnight2018_Backend/ENV/lib/python3.6/site-packages/rest_framework/generics.py", line 201, in get
    return self.list(request, *args, **kwargs)
  File "/Users/YuChih/Project/IMnight2018_Backend/ENV/lib/python3.6/site-packages/rest_framework/mixins.py", line 48, in list
    return Response(serializer.data)
  File "/Users/YuChih/Project/IMnight2018_Backend/ENV/lib/python3.6/site-packages/rest_framework/serializers.py", line 738, in data
    ret = super(ListSerializer, self).data
  File "/Users/YuChih/Project/IMnight2018_Backend/ENV/lib/python3.6/site-packages/rest_framework/serializers.py", line 262, in data
    self._data = self.to_representation(self.instance)
  File "/Users/YuChih/Project/IMnight2018_Backend/ENV/lib/python3.6/site-packages/rest_framework/serializers.py", line 656, in to_representation
    self.child.to_representation(item) for item in iterable
  File "/Users/YuChih/Project/IMnight2018_Backend/ENV/lib/python3.6/site-packages/rest_framework/serializers.py", line 656, in <listcomp>
    self.child.to_representation(item) for item in iterable
  File "/Users/YuChih/Project/IMnight2018_Backend/ENV/lib/python3.6/site-packages/rest_framework/serializers.py", line 487, in to_representation
    attribute = field.get_attribute(instance)
  File "/Users/YuChih/Project/IMnight2018_Backend/ENV/lib/python3.6/site-packages/rest_framework/fields.py", line 462, in get_attribute
    raise type(exc)(msg)
AttributeError: Got AttributeError when attempting to get a value for field `store` on serializer `VocherSerializer`.
The serializer field might be named incorrectly and not match any attribute or key on the `QuerySet` instance.
Original exception text was: 'QuerySet' object has no attribute 'store'.
ERROR - [2018-01-23 16:06:31] (exception 79580 123145342709760) Internal Server Error: /earth/vocher/八方雲集/
Traceback (most recent call last):
  File "/Users/YuChih/Project/IMnight2018_Backend/ENV/lib/python3.6/site-packages/rest_framework/fields.py", line 441, in get_attribute
    return get_attribute(instance, self.source_attrs)
  File "/Users/YuChih/Project/IMnight2018_Backend/ENV/lib/python3.6/site-packages/rest_framework/fields.py", line 100, in get_attribute
    instance = getattr(instance, attr)
AttributeError: 'QuerySet' object has no attribute 'store'

During handling of the above exception, another exception occurred:

Traceback (most recent call last):
  File "/Users/YuChih/Project/IMnight2018_Backend/ENV/lib/python3.6/site-packages/django/core/handlers/exception.py", line 35, in inner
    response = get_response(request)
  File "/Users/YuChih/Project/IMnight2018_Backend/ENV/lib/python3.6/site-packages/django/core/handlers/base.py", line 128, in _get_response
    response = self.process_exception_by_middleware(e, request)
  File "/Users/YuChih/Project/IMnight2018_Backend/ENV/lib/python3.6/site-packages/channels/handler.py", line 243, in process_exception_by_middleware
    return super(AsgiHandler, self).process_exception_by_middleware(exception, request)
  File "/Users/YuChih/Project/IMnight2018_Backend/ENV/lib/python3.6/site-packages/django/core/handlers/base.py", line 126, in _get_response
    response = wrapped_callback(request, *callback_args, **callback_kwargs)
  File "/Users/YuChih/Project/IMnight2018_Backend/ENV/lib/python3.6/site-packages/django/views/decorators/csrf.py", line 54, in wrapped_view
    return view_func(*args, **kwargs)
  File "/Users/YuChih/Project/IMnight2018_Backend/ENV/lib/python3.6/site-packages/django/views/generic/base.py", line 69, in view
    return self.dispatch(request, *args, **kwargs)
  File "/Users/YuChih/Project/IMnight2018_Backend/ENV/lib/python3.6/site-packages/rest_framework/views.py", line 489, in dispatch
    response = self.handle_exception(exc)
  File "/Users/YuChih/Project/IMnight2018_Backend/ENV/lib/python3.6/site-packages/rest_framework/views.py", line 449, in handle_exception
    self.raise_uncaught_exception(exc)
  File "/Users/YuChih/Project/IMnight2018_Backend/ENV/lib/python3.6/site-packages/rest_framework/views.py", line 486, in dispatch
    response = handler(request, *args, **kwargs)
  File "/Users/YuChih/Project/IMnight2018_Backend/ENV/lib/python3.6/site-packages/rest_framework/generics.py", line 201, in get
    return self.list(request, *args, **kwargs)
  File "/Users/YuChih/Project/IMnight2018_Backend/ENV/lib/python3.6/site-packages/rest_framework/mixins.py", line 48, in list
    return Response(serializer.data)
  File "/Users/YuChih/Project/IMnight2018_Backend/ENV/lib/python3.6/site-packages/rest_framework/serializers.py", line 738, in data
    ret = super(ListSerializer, self).data
  File "/Users/YuChih/Project/IMnight2018_Backend/ENV/lib/python3.6/site-packages/rest_framework/serializers.py", line 262, in data
    self._data = self.to_representation(self.instance)
  File "/Users/YuChih/Project/IMnight2018_Backend/ENV/lib/python3.6/site-packages/rest_framework/serializers.py", line 656, in to_representation
    self.child.to_representation(item) for item in iterable
  File "/Users/YuChih/Project/IMnight2018_Backend/ENV/lib/python3.6/site-packages/rest_framework/serializers.py", line 656, in <listcomp>
    self.child.to_representation(item) for item in iterable
  File "/Users/YuChih/Project/IMnight2018_Backend/ENV/lib/python3.6/site-packages/rest_framework/serializers.py", line 487, in to_representation
    attribute = field.get_attribute(instance)
  File "/Users/YuChih/Project/IMnight2018_Backend/ENV/lib/python3.6/site-packages/rest_framework/fields.py", line 462, in get_attribute
    raise type(exc)(msg)
AttributeError: Got AttributeError when attempting to get a value for field `store` on serializer `VocherSerializer`.
The serializer field might be named incorrectly and not match any attribute or key on the `QuerySet` instance.
Original exception text was: 'QuerySet' object has no attribute 'store'.
ERROR - [2018-01-23 16:32:11] (exception 80447 123145370038272) Internal Server Error: /admin/earth/holdingvocher/1/change/
Traceback (most recent call last):
  File "/Users/YuChih/Project/IMnight2018_Backend/ENV/lib/python3.6/site-packages/django/core/handlers/exception.py", line 35, in inner
    response = get_response(request)
  File "/Users/YuChih/Project/IMnight2018_Backend/ENV/lib/python3.6/site-packages/django/core/handlers/base.py", line 128, in _get_response
    response = self.process_exception_by_middleware(e, request)
  File "/Users/YuChih/Project/IMnight2018_Backend/ENV/lib/python3.6/site-packages/channels/handler.py", line 243, in process_exception_by_middleware
    return super(AsgiHandler, self).process_exception_by_middleware(exception, request)
  File "/Users/YuChih/Project/IMnight2018_Backend/ENV/lib/python3.6/site-packages/django/core/handlers/base.py", line 126, in _get_response
    response = wrapped_callback(request, *callback_args, **callback_kwargs)
  File "/Users/YuChih/Project/IMnight2018_Backend/ENV/lib/python3.6/site-packages/django/contrib/admin/options.py", line 574, in wrapper
    return self.admin_site.admin_view(view)(*args, **kwargs)
  File "/Users/YuChih/Project/IMnight2018_Backend/ENV/lib/python3.6/site-packages/django/utils/decorators.py", line 142, in _wrapped_view
    response = view_func(request, *args, **kwargs)
  File "/Users/YuChih/Project/IMnight2018_Backend/ENV/lib/python3.6/site-packages/django/views/decorators/cache.py", line 44, in _wrapped_view_func
    response = view_func(request, *args, **kwargs)
  File "/Users/YuChih/Project/IMnight2018_Backend/ENV/lib/python3.6/site-packages/django/contrib/admin/sites.py", line 223, in inner
    return view(request, *args, **kwargs)
  File "/Users/YuChih/Project/IMnight2018_Backend/ENV/lib/python3.6/site-packages/django/contrib/admin/options.py", line 1556, in change_view
    return self.changeform_view(request, object_id, form_url, extra_context)
  File "/Users/YuChih/Project/IMnight2018_Backend/ENV/lib/python3.6/site-packages/django/utils/decorators.py", line 62, in _wrapper
    return bound_func(*args, **kwargs)
  File "/Users/YuChih/Project/IMnight2018_Backend/ENV/lib/python3.6/site-packages/django/utils/decorators.py", line 142, in _wrapped_view
    response = view_func(request, *args, **kwargs)
  File "/Users/YuChih/Project/IMnight2018_Backend/ENV/lib/python3.6/site-packages/django/utils/decorators.py", line 58, in bound_func
    return func.__get__(self, type(self))(*args2, **kwargs2)
  File "/Users/YuChih/Project/IMnight2018_Backend/ENV/lib/python3.6/site-packages/django/contrib/admin/options.py", line 1450, in changeform_view
    return self._changeform_view(request, object_id, form_url, extra_context)
  File "/Users/YuChih/Project/IMnight2018_Backend/ENV/lib/python3.6/site-packages/django/contrib/admin/options.py", line 1490, in _changeform_view
    self.save_model(request, new_object, form, not add)
  File "/Users/YuChih/Project/IMnight2018_Backend/ENV/lib/python3.6/site-packages/django/contrib/admin/options.py", line 1026, in save_model
    obj.save()
  File "/Users/YuChih/Project/IMnight2018_Backend/IMnight/earth/models.py", line 151, in save
    holdingVocher_label = slugify(relationship_label)
NameError: name 'slugify' is not defined
ERROR - [2018-01-23 16:32:59] (exception 80460 123145404776448) Internal Server Error: /admin/earth/holdingvocher/2/change/
Traceback (most recent call last):
  File "/Users/YuChih/Project/IMnight2018_Backend/ENV/lib/python3.6/site-packages/django/core/handlers/exception.py", line 35, in inner
    response = get_response(request)
  File "/Users/YuChih/Project/IMnight2018_Backend/ENV/lib/python3.6/site-packages/django/core/handlers/base.py", line 128, in _get_response
    response = self.process_exception_by_middleware(e, request)
  File "/Users/YuChih/Project/IMnight2018_Backend/ENV/lib/python3.6/site-packages/channels/handler.py", line 243, in process_exception_by_middleware
    return super(AsgiHandler, self).process_exception_by_middleware(exception, request)
  File "/Users/YuChih/Project/IMnight2018_Backend/ENV/lib/python3.6/site-packages/django/core/handlers/base.py", line 126, in _get_response
    response = wrapped_callback(request, *callback_args, **callback_kwargs)
  File "/Users/YuChih/Project/IMnight2018_Backend/ENV/lib/python3.6/site-packages/django/contrib/admin/options.py", line 574, in wrapper
    return self.admin_site.admin_view(view)(*args, **kwargs)
  File "/Users/YuChih/Project/IMnight2018_Backend/ENV/lib/python3.6/site-packages/django/utils/decorators.py", line 142, in _wrapped_view
    response = view_func(request, *args, **kwargs)
  File "/Users/YuChih/Project/IMnight2018_Backend/ENV/lib/python3.6/site-packages/django/views/decorators/cache.py", line 44, in _wrapped_view_func
    response = view_func(request, *args, **kwargs)
  File "/Users/YuChih/Project/IMnight2018_Backend/ENV/lib/python3.6/site-packages/django/contrib/admin/sites.py", line 223, in inner
    return view(request, *args, **kwargs)
  File "/Users/YuChih/Project/IMnight2018_Backend/ENV/lib/python3.6/site-packages/django/contrib/admin/options.py", line 1556, in change_view
    return self.changeform_view(request, object_id, form_url, extra_context)
  File "/Users/YuChih/Project/IMnight2018_Backend/ENV/lib/python3.6/site-packages/django/utils/decorators.py", line 62, in _wrapper
    return bound_func(*args, **kwargs)
  File "/Users/YuChih/Project/IMnight2018_Backend/ENV/lib/python3.6/site-packages/django/utils/decorators.py", line 142, in _wrapped_view
    response = view_func(request, *args, **kwargs)
  File "/Users/YuChih/Project/IMnight2018_Backend/ENV/lib/python3.6/site-packages/django/utils/decorators.py", line 58, in bound_func
    return func.__get__(self, type(self))(*args2, **kwargs2)
  File "/Users/YuChih/Project/IMnight2018_Backend/ENV/lib/python3.6/site-packages/django/contrib/admin/options.py", line 1450, in changeform_view
    return self._changeform_view(request, object_id, form_url, extra_context)
  File "/Users/YuChih/Project/IMnight2018_Backend/ENV/lib/python3.6/site-packages/django/contrib/admin/options.py", line 1490, in _changeform_view
    self.save_model(request, new_object, form, not add)
  File "/Users/YuChih/Project/IMnight2018_Backend/ENV/lib/python3.6/site-packages/django/contrib/admin/options.py", line 1026, in save_model
    obj.save()
  File "/Users/YuChih/Project/IMnight2018_Backend/IMnight/earth/models.py", line 152, in save
    holdingVocher_label = slugify(relationship_label)
NameError: name 'relationship_label' is not defined
